Workbook

Sheet 12-18
A1: BẢNG TỔNG HỢP KHÁM SỨC KHỎE HỌC SINH
A2: (Khám sức khỏe học sinh năm học 2026-2027 ngày 15 tháng 9 năm 2026)
V3: NGÀY CÂN ĐO
A4: TÊN ĐƠN VỊ | C4: : TRƯỜNG MẦM NON TƯ THỤC MINH ANH | J4: LỚP | K4: NHÀ TRẺ 12-18 THÁNG | W4: 9 | X4: 2026
A5: ĐỊA CHỈ | C5: : SỐ 15/6 TRẦN ĐƯỜNG - PHƯỜNG TÂY NHA TRANG - KHÁNH HÒA
A8: STT | B8: HỌ VÀ TÊN | D8: NGÀY SINH | E8: GIỚI TÍNH | G8: TÌNH TRẠNG DINH DƯỠNG | L8: KHÁM CHUYÊN KHOA | R8: PHÂN LOẠI SỨC KHỎE | T8: THÁNG
E9: Nam | F9: Nữ | G9: Cân nặng (kg) | H9: Kết quả | I9: Chiều cao (cm) | J9: Kết quả | K9: Cân nặng theo chiều cao | L9: NHI KHOA | M9: TAI MŨI HỌNG | N9: MẮT | O9: CƠ XƯƠNG KHỚP | P9: RĂNG HÀM MẶT | Q9: CHUYÊN KHOA KHÁC | Y9: bt | Z9: SDDTNC | AA9: CNC | AB9: bt | AC9: SDDTTC | AD9: CHT | AE9: bt | AF9: TC | AG9: BP | AH9: SDDTGC | AI9: I | AJ9: II | AK9: III
A10: 1 | B10: Nguyễn Nhật | C10: Khang | D10: 45780 | E10: x | G10: 11.5 | H10: =IF(DATEDIF(D10,DATE($X$4,$W$4,$V$4),"m")<=60,LOOKUP(2,1/(G10>=INDEX(IF(E10="x",CNTT!$B$4:$E$64,CNTT!$F$4:$I$64),MATCH(DATEDIF(D10,DATE($X$4,$W$4,$V$4),"m"),CNTT!$A$4:$A$64,0),0)),CNTT!$B$3:$E$3),LOOKUP(2,1/(G10>=INDEX(IF(E10="x",CNTT!$B$70:$E$93,CNTT!$F$70:$I$93),MATCH(DATEDIF(D10,DATE($X$4,$W$4,$V$4),"m"),CNTT!$A$70:$A$93,0),0)),CNTT!$B$69:$E$69)) -> bt | I10: 78 | J10: =IF(DATEDIF(D10,DATE($X$4,$W$4,$V$4),"m")<=60,LOOKUP(2,1/(I10>=INDEX(IF(E10="x",CCTT!$B$4:$E$64,CCTT!$F$4:$I$64),MATCH(DATEDIF(D10,DATE($X$4,$W$4,$V$4),"m"),CCTT!$A$4:$A$64,0),0)),CCTT!$B$3:$E$3),LOOKUP(2,1/(I10>=INDEX(IF(E10="x",CCTT!$B$70:$E$93,CCTT!$F$70:$I$93),MATCH(DATEDIF(D10,DATE($X$4,$W$4,$V$4),"m"),CCTT!$A$70:$A$93,0),0)),CCTT!B$69:E$69)) -> bt | K10: bt | L10: Bt | M10: Bt | N10: Bt | O10: Bt | P10: Bt | Q10: Bt | R10: I | S10: =PROPER(B10) -> Nguyễn Nhật | T10: =DATEDIF(D10,DATE($X$4,$W$4,$V$4),"m") -> 15 | U10: =G10/(I10/100)^2 -> 18.902038 | Y10: =COUNTIF(H10:H19,Y9) -> 10 | Z10: =COUNTIF(H10:H19,Z9) -> 0 | AA10: =COUNTIF(H10:H19,AA9) -> 0 | AB10: =COUNTIF(J10:J19,AB9) -> 10 | AC10: =COUNTIF(J10:J19,AC9) -> 0 | AD10: =COUNTIF(J10:J19,AD9) -> 0 | AE10: =COUNTIF(K10:K19,AE9) -> 10 | AF10: =COUNTIF(K10:K19,AF9) -> 0 | AG10: =COUNTIF(K10:K19,AG9) -> 0 | AH10: =COUNTIF(K10:K19,AH9) -> 0 | AI10: =COUNTIF(R10:R19,AI9) -> 8 | AJ10: =COUNTIF(R10:R19,AJ9) -> 2 | AK10: =COUNTIF(R10:R19,AK9) -> 0
A11: 2 | B11: Vũ Diệp Nhã | C11: Kỳ | D11: 45865 | F11: x | G11: 8.2 | H11: =IF(DATEDIF(D11,DATE($X$4,$W$4,$V$4),"m")<=60,LOOKUP(2,1/(G11>=INDEX(IF(E11="x",CNTT!$B$4:$E$64,CNTT!$F$4:$I$64),MATCH(DATEDIF(D11,DATE($X$4,$W$4,$V$4),"m"),CNTT!$A$4:$A$64,0),0)),CNTT!$B$3:$E$3),LOOKUP(2,1/(G11>=INDEX(IF(E11="x",CNTT!$B$70:$E$93,CNTT!$F$70:$I$93),MATCH(DATEDIF(D11,DATE($X$4,$W$4,$V$4),"m"),CNTT!$A$70:$A$93,0),0)),CNTT!$B$69:$E$69)) -> bt | I11: 73 | J11: =IF(DATEDIF(D11,DATE($X$4,$W$4,$V$4),"m")<=60,LOOKUP(2,1/(I11>=INDEX(IF(E11="x",CCTT!$B$4:$E$64,CCTT!$F$4:$I$64),MATCH(DATEDIF(D11,DATE($X$4,$W$4,$V$4),"m"),CCTT!$A$4:$A$64,0),0)),CCTT!$B$3:$E$3),LOOKUP(2,1/(I11>=INDEX(IF(E11="x",CCTT!$B$70:$E$93,CCTT!$F$70:$I$93),MATCH(DATEDIF(D11,DATE($X$4,$W$4,$V$4),"m"),CCTT!$A$70:$A$93,0),0)),CCTT!B$69:E$69)) -> bt | K11: bt | L11: Bt | M11: Bt | N11: Bt | O11: Bt | P11: Bt | Q11: Bt | R11: I | S11: =PROPER(B11) -> Vũ Diệp Nhã | T11: =DATEDIF(D11,DATE($X$4,$W$4,$V$4),"m") -> 13 | U11: =G11/(I11/100)^2 -> 15.387502 | Y11: =SUM(Y10:AA10) -> 10
A12: 3 | B12: Trần Chí | C12: Kiên | D12: 45812 | E12: x | G12: 10.1 | H12: =IF(DATEDIF(D12,DATE($X$4,$W$4,$V$4),"m")<=60,LOOKUP(2,1/(G12>=INDEX(IF(E12="x",CNTT!$B$4:$E$64,CNTT!$F$4:$I$64),MATCH(DATEDIF(D12,DATE($X$4,$W$4,$V$4),"m"),CNTT!$A$4:$A$64,0),0)),CNTT!$B$3:$E$3),LOOKUP(2,1/(G12>=INDEX(IF(E12="x",CNTT!$B$70:$E$93,CNTT!$F$70:$I$93),MATCH(DATEDIF(D12,DATE($X$4,$W$4,$V$4),"m"),CNTT!$A$70:$A$93,0),0)),CNTT!$B$69:$E$69)) -> bt | I12: 79 | J12: =IF(DATEDIF(D12,DATE($X$4,$W$4,$V$4),"m")<=60,LOOKUP(2,1/(I12>=INDEX(IF(E12="x",CCTT!$B$4:$E$64,CCTT!$F$4:$I$64),MATCH(DATEDIF(D12,DATE($X$4,$W$4,$V$4),"m"),CCTT!$A$4:$A$64,0),0)),CCTT!$B$3:$E$3),LOOKUP(2,1/(I12>=INDEX(IF(E12="x",CCTT!$B$70:$E$93,CCTT!$F$70:$I$93),MATCH(DATEDIF(D12,DATE($X$4,$W$4,$V$4),"m"),CCTT!$A$70:$A$93,0),0)),CCTT!B$69:E$69)) -> bt | K12: bt | L12: Bt | M12: Bt | N12: Bt | O12: Bt | P12: Bt | Q12: Bt | R12: I | S12: =PROPER(B12) -> Trần Chí | T12: =DATEDIF(D12,DATE($X$4,$W$4,$V$4),"m") -> 14 | U12: =G12/(I12/100)^2 -> 16.183304 | Y12: =SUM(AB10:AD10) -> 10
A13: 4 | B13: Đỗ Hoàng Trà | C13: My | D13: 45719 | F13: x | G13: 8.2 | H13: =IF(DATEDIF(D13,DATE($X$4,$W$4,$V$4),"m")<=60,LOOKUP(2,1/(G13>=INDEX(IF(E13="x",CNTT!$B$4:$E$64,CNTT!$F$4:$I$64),MATCH(DATEDIF(D13,DATE($X$4,$W$4,$V$4),"m"),CNTT!$A$4:$A$64,0),0)),CNTT!$B$3:$E$3),LOOKUP(2,1/(G13>=INDEX(IF(E13="x",CNTT!$B$70:$E$93,CNTT!$F$70:$I$93),MATCH(DATEDIF(D13,DATE($X$4,$W$4,$V$4),"m"),CNTT!$A$70:$A$93,0),0)),CNTT!$B$69:$E$69)) -> bt | I13: 75 | J13: =IF(DATEDIF(D13,DATE($X$4,$W$4,$V$4),"m")<=60,LOOKUP(2,1/(I13>=INDEX(IF(E13="x",CCTT!$B$4:$E$64,CCTT!$F$4:$I$64),MATCH(DATEDIF(D13,DATE($X$4,$W$4,$V$4),"m"),CCTT!$A$4:$A$64,0),0)),CCTT!$B$3:$E$3),LOOKUP(2,1/(I13>=INDEX(IF(E13="x",CCTT!$B$70:$E$93,CCTT!$F$70:$I$93),MATCH(DATEDIF(D13,DATE($X$4,$W$4,$V$4),"m"),CCTT!$A$70:$A$93,0),0)),CCTT!B$69:E$69)) -> bt | K13: bt | L13: Bt | M13: VMH | N13: Bt | O13: Bt | P13: Bt | Q13: Bt | R13: II | S13: =PROPER(B13) -> Đỗ Hoàng Trà | T13: =DATEDIF(D13,DATE($X$4,$W$4,$V$4),"m") -> 17 | U13: =G13/(I13/100)^2 -> 14.577778 | Y13: =SUM(AE10:AH10) -> 10
A14: 5 | B14: Nguyễn Trúc | C14: Nghi | D14: 45744 | F14: x | G14: 9 | H14: =IF(DATEDIF(D14,DATE($X$4,$W$4,$V$4),"m")<=60,LOOKUP(2,1/(G14>=INDEX(IF(E14="x",CNTT!$B$4:$E$64,CNTT!$F$4:$I$64),MATCH(DATEDIF(D14,DATE($X$4,$W$4,$V$4),"m"),CNTT!$A$4:$A$64,0),0)),CNTT!$B$3:$E$3),LOOKUP(2,1/(G14>=INDEX(IF(E14="x",CNTT!$B$70:$E$93,CNTT!$F$70:$I$93),MATCH(DATEDIF(D14,DATE($X$4,$W$4,$V$4),"m"),CNTT!$A$70:$A$93,0),0)),CNTT!$B$69:$E$69)) -> bt | I14: 78 | J14: =IF(DATEDIF(D14,DATE($X$4,$W$4,$V$4),"m")<=60,LOOKUP(2,1/(I14>=INDEX(IF(E14="x",CCTT!$B$4:$E$64,CCTT!$F$4:$I$64),MATCH(DATEDIF(D14,DATE($X$4,$W$4,$V$4),"m"),CCTT!$A$4:$A$64,0),0)),CCTT!$B$3:$E$3),LOOKUP(2,1/(I14>=INDEX(IF(E14="x",CCTT!$B$70:$E$93,CCTT!$F$70:$I$93),MATCH(DATEDIF(D14,DATE($X$4,$W$4,$V$4),"m"),CCTT!$A$70:$A$93,0),0)),CCTT!B$69:E$69)) -> bt | K14: bt | L14: Bt | M14: Bt | N14: Bt | O14: Bt | P14: Bt | Q14: Bt | R14: I | S14: =PROPER(B14) -> Nguyễn Trúc | T14: =DATEDIF(D14,DATE($X$4,$W$4,$V$4),"m") -> 17 | U14: =G14/(I14/100)^2 -> 14.792899 | Y14: =SUM(AI10:AK10) -> 10
A15: 6 | B15: Võ Duy | C15: Thịnh | D15: 45887 | E15: x | G15: 10.4 | H15: =IF(DATEDIF(D15,DATE($X$4,$W$4,$V$4),"m")<=60,LOOKUP(2,1/(G15>=INDEX(IF(E15="x",CNTT!$B$4:$E$64,CNTT!$F$4:$I$64),MATCH(DATEDIF(D15,DATE($X$4,$W$4,$V$4),"m"),CNTT!$A$4:$A$64,0),0)),CNTT!$B$3:$E$3),LOOKUP(2,1/(G15>=INDEX(IF(E15="x",CNTT!$B$70:$E$93,CNTT!$F$70:$I$93),MATCH(DATEDIF(D15,DATE($X$4,$W$4,$V$4),"m"),CNTT!$A$70:$A$93,0),0)),CNTT!$B$69:$E$69)) -> bt | I15: 76 | J15: =IF(DATEDIF(D15,DATE($X$4,$W$4,$V$4),"m")<=60,LOOKUP(2,1/(I15>=INDEX(IF(E15="x",CCTT!$B$4:$E$64,CCTT!$F$4:$I$64),MATCH(DATEDIF(D15,DATE($X$4,$W$4,$V$4),"m"),CCTT!$A$4:$A$64,0),0)),CCTT!$B$3:$E$3),LOOKUP(2,1/(I15>=INDEX(IF(E15="x",CCTT!$B$70:$E$93,CCTT!$F$70:$I$93),MATCH(DATEDIF(D15,DATE($X$4,$W$4,$V$4),"m"),CCTT!$A$70:$A$93,0),0)),CCTT!B$69:E$69)) -> bt | K15: bt | L15: Bt | M15: Bt | N15: Bt | O15: Bt | P15: Bt | Q15: Bt | R15: I | S15: =PROPER(B15) -> Võ Duy | T15: =DATEDIF(D15,DATE($X$4,$W$4,$V$4),"m") -> 12 | U15: =G15/(I15/100)^2 -> 18.00554
A16: 7 | B16: Vòng Ngọc Cát | C16: Tường | D16: 45754 | E16: x | G16: 10 | H16: =IF(DATEDIF(D16,DATE($X$4,$W$4,$V$4),"m")<=60,LOOKUP(2,1/(G16>=INDEX(IF(E16="x",CNTT!$B$4:$E$64,CNTT!$F$4:$I$64),MATCH(DATEDIF(D16,DATE($X$4,$W$4,$V$4),"m"),CNTT!$A$4:$A$64,0),0)),CNTT!$B$3:$E$3),LOOKUP(2,1/(G16>=INDEX(IF(E16="x",CNTT!$B$70:$E$93,CNTT!$F$70:$I$93),MATCH(DATEDIF(D16,DATE($X$4,$W$4,$V$4),"m"),CNTT!$A$70:$A$93,0),0)),CNTT!$B$69:$E$69)) -> bt | I16: 76 | J16: =IF(DATEDIF(D16,DATE($X$4,$W$4,$V$4),"m")<=60,LOOKUP(2,1/(I16>=INDEX(IF(E16="x",CCTT!$B$4:$E$64,CCTT!$F$4:$I$64),MATCH(DATEDIF(D16,DATE($X$4,$W$4,$V$4),"m"),CCTT!$A$4:$A$64,0),0)),CCTT!$B$3:$E$3),LOOKUP(2,1/(I16>=INDEX(IF(E16="x",CCTT!$B$70:$E$93,CCTT!$F$70:$I$93),MATCH(DATEDIF(D16,DATE($X$4,$W$4,$V$4),"m"),CCTT!$A$70:$A$93,0),0)),CCTT!B$69:E$69)) -> bt | K16: bt | L16: Bt | M16: Bt | N16: Bt | O16: Bt | P16: Bt | Q16: Bt | R16: I | S16: =PROPER(B16) -> Vòng Ngọc Cát | T16: =DATEDIF(D16,DATE($X$4,$W$4,$V$4),"m") -> 16 | U16: =G16/(I16/100)^2 -> 17.313019
A17: 8 | B17: Đỗ Khánh | C17: Trân | D17: 45675 | F17: x | G17: 11.3 | H17: =IF(DATEDIF(D17,DATE($X$4,$W$4,$V$4),"m")<=60,LOOKUP(2,1/(G17>=INDEX(IF(E17="x",CNTT!$B$4:$E$64,CNTT!$F$4:$I$64),MATCH(DATEDIF(D17,DATE($X$4,$W$4,$V$4),"m"),CNTT!$A$4:$A$64,0),0)),CNTT!$B$3:$E$3),LOOKUP(2,1/(G17>=INDEX(IF(E17="x",CNTT!$B$70:$E$93,CNTT!$F$70:$I$93),MATCH(DATEDIF(D17,DATE($X$4,$W$4,$V$4),"m"),CNTT!$A$70:$A$93,0),0)),CNTT!$B$69:$E$69)) -> bt | I17: 84 | J17: =IF(DATEDIF(D17,DATE($X$4,$W$4,$V$4),"m")<=60,LOOKUP(2,1/(I17>=INDEX(IF(E17="x",CCTT!$B$4:$E$64,CCTT!$F$4:$I$64),MATCH(DATEDIF(D17,DATE($X$4,$W$4,$V$4),"m"),CCTT!$A$4:$A$64,0),0)),CCTT!$B$3:$E$3),LOOKUP(2,1/(I17>=INDEX(IF(E17="x",CCTT!$B$70:$E$93,CCTT!$F$70:$I$93),MATCH(DATEDIF(D17,DATE($X$4,$W$4,$V$4),"m"),CCTT!$A$70:$A$93,0),0)),CCTT!B$69:E$69)) -> bt | K17: bt | L17: Bt | M17: Bt | N17: Bt | O17: Bt | P17: Bt | Q17: Bt | R17: I | S17: =PROPER(B17) -> Đỗ Khánh | T17: =DATEDIF(D17,DATE($X$4,$W$4,$V$4),"m") -> 19 | U17: =G17/(I17/100)^2 -> 16.014739
A18: 9 | B18: Phan Nguyễn Phương | C18: Sam | D18: 45717 | F18: x | G18: 11.5 | H18: =IF(DATEDIF(D18,DATE($X$4,$W$4,$V$4),"m")<=60,LOOKUP(2,1/(G18>=INDEX(IF(E18="x",CNTT!$B$4:$E$64,CNTT!$F$4:$I$64),MATCH(DATEDIF(D18,DATE($X$4,$W$4,$V$4),"m"),CNTT!$A$4:$A$64,0),0)),CNTT!$B$3:$E$3),LOOKUP(2,1/(G18>=INDEX(IF(E18="x",CNTT!$B$70:$E$93,CNTT!$F$70:$I$93),MATCH(DATEDIF(D18,DATE($X$4,$W$4,$V$4),"m"),CNTT!$A$70:$A$93,0),0)),CNTT!$B$69:$E$69)) -> bt | I18: 78 | J18: =IF(DATEDIF(D18,DATE($X$4,$W$4,$V$4),"m")<=60,LOOKUP(2,1/(I18>=INDEX(IF(E18="x",CCTT!$B$4:$E$64,CCTT!$F$4:$I$64),MATCH(DATEDIF(D18,DATE($X$4,$W$4,$V$4),"m"),CCTT!$A$4:$A$64,0),0)),CCTT!$B$3:$E$3),LOOKUP(2,1/(I18>=INDEX(IF(E18="x",CCTT!$B$70:$E$93,CCTT!$F$70:$I$93),MATCH(DATEDIF(D18,DATE($X$4,$W$4,$V$4),"m"),CCTT!$A$70:$A$93,0),0)),CCTT!B$69:E$69)) -> bt | K18: bt | L18: Bt | M18: Bt | N18: Bt | O18: Bt | P18: Bt | Q18: Bt | R18: I | S18: =PROPER(B18) -> Phan Nguyễn Phương | T18: =DATEDIF(D18,DATE($X$4,$W$4,$V$4),"m") -> 17 | U18: =G18/(I18/100)^2 -> 18.902038
A19: 10 | B19: Dương Ngọc An | C19: Di | D19: 45861 | F19: x | G19: 11.7 | H19: =IF(DATEDIF(D19,DATE($X$4,$W$4,$V$4),"m")<=60,LOOKUP(2,1/(G19>=INDEX(IF(E19="x",CNTT!$B$4:$E$64,CNTT!$F$4:$I$64),MATCH(DATEDIF(D19,DATE($X$4,$W$4,$V$4),"m"),CNTT!$A$4:$A$64,0),0)),CNTT!$B$3:$E$3),LOOKUP(2,1/(G19>=INDEX(IF(E19="x",CNTT!$B$70:$E$93,CNTT!$F$70:$I$93),MATCH(DATEDIF(D19,DATE($X$4,$W$4,$V$4),"m"),CNTT!$A$70:$A$93,0),0)),CNTT!$B$69:$E$69)) -> bt | I19: 72 | J19: =IF(DATEDIF(D19,DATE($X$4,$W$4,$V$4),"m")<=60,LOOKUP(2,1/(I19>=INDEX(IF(E19="x",CCTT!$B$4:$E$64,CCTT!$F$4:$I$64),MATCH(DATEDIF(D19,DATE($X$4,$W$4,$V$4),"m"),CCTT!$A$4:$A$64,0),0)),CCTT!$B$3:$E$3),LOOKUP(2,1/(I19>=INDEX(IF(E19="x",CCTT!$B$70:$E$93,CCTT!$F$70:$I$93),MATCH(DATEDIF(D19,DATE($X$4,$W$4,$V$4),"m"),CCTT!$A$70:$A$93,0),0)),CCTT!B$69:E$69)) -> bt | K19: bt | L19: Bt | M19: VMH | N19: Bt | O19: Bt | P19: Bt | Q19: Bt | R19: II | S19: =PROPER(B19) -> Dương Ngọc An | T19: =DATEDIF(D19,DATE($X$4,$W$4,$V$4),"m") -> 13 | U19: =G19/(I19/100)^2 -> 22.569444
D21: GHI CHÚ CHỮ VIẾT TẮT:
A23: bt | C23: : Bình thường | I23: SDDTTC | L23: : Suy dinh dưỡng thể thấp còi
A24: SDDTNC | C24: : Suy dinh dưỡng thể nhẹ cân | I24: SDDTTCMĐN | L24: : Suy dinh dưỡng thể thấp còi mức độ nặng
A25: TC | C25: : Thừa cân | I25: SDDTGC | L25: : Suy dinh dưỡng thể gầy còm
A26: BP | C26: : Béo phì | I26: SDDTGCMĐN | L26: : Suy dinh dưỡng thể gầy còm mức độ nặng
A27: CNC | C27: : Cân nặng cao | I27: CHT | L27: : Cao hơn tuổi
A28: VP | C28: : Viêm phổi | I28: VMH | L28: : Viêm mũi họng
A29: Sr | C29: : Sâu răng | I29: VMXT | L29: : Viêm mũi xuất tiết
A30: VHHT | C30: : Viêm hô hấp trên | I30: TKX | L30: : Tật khúc xa

Sheet 19-24 a
A1: BẢNG TỔNG HỢP KHÁM SỨC KHỎE HỌC SINH
A2: (Khám sức khỏe học sinh năm học 2026-2027 ngày 15 tháng 9 năm 2026)
V3: NGÀY CÂN ĐO
A4: TÊN ĐƠN VỊ | C4: : TRƯỜNG MẦM NON TƯ THỤC MINH ANH | J4: LỚP | K4: NHÀ TRẺ 19-24 THÁNG A | W4: 9 | X4: 2026
A5: ĐỊA CHỈ | C5: : SỐ 15/6 TRẦN ĐƯỜNG - PHƯỜNG TÂY NHA TRANG - KHÁNH HÒA
A8: STT | B8: HỌ VÀ TÊN | D8: NGÀY SINH | E8: GIỚI TÍNH | G8: TÌNH TRẠNG DINH DƯỠNG | L8: KHÁM CHUYÊN KHOA | R8: PHÂN LOẠI SỨC KHỎE | T8: THÁNG
E9: Nam | F9: Nữ | G9: Cân nặng (kg) | H9: Kết quả | I9: Chiều cao (cm) | J9: Kết quả | K9: Cân nặng theo chiều cao | L9: NHI KHOA | M9: TAI MŨI HỌNG | N9: MẮT | O9: CƠ XƯƠNG KHỚP | P9: RĂNG HÀM MẶT | Q9: CHUYÊN KHOA KHÁC | Y9: bt | Z9: SDDTNC | AA9: CNC | AB9: bt | AC9: SDDTTC | AD9: CHT | AE9: bt | AF9: TC | AG9: BP | AH9: SDDTGC | AI9: I | AJ9: II | AK9: III
A10: 1 | B10: Nguyễn Ngọc Bảo | C10: Đan | D10: 45694 | F10: x | G10: 11 | H10: =IF(DATEDIF(D10,DATE($X$4,$W$4,$V$4),"m")<=60,LOOKUP(2,1/(G10>=INDEX(IF(E10="x",CNTT!$B$4:$E$64,CNTT!$F$4:$I$64),MATCH(DATEDIF(D10,DATE($X$4,$W$4,$V$4),"m"),CNTT!$A$4:$A$64,0),0)),CNTT!$B$3:$E$3),LOOKUP(2,1/(G10>=INDEX(IF(E10="x",CNTT!$B$70:$E$93,CNTT!$F$70:$I$93),MATCH(DATEDIF(D10,DATE($X$4,$W$4,$V$4),"m"),CNTT!$A$70:$A$93,0),0)),CNTT!$B$69:$E$69)) -> bt | I10: 79 | J10: =IF(DATEDIF(D10,DATE($X$4,$W$4,$V$4),"m")<=60,LOOKUP(2,1/(I10>=INDEX(IF(E10="x",CCTT!$B$4:$E$64,CCTT!$F$4:$I$64),MATCH(DATEDIF(D10,DATE($X$4,$W$4,$V$4),"m"),CCTT!$A$4:$A$64,0),0)),CCTT!$B$3:$E$3),LOOKUP(2,1/(I10>=INDEX(IF(E10="x",CCTT!$B$70:$E$93,CCTT!$F$70:$I$93),MATCH(DATEDIF(D10,DATE($X$4,$W$4,$V$4),"m"),CCTT!$A$70:$A$93,0),0)),CCTT!B$69:E$69)) -> bt | K10: bt | L10: Bt | M10: Bt | N10: Bt | O10: Bt | P10: Bt | Q10: Bt | R10: I | S10: =PROPER(B10) -> Nguyễn Ngọc Bảo | T10: =DATEDIF(D10,DATE($X$4,$W$4,$V$4),"m") -> 18 | U10: =G10/(I10/100)^2 -> 17.625381 | Y10: =COUNTIF(H10:H18,Y9) -> 9 | Z10: =COUNTIF(H10:H18,Z9) -> 0 | AA10: =COUNTIF(H10:H18,AA9) -> 0 | AB10: =COUNTIF(J10:J18,AB9) -> 9 | AC10: =COUNTIF(J10:J18,AC9) -> 0 | AD10: =COUNTIF(J10:J18,AD9) -> 0 | AE10: =COUNTIF(K10:K18,AE9) -> 9 | AF10: =COUNTIF(K10:K18,AF9) -> 0 | AG10: =COUNTIF(K10:K18,AG9) -> 0 | AH10: =COUNTIF(K10:K18,AH9) -> 0 | AI10: =COUNTIF(R10:R18,AI9) -> 6 | AJ10: =COUNTIF(R10:R18,AJ9) -> 3 | AK10: =COUNTIF(R10:R18,AK9) -> 0
A11: 2 | B11: Nguyễn Khả | C11: Hân | D11: 45570 | F11: x | G11: 11.4 | H11: =IF(DATEDIF(D11,DATE($X$4,$W$4,$V$4),"m")<=60,LOOKUP(2,1/(G11>=INDEX(IF(E11="x",CNTT!$B$4:$E$64,CNTT!$F$4:$I$64),MATCH(DATEDIF(D11,DATE($X$4,$W$4,$V$4),"m"),CNTT!$A$4:$A$64,0),0)),CNTT!$B$3:$E$3),LOOKUP(2,1/(G11>=INDEX(IF(E11="x",CNTT!$B$70:$E$93,CNTT!$F$70:$I$93),MATCH(DATEDIF(D11,DATE($X$4,$W$4,$V$4),"m"),CNTT!$A$70:$A$93,0),0)),CNTT!$B$69:$E$69)) -> bt | I11: 86 | J11: =IF(DATEDIF(D11,DATE($X$4,$W$4,$V$4),"m")<=60,LOOKUP(2,1/(I11>=INDEX(IF(E11="x",CCTT!$B$4:$E$64,CCTT!$F$4:$I$64),MATCH(DATEDIF(D11,DATE($X$4,$W$4,$V$4),"m"),CCTT!$A$4:$A$64,0),0)),CCTT!$B$3:$E$3),LOOKUP(2,1/(I11>=INDEX(IF(E11="x",CCTT!$B$70:$E$93,CCTT!$F$70:$I$93),MATCH(DATEDIF(D11,DATE($X$4,$W$4,$V$4),"m"),CCTT!$A$70:$A$93,0),0)),CCTT!B$69:E$69)) -> bt | K11: bt | L11: Bt | M11: Bt | N11: Bt | O11: Bt | P11: Bt | Q11: Bt | R11: I | S11: =PROPER(B11) -> Nguyễn Khả | T11: =DATEDIF(D11,DATE($X$4,$W$4,$V$4),"m") -> 22 | U11: =G11/(I11/100)^2 -> 15.413737 | Y11: =SUM(Y10:AA10) -> 9
A12: 3 | B12: Lê Bảo | C12: Long | D12: 45638 | E12: x | G12: 12.5 | H12: =IF(DATEDIF(D12,DATE($X$4,$W$4,$V$4),"m")<=60,LOOKUP(2,1/(G12>=INDEX(IF(E12="x",CNTT!$B$4:$E$64,CNTT!$F$4:$I$64),MATCH(DATEDIF(D12,DATE($X$4,$W$4,$V$4),"m"),CNTT!$A$4:$A$64,0),0)),CNTT!$B$3:$E$3),LOOKUP(2,1/(G12>=INDEX(IF(E12="x",CNTT!$B$70:$E$93,CNTT!$F$70:$I$93),MATCH(DATEDIF(D12,DATE($X$4,$W$4,$V$4),"m"),CNTT!$A$70:$A$93,0),0)),CNTT!$B$69:$E$69)) -> bt | I12: 86 | J12: =IF(DATEDIF(D12,DATE($X$4,$W$4,$V$4),"m")<=60,LOOKUP(2,1/(I12>=INDEX(IF(E12="x",CCTT!$B$4:$E$64,CCTT!$F$4:$I$64),MATCH(DATEDIF(D12,DATE($X$4,$W$4,$V$4),"m"),CCTT!$A$4:$A$64,0),0)),CCTT!$B$3:$E$3),LOOKUP(2,1/(I12>=INDEX(IF(E12="x",CCTT!$B$70:$E$93,CCTT!$F$70:$I$93),MATCH(DATEDIF(D12,DATE($X$4,$W$4,$V$4),"m"),CCTT!$A$70:$A$93,0),0)),CCTT!B$69:E$69)) -> bt | K12: bt | L12: Bt | M12: VMXT | N12: Bt | O12: Bt | P12: Bt | Q12: Bt | R12: II | S12: =PROPER(B12) -> Lê Bảo | T12: =DATEDIF(D12,DATE($X$4,$W$4,$V$4),"m") -> 20 | U12: =G12/(I12/100)^2 -> 16.901028 | Y12: =SUM(AB10:AD10) -> 9
A13: 4 | B13: Nguyễn Nhật | C13: Minh | D13: 45667 | E13: x | G13: 11.9 | H13: =IF(DATEDIF(D13,DATE($X$4,$W$4,$V$4),"m")<=60,LOOKUP(2,1/(G13>=INDEX(IF(E13="x",CNTT!$B$4:$E$64,CNTT!$F$4:$I$64),MATCH(DATEDIF(D13,DATE($X$4,$W$4,$V$4),"m"),CNTT!$A$4:$A$64,0),0)),CNTT!$B$3:$E$3),LOOKUP(2,1/(G13>=INDEX(IF(E13="x",CNTT!$B$70:$E$93,CNTT!$F$70:$I$93),MATCH(DATEDIF(D13,DATE($X$4,$W$4,$V$4),"m"),CNTT!$A$70:$A$93,0),0)),CNTT!$B$69:$E$69)) -> bt | I13: 79 | J13: =IF(DATEDIF(D13,DATE($X$4,$W$4,$V$4),"m")<=60,LOOKUP(2,1/(I13>=INDEX(IF(E13="x",CCTT!$B$4:$E$64,CCTT!$F$4:$I$64),MATCH(DATEDIF(D13,DATE($X$4,$W$4,$V$4),"m"),CCTT!$A$4:$A$64,0),0)),CCTT!$B$3:$E$3),LOOKUP(2,1/(I13>=INDEX(IF(E13="x",CCTT!$B$70:$E$93,CCTT!$F$70:$I$93),MATCH(DATEDIF(D13,DATE($X$4,$W$4,$V$4),"m"),CCTT!$A$70:$A$93,0),0)),CCTT!B$69:E$69)) -> bt | K13: bt | L13: Bt | M13: Bt | N13: Bt | O13: Bt | P13: Bt | Q13: Bt | R13: I | S13: =PROPER(B13) -> Nguyễn Nhật | T13: =DATEDIF(D13,DATE($X$4,$W$4,$V$4),"m") -> 19 | U13: =G13/(I13/100)^2 -> 19.067457 | Y13: =SUM(AE10:AH10) -> 9
A14: 5 | B14: Nguyễn Lê Kim | C14: Ngân | D14: 45695 | F14: x | G14: 9.1 | H14: =IF(DATEDIF(D14,DATE($X$4,$W$4,$V$4),"m")<=60,LOOKUP(2,1/(G14>=INDEX(IF(E14="x",CNTT!$B$4:$E$64,CNTT!$F$4:$I$64),MATCH(DATEDIF(D14,DATE($X$4,$W$4,$V$4),"m"),CNTT!$A$4:$A$64,0),0)),CNTT!$B$3:$E$3),LOOKUP(2,1/(G14>=INDEX(IF(E14="x",CNTT!$B$70:$E$93,CNTT!$F$70:$I$93),MATCH(DATEDIF(D14,DATE($X$4,$W$4,$V$4),"m"),CNTT!$A$70:$A$93,0),0)),CNTT!$B$69:$E$69)) -> bt | I14: 78 | J14: =IF(DATEDIF(D14,DATE($X$4,$W$4,$V$4),"m")<=60,LOOKUP(2,1/(I14>=INDEX(IF(E14="x",CCTT!$B$4:$E$64,CCTT!$F$4:$I$64),MATCH(DATEDIF(D14,DATE($X$4,$W$4,$V$4),"m"),CCTT!$A$4:$A$64,0),0)),CCTT!$B$3:$E$3),LOOKUP(2,1/(I14>=INDEX(IF(E14="x",CCTT!$B$70:$E$93,CCTT!$F$70:$I$93),MATCH(DATEDIF(D14,DATE($X$4,$W$4,$V$4),"m"),CCTT!$A$70:$A$93,0),0)),CCTT!B$69:E$69)) -> bt | K14: bt | L14: Bt | M14: Bt | N14: Bt | O14: Bt | P14: Bt | Q14: Bt | R14: I | S14: =PROPER(B14) -> Nguyễn Lê Kim | T14: =DATEDIF(D14,DATE($X$4,$W$4,$V$4),"m") -> 18 | U14: =G14/(I14/100)^2 -> 14.957265 | Y14: =SUM(AI10:AK10) -> 9
A15: 6 | B15: Nguyễn Trần Hạ | C15: Vi | D15: 45693 | F15: x | G15: 11.7 | H15: =IF(DATEDIF(D15,DATE($X$4,$W$4,$V$4),"m")<=60,LOOKUP(2,1/(G15>=INDEX(IF(E15="x",CNTT!$B$4:$E$64,CNTT!$F$4:$I$64),MATCH(DATEDIF(D15,DATE($X$4,$W$4,$V$4),"m"),CNTT!$A$4:$A$64,0),0)),CNTT!$B$3:$E$3),LOOKUP(2,1/(G15>=INDEX(IF(E15="x",CNTT!$B$70:$E$93,CNTT!$F$70:$I$93),MATCH(DATEDIF(D15,DATE($X$4,$W$4,$V$4),"m"),CNTT!$A$70:$A$93,0),0)),CNTT!$B$69:$E$69)) -> bt | I15: 80 | J15: =IF(DATEDIF(D15,DATE($X$4,$W$4,$V$4),"m")<=60,LOOKUP(2,1/(I15>=INDEX(IF(E15="x",CCTT!$B$4:$E$64,CCTT!$F$4:$I$64),MATCH(DATEDIF(D15,DATE($X$4,$W$4,$V$4),"m"),CCTT!$A$4:$A$64,0),0)),CCTT!$B$3:$E$3),LOOKUP(2,1/(I15>=INDEX(IF(E15="x",CCTT!$B$70:$E$93,CCTT!$F$70:$I$93),MATCH(DATEDIF(D15,DATE($X$4,$W$4,$V$4),"m"),CCTT!$A$70:$A$93,0),0)),CCTT!B$69:E$69)) -> bt | K15: bt | L15: Bt | M15: Bt | N15: Bt | O15: Bt | P15: Bt | Q15: Bt | R15: I | S15: =PROPER(B15) -> Nguyễn Trần Hạ | T15: =DATEDIF(D15,DATE($X$4,$W$4,$V$4),"m") -> 18 | U15: =G15/(I15/100)^2 -> 18.28125
A16: 7 | B16: Nguyễn Đăng | C16: Vỹ | D16: 45644 | E16: x | G16: 11.4 | H16: =IF(DATEDIF(D16,DATE($X$4,$W$4,$V$4),"m")<=60,LOOKUP(2,1/(G16>=INDEX(IF(E16="x",CNTT!$B$4:$E$64,CNTT!$F$4:$I$64),MATCH(DATEDIF(D16,DATE($X$4,$W$4,$V$4),"m"),CNTT!$A$4:$A$64,0),0)),CNTT!$B$3:$E$3),LOOKUP(2,1/(G16>=INDEX(IF(E16="x",CNTT!$B$70:$E$93,CNTT!$F$70:$I$93),MATCH(DATEDIF(D16,DATE($X$4,$W$4,$V$4),"m"),CNTT!$A$70:$A$93,0),0)),CNTT!$B$69:$E$69)) -> bt | I16: 84 | J16: =IF(DATEDIF(D16,DATE($X$4,$W$4,$V$4),"m")<=60,LOOKUP(2,1/(I16>=INDEX(IF(E16="x",CCTT!$B$4:$E$64,CCTT!$F$4:$I$64),MATCH(DATEDIF(D16,DATE($X$4,$W$4,$V$4),"m"),CCTT!$A$4:$A$64,0),0)),CCTT!$B$3:$E$3),LOOKUP(2,1/(I16>=INDEX(IF(E16="x",CCTT!$B$70:$E$93,CCTT!$F$70:$I$93),MATCH(DATEDIF(D16,DATE($X$4,$W$4,$V$4),"m"),CCTT!$A$70:$A$93,0),0)),CCTT!B$69:E$69)) -> bt | K16: bt | L16: Bt | M16: VMXT | N16: Bt | O16: Bt | P16: Bt | Q16: Bt | R16: II | S16: =PROPER(B16) -> Nguyễn Đăng | T16: =DATEDIF(D16,DATE($X$4,$W$4,$V$4),"m") -> 20 | U16: =G16/(I16/100)^2 -> 16.156463
A17: 8 | B17: Nguyễn Ngọc Ánh | C17: Xuân | D17: 45686 | F17: x | G17: 10.3 | H17: =IF(DATEDIF(D17,DATE($X$4,$W$4,$V$4),"m")<=60,LOOKUP(2,1/(G17>=INDEX(IF(E17="x",CNTT!$B$4:$E$64,CNTT!$F$4:$I$64),MATCH(DATEDIF(D17,DATE($X$4,$W$4,$V$4),"m"),CNTT!$A$4:$A$64,0),0)),CNTT!$B$3:$E$3),LOOKUP(2,1/(G17>=INDEX(IF(E17="x",CNTT!$B$70:$E$93,CNTT!$F$70:$I$93),MATCH(DATEDIF(D17,DATE($X$4,$W$4,$V$4),"m"),CNTT!$A$70:$A$93,0),0)),CNTT!$B$69:$E$69)) -> bt | I17: 81 | J17: =IF(DATEDIF(D17,DATE($X$4,$W$4,$V$4),"m")<=60,LOOKUP(2,1/(I17>=INDEX(IF(E17="x",CCTT!$B$4:$E$64,CCTT!$F$4:$I$64),MATCH(DATEDIF(D17,DATE($X$4,$W$4,$V$4),"m"),CCTT!$A$4:$A$64,0),0)),CCTT!$B$3:$E$3),LOOKUP(2,1/(I17>=INDEX(IF(E17="x",CCTT!$B$70:$E$93,CCTT!$F$70:$I$93),MATCH(DATEDIF(D17,DATE($X$4,$W$4,$V$4),"m"),CCTT!$A$70:$A$93,0),0)),CCTT!B$69:E$69)) -> bt | K17: bt | L17: Bt | M17: VMXT | N17: Bt | O17: Bt | P17: Bt | Q17: Bt | R17: II | S17: =PROPER(B17) -> Nguyễn Ngọc Ánh | T17: =DATEDIF(D17,DATE($X$4,$W$4,$V$4),"m") -> 19 | U17: =G17/(I17/100)^2 -> 15.698826
A18: 9 | B18: Lã Trương Minh | C18: Khải | D18: 45734 | E18: x | G18: 11.1 | H18: =IF(DATEDIF(D18,DATE($X$4,$W$4,$V$4),"m")<=60,LOOKUP(2,1/(G18>=INDEX(IF(E18="x",CNTT!$B$4:$E$64,CNTT!$F$4:$I$64),MATCH(DATEDIF(D18,DATE($X$4,$W$4,$V$4),"m"),CNTT!$A$4:$A$64,0),0)),CNTT!$B$3:$E$3),LOOKUP(2,1/(G18>=INDEX(IF(E18="x",CNTT!$B$70:$E$93,CNTT!$F$70:$I$93),MATCH(DATEDIF(D18,DATE($X$4,$W$4,$V$4),"m"),CNTT!$A$70:$A$93,0),0)),CNTT!$B$69:$E$69)) -> bt | I18: 86 | J18: =IF(DATEDIF(D18,DATE($X$4,$W$4,$V$4),"m")<=60,LOOKUP(2,1/(I18>=INDEX(IF(E18="x",CCTT!$B$4:$E$64,CCTT!$F$4:$I$64),MATCH(DATEDIF(D18,DATE($X$4,$W$4,$V$4),"m"),CCTT!$A$4:$A$64,0),0)),CCTT!$B$3:$E$3),LOOKUP(2,1/(I18>=INDEX(IF(E18="x",CCTT!$B$70:$E$93,CCTT!$F$70:$I$93),MATCH(DATEDIF(D18,DATE($X$4,$W$4,$V$4),"m"),CCTT!$A$70:$A$93,0),0)),CCTT!B$69:E$69)) -> bt | K18: =IF(DATEDIF(D18,DATE($X$4,$W$4,$V$4),"m")<24,LOOKUP(2,1/(G18>=INDEX(IF(E18="x",CNTCC!$B$4:$F$134,CNTCC!$F$4),MATCH(I18,CNTCC!$A$4:$A$134,0),0)),CNTCC!$B$3:$F$3),IF(AND(DATEDIF(D18,DATE($X$4,$W$4,$V$4),"m")>=24,DATEDIF(D18,DATE($X$4,$W$4,$V$4),"m")<=60),LOOKUP(2,1/(G18>=INDEX(IF(E18="x",CNTCC!$B$141:$F$251,CNTCC!$G$141:$K$251),MATCH(I18,CNTCC!$A$141:$A$251,0),0)),CNTCC!$B$140:$F$140),0)) -> bt | L18: Bt | M18: Bt | N18: Bt | O18: Bt | P18: Bt | Q18: Bt | R18: I | S18: =PROPER(B18) -> Lã Trương Minh | T18: =DATEDIF(D18,DATE($X$4,$W$4,$V$4),"m") -> 17 | U18: =G18/(I18/100)^2 -> 15.008112
D20: GHI CHÚ CHỮ VIẾT TẮT:
A22: bt | C22: : Bình thường | I22: SDDTTC | L22: : Suy dinh dưỡng thể thấp còi
A23: SDDTNC | C23: : Suy dinh dưỡng thể nhẹ cân | I23: SDDTTCMĐN | L23: : Suy dinh dưỡng thể thấp còi mức độ nặng
A24: TC | C24: : Thừa cân | I24: SDDTGC | L24: : Suy dinh dưỡng thể gầy còm
A25: BP | C25: : Béo phì | I25: SDDTGCMĐN | L25: : Suy dinh dưỡng thể gầy còm mức độ nặng
A26: CNC | C26: : Cân nặng cao | I26: CHT | L26: : Cao hơn tuổi
A27: VP | C27: : Viêm phổi | I27: VMH | L27: : Viêm mũi họng
A28: Sr | C28: : Sâu răng | I28: VMXT | L28: : Viêm mũi xuất tiết
A29: VHHT | C29: : Viêm hô hấp trên | I29: TKX | L29: : Tật khúc xa

Sheet 19-24 B
A1: BẢNG TỔNG HỢP KHÁM SỨC KHỎE HỌC SINH
A2: (Khám sức khỏe học sinh năm học 2026-2027 ngày 15 tháng 9 năm 2026)
V3: NGÀY CÂN ĐO
A4: TÊN ĐƠN VỊ | C4: : TRƯỜNG MẦM NON TƯ THỤC MINH ANH | J4: LỚP | K4: NHÀ TRẺ 19-24 THÁNG B | W4: 9 | X4: 2026
A5: ĐỊA CHỈ | C5: : SỐ 15/6 TRẦN ĐƯỜNG - PHƯỜNG TÂY NHA TRANG - KHÁNH HÒA
A8: STT | B8: HỌ VÀ TÊN | D8: NGÀY SINH | E8: GIỚI TÍNH | G8: TÌNH TRẠNG DINH DƯỠNG | L8: KHÁM CHUYÊN KHOA | R8: PHÂN LOẠI SỨC KHỎE | T8: THÁNG
E9: Nam | F9: Nữ | G9: Cân nặng (kg) | H9: Kết quả | I9: Chiều cao (cm) | J9: Kết quả | K9: Cân nặng theo chiều cao | L9: NHI KHOA | M9: TAI MŨI HỌNG | N9: MẮT | O9: CƠ XƯƠNG KHỚP | P9: RĂNG HÀM MẶT | Q9: CHUYÊN KHOA KHÁC | Y9: bt | Z9: SDDTNC | AA9: CNC | AB9: bt | AC9: SDDTTC | AD9: CHT | AE9: bt | AF9: TC | AG9: BP | AH9: SDDTGC | AI9: I | AJ9: II | AK9: III
A10: 1 | B10: Trương Ng. Khánh | C10: An | D10: 25/12/2024 | F10: x | G10: 10.1 | H10: =IF(DATEDIF(D10,DATE($X$4,$W$4,$V$4),"m")<=60,LOOKUP(2,1/(G10>=INDEX(IF(E10="x",CNTT!$B$4:$E$64,CNTT!$F$4:$I$64),MATCH(DATEDIF(D10,DATE($X$4,$W$4,$V$4),"m"),CNTT!$A$4:$A$64,0),0)),CNTT!$B$3:$E$3),LOOKUP(2,1/(G10>=INDEX(IF(E10="x",CNTT!$B$70:$E$93,CNTT!$F$70:$I$93),MATCH(DATEDIF(D10,DATE($X$4,$W$4,$V$4),"m"),CNTT!$A$70:$A$93,0),0)),CNTT!$B$69:$E$69)) -> bt | I10: 77 | J10: =IF(DATEDIF(D10,DATE($X$4,$W$4,$V$4),"m")<=60,LOOKUP(2,1/(I10>=INDEX(IF(E10="x",CCTT!$B$4:$E$64,CCTT!$F$4:$I$64),MATCH(DATEDIF(D10,DATE($X$4,$W$4,$V$4),"m"),CCTT!$A$4:$A$64,0),0)),CCTT!$B$3:$E$3),LOOKUP(2,1/(I10>=INDEX(IF(E10="x",CCTT!$B$70:$E$93,CCTT!$F$70:$I$93),MATCH(DATEDIF(D10,DATE($X$4,$W$4,$V$4),"m"),CCTT!$A$70:$A$93,0),0)),CCTT!B$69:E$69)) -> bt | K10: bt | L10: Bt | M10: Bt | N10: Bt | O10: Bt | P10: Bt | Q10: Bt | R10: I | S10: =PROPER(B10) -> Trương Ng. Khánh | T10: =DATEDIF(D10,DATE($X$4,$W$4,$V$4),"m") -> 20 | U10: =G10/(I10/100)^2 -> 17.034913 | Y10: =COUNTIF(H10:H22,Y9) -> 13 | Z10: =COUNTIF(H10:H22,Z9) -> 0 | AA10: =COUNTIF(H10:H22,AA9) -> 0 | AB10: =COUNTIF(J10:J22,AB9) -> 13 | AC10: =COUNTIF(J10:J22,AC9) -> 0 | AD10: =COUNTIF(J10:J22,AD9) -> 0 | AE10: =COUNTIF(K10:K22,AE9) -> 13 | AF10: =COUNTIF(K10:K22,AF9) -> 0 | AG10: =COUNTIF(K10:K22,AG9) -> 0 | AH10: =COUNTIF(K10:K22,AH9) -> 0 | AI10: =COUNTIF(R10:R22,AI9) -> 12 | AJ10: =COUNTIF(R10:R22,AJ9) -> 1 | AK10: =COUNTIF(R10:R22,AK9) -> 0
A11: 2 | B11: Đặng Nguyễn Minh | C11: Khang | D11: 45684 | E11: x | G11: 12 | H11: =IF(DATEDIF(D11,DATE($X$4,$W$4,$V$4),"m")<=60,LOOKUP(2,1/(G11>=INDEX(IF(E11="x",CNTT!$B$4:$E$64,CNTT!$F$4:$I$64),MATCH(DATEDIF(D11,DATE($X$4,$W$4,$V$4),"m"),CNTT!$A$4:$A$64,0),0)),CNTT!$B$3:$E$3),LOOKUP(2,1/(G11>=INDEX(IF(E11="x",CNTT!$B$70:$E$93,CNTT!$F$70:$I$93),MATCH(DATEDIF(D11,DATE($X$4,$W$4,$V$4),"m"),CNTT!$A$70:$A$93,0),0)),CNTT!$B$69:$E$69)) -> bt | I11: 81 | J11: =IF(DATEDIF(D11,DATE($X$4,$W$4,$V$4),"m")<=60,LOOKUP(2,1/(I11>=INDEX(IF(E11="x",CCTT!$B$4:$E$64,CCTT!$F$4:$I$64),MATCH(DATEDIF(D11,DATE($X$4,$W$4,$V$4),"m"),CCTT!$A$4:$A$64,0),0)),CCTT!$B$3:$E$3),LOOKUP(2,1/(I11>=INDEX(IF(E11="x",CCTT!$B$70:$E$93,CCTT!$F$70:$I$93),MATCH(DATEDIF(D11,DATE($X$4,$W$4,$V$4),"m"),CCTT!$A$70:$A$93,0),0)),CCTT!B$69:E$69)) -> bt | K11: =IF(DATEDIF(D11,DATE($X$4,$W$4,$V$4),"m")<24,LOOKUP(2,1/(G11>=INDEX(IF(E11="x",CNTCC!$B$4:$F$134,CNTCC!$F$4),MATCH(I11,CNTCC!$A$4:$A$134,0),0)),CNTCC!$B$3:$F$3),IF(AND(DATEDIF(D11,DATE($X$4,$W$4,$V$4),"m")>=24,DATEDIF(D11,DATE($X$4,$W$4,$V$4),"m")<=60),LOOKUP(2,1/(G11>=INDEX(IF(E11="x",CNTCC!$B$141:$F$251,CNTCC!$G$141:$K$251),MATCH(I11,CNTCC!$A$141:$A$251,0),0)),CNTCC!$B$140:$F$140),0)) -> bt | L11: Bt | M11: Bt | N11: Bt | O11: Bt | P11: Bt | Q11: Bt | R11: I | S11: =PROPER(B11) -> Đặng Nguyễn Minh | T11: =DATEDIF(D11,DATE($X$4,$W$4,$V$4),"m") -> 19 | U11: =G11/(I11/100)^2 -> 18.289895 | Y11: =SUM(Y10:AA10) -> 13
A12: 3 | B12: Mai Hưng | C12: Khôi | D12: 45562 | E12: x | G12: 11.3 | H12: =IF(DATEDIF(D12,DATE($X$4,$W$4,$V$4),"m")<=60,LOOKUP(2,1/(G12>=INDEX(IF(E12="x",CNTT!$B$4:$E$64,CNTT!$F$4:$I$64),MATCH(DATEDIF(D12,DATE($X$4,$W$4,$V$4),"m"),CNTT!$A$4:$A$64,0),0)),CNTT!$B$3:$E$3),LOOKUP(2,1/(G12>=INDEX(IF(E12="x",CNTT!$B$70:$E$93,CNTT!$F$70:$I$93),MATCH(DATEDIF(D12,DATE($X$4,$W$4,$V$4),"m"),CNTT!$A$70:$A$93,0),0)),CNTT!$B$69:$E$69)) -> bt | I12: 82 | J12: =IF(DATEDIF(D12,DATE($X$4,$W$4,$V$4),"m")<=60,LOOKUP(2,1/(I12>=INDEX(IF(E12="x",CCTT!$B$4:$E$64,CCTT!$F$4:$I$64),MATCH(DATEDIF(D12,DATE($X$4,$W$4,$V$4),"m"),CCTT!$A$4:$A$64,0),0)),CCTT!$B$3:$E$3),LOOKUP(2,1/(I12>=INDEX(IF(E12="x",CCTT!$B$70:$E$93,CCTT!$F$70:$I$93),MATCH(DATEDIF(D12,DATE($X$4,$W$4,$V$4),"m"),CCTT!$A$70:$A$93,0),0)),CCTT!B$69:E$69)) -> bt | K12: =IF(DATEDIF(D12,DATE($X$4,$W$4,$V$4),"m")<24,LOOKUP(2,1/(G12>=INDEX(IF(E12="x",CNTCC!$B$4:$F$134,CNTCC!$F$4),MATCH(I12,CNTCC!$A$4:$A$134,0),0)),CNTCC!$B$3:$F$3),IF(AND(DATEDIF(D12,DATE($X$4,$W$4,$V$4),"m")>=24,DATEDIF(D12,DATE($X$4,$W$4,$V$4),"m")<=60),LOOKUP(2,1/(G12>=INDEX(IF(E12="x",CNTCC!$B$141:$F$251,CNTCC!$G$141:$K$251),MATCH(I12,CNTCC!$A$141:$A$251,0),0)),CNTCC!$B$140:$F$140),0)) -> bt | L12: Bt | M12: Bt | N12: Bt | O12: Bt | P12: Bt | Q12: Bt | R12: I | S12: =PROPER(B12) -> Mai Hưng | T12: =DATEDIF(D12,DATE($X$4,$W$4,$V$4),"m") -> 23 | U12: =G12/(I12/100)^2 -> 16.805473 | Y12: =SUM(AB10:AD10) -> 13
A13: 4 | B13: Ngô Đăng | C13: Khôi | D13: 45576 | E13: x | G13: 12.3 | H13: =IF(DATEDIF(D13,DATE($X$4,$W$4,$V$4),"m")<=60,LOOKUP(2,1/(G13>=INDEX(IF(E13="x",CNTT!$B$4:$E$64,CNTT!$F$4:$I$64),MATCH(DATEDIF(D13,DATE($X$4,$W$4,$V$4),"m"),CNTT!$A$4:$A$64,0),0)),CNTT!$B$3:$E$3),LOOKUP(2,1/(G13>=INDEX(IF(E13="x",CNTT!$B$70:$E$93,CNTT!$F$70:$I$93),MATCH(DATEDIF(D13,DATE($X$4,$W$4,$V$4),"m"),CNTT!$A$70:$A$93,0),0)),CNTT!$B$69:$E$69)) -> bt | I13: 84 | J13: =IF(DATEDIF(D13,DATE($X$4,$W$4,$V$4),"m")<=60,LOOKUP(2,1/(I13>=INDEX(IF(E13="x",CCTT!$B$4:$E$64,CCTT!$F$4:$I$64),MATCH(DATEDIF(D13,DATE($X$4,$W$4,$V$4),"m"),CCTT!$A$4:$A$64,0),0)),CCTT!$B$3:$E$3),LOOKUP(2,1/(I13>=INDEX(IF(E13="x",CCTT!$B$70:$E$93,CCTT!$F$70:$I$93),MATCH(DATEDIF(D13,DATE($X$4,$W$4,$V$4),"m"),CCTT!$A$70:$A$93,0),0)),CCTT!B$69:E$69)) -> bt | K13: =IF(DATEDIF(D13,DATE($X$4,$W$4,$V$4),"m")<24,LOOKUP(2,1/(G13>=INDEX(IF(E13="x",CNTCC!$B$4:$F$134,CNTCC!$F$4),MATCH(I13,CNTCC!$A$4:$A$134,0),0)),CNTCC!$B$3:$F$3),IF(AND(DATEDIF(D13,DATE($X$4,$W$4,$V$4),"m")>=24,DATEDIF(D13,DATE($X$4,$W$4,$V$4),"m")<=60),LOOKUP(2,1/(G13>=INDEX(IF(E13="x",CNTCC!$B$141:$F$251,CNTCC!$G$141:$K$251),MATCH(I13,CNTCC!$A$141:$A$251,0),0)),CNTCC!$B$140:$F$140),0)) -> bt | L13: Bt | M13: Bt | N13: Bt | O13: Bt | P13: Bt | Q13: Bt | R13: I | S13: =PROPER(B13) -> Ngô Đăng | T13: =DATEDIF(D13,DATE($X$4,$W$4,$V$4),"m") -> 22 | U13: =G13/(I13/100)^2 -> 17.431973 | Y13: =SUM(AE10:AH10) -> 13
A14: 5 | B14: Trần Ngọc Thiên | C14: Kim | D14: 45637 | F14: x | G14: 12.3 | H14: =IF(DATEDIF(D14,DATE($X$4,$W$4,$V$4),"m")<=60,LOOKUP(2,1/(G14>=INDEX(IF(E14="x",CNTT!$B$4:$E$64,CNTT!$F$4:$I$64),MATCH(DATEDIF(D14,DATE($X$4,$W$4,$V$4),"m"),CNTT!$A$4:$A$64,0),0)),CNTT!$B$3:$E$3),LOOKUP(2,1/(G14>=INDEX(IF(E14="x",CNTT!$B$70:$E$93,CNTT!$F$70:$I$93),MATCH(DATEDIF(D14,DATE($X$4,$W$4,$V$4),"m"),CNTT!$A$70:$A$93,0),0)),CNTT!$B$69:$E$69)) -> bt | I14: 83 | J14: =IF(DATEDIF(D14,DATE($X$4,$W$4,$V$4),"m")<=60,LOOKUP(2,1/(I14>=INDEX(IF(E14="x",CCTT!$B$4:$E$64,CCTT!$F$4:$I$64),MATCH(DATEDIF(D14,DATE($X$4,$W$4,$V$4),"m"),CCTT!$A$4:$A$64,0),0)),CCTT!$B$3:$E$3),LOOKUP(2,1/(I14>=INDEX(IF(E14="x",CCTT!$B$70:$E$93,CCTT!$F$70:$I$93),MATCH(DATEDIF(D14,DATE($X$4,$W$4,$V$4),"m"),CCTT!$A$70:$A$93,0),0)),CCTT!B$69:E$69)) -> bt | K14: bt | L14: Bt | M14: VMH | N14: Bt | O14: Bt | P14: Bt | Q14: Bt | R14: II | S14: =PROPER(B14) -> Trần Ngọc Thiên | T14: =DATEDIF(D14,DATE($X$4,$W$4,$V$4),"m") -> 20 | U14: =G14/(I14/100)^2 -> 17.854551 | Y14: =SUM(AI10:AK10) -> 13
A15: 6 | B15: Văn Trúc | C15: Lam | D15: 45639 | F15: x | G15: 12 | H15: =IF(DATEDIF(D15,DATE($X$4,$W$4,$V$4),"m")<=60,LOOKUP(2,1/(G15>=INDEX(IF(E15="x",CNTT!$B$4:$E$64,CNTT!$F$4:$I$64),MATCH(DATEDIF(D15,DATE($X$4,$W$4,$V$4),"m"),CNTT!$A$4:$A$64,0),0)),CNTT!$B$3:$E$3),LOOKUP(2,1/(G15>=INDEX(IF(E15="x",CNTT!$B$70:$E$93,CNTT!$F$70:$I$93),MATCH(DATEDIF(D15,DATE($X$4,$W$4,$V$4),"m"),CNTT!$A$70:$A$93,0),0)),CNTT!$B$69:$E$69)) -> bt | I15: 80 | J15: =IF(DATEDIF(D15,DATE($X$4,$W$4,$V$4),"m")<=60,LOOKUP(2,1/(I15>=INDEX(IF(E15="x",CCTT!$B$4:$E$64,CCTT!$F$4:$I$64),MATCH(DATEDIF(D15,DATE($X$4,$W$4,$V$4),"m"),CCTT!$A$4:$A$64,0),0)),CCTT!$B$3:$E$3),LOOKUP(2,1/(I15>=INDEX(IF(E15="x",CCTT!$B$70:$E$93,CCTT!$F$70:$I$93),MATCH(DATEDIF(D15,DATE($X$4,$W$4,$V$4),"m"),CCTT!$A$70:$A$93,0),0)),CCTT!B$69:E$69)) -> bt | K15: bt | L15: Bt | M15: Bt | N15: Bt | O15: Bt | P15: Bt | Q15: Bt | R15: I | S15: =PROPER(B15) -> Văn Trúc | T15: =DATEDIF(D15,DATE($X$4,$W$4,$V$4),"m") -> 20 | U15: =G15/(I15/100)^2 -> 18.75
A16: 7 | B16: Nguyễn Bảo | C16: Luân | D16: 45629 | E16: x | G16: 10.1 | H16: =IF(DATEDIF(D16,DATE($X$4,$W$4,$V$4),"m")<=60,LOOKUP(2,1/(G16>=INDEX(IF(E16="x",CNTT!$B$4:$E$64,CNTT!$F$4:$I$64),MATCH(DATEDIF(D16,DATE($X$4,$W$4,$V$4),"m"),CNTT!$A$4:$A$64,0),0)),CNTT!$B$3:$E$3),LOOKUP(2,1/(G16>=INDEX(IF(E16="x",CNTT!$B$70:$E$93,CNTT!$F$70:$I$93),MATCH(DATEDIF(D16,DATE($X$4,$W$4,$V$4),"m"),CNTT!$A$70:$A$93,0),0)),CNTT!$B$69:$E$69)) -> bt | I16: 78 | J16: bt | K16: =IF(DATEDIF(D16,DATE($X$4,$W$4,$V$4),"m")<24,LOOKUP(2,1/(G16>=INDEX(IF(E16="x",CNTCC!$B$4:$F$134,CNTCC!$F$4),MATCH(I16,CNTCC!$A$4:$A$134,0),0)),CNTCC!$B$3:$F$3),IF(AND(DATEDIF(D16,DATE($X$4,$W$4,$V$4),"m")>=24,DATEDIF(D16,DATE($X$4,$W$4,$V$4),"m")<=60),LOOKUP(2,1/(G16>=INDEX(IF(E16="x",CNTCC!$B$141:$F$251,CNTCC!$G$141:$K$251),MATCH(I16,CNTCC!$A$141:$A$251,0),0)),CNTCC!$B$140:$F$140),0)) -> bt | L16: Bt | M16: Bt | N16: Bt | O16: Bt | P16: Bt | Q16: Bt | R16: I | S16: =PROPER(B16) -> Nguyễn Bảo | T16: =DATEDIF(D16,DATE($X$4,$W$4,$V$4),"m") -> 20 | U16: =G16/(I16/100)^2 -> 16.60092
A17: 8 | B17: Nguyễn Đại | C17: Minh | D17: 45583 | E17: x | G17: 11.7 | H17: =IF(DATEDIF(D17,DATE($X$4,$W$4,$V$4),"m")<=60,LOOKUP(2,1/(G17>=INDEX(IF(E17="x",CNTT!$B$4:$E$64,CNTT!$F$4:$I$64),MATCH(DATEDIF(D17,DATE($X$4,$W$4,$V$4),"m"),CNTT!$A$4:$A$64,0),0)),CNTT!$B$3:$E$3),LOOKUP(2,1/(G17>=INDEX(IF(E17="x",CNTT!$B$70:$E$93,CNTT!$F$70:$I$93),MATCH(DATEDIF(D17,DATE($X$4,$W$4,$V$4),"m"),CNTT!$A$70:$A$93,0),0)),CNTT!$B$69:$E$69)) -> bt | I17: 81 | J17: =IF(DATEDIF(D17,DATE($X$4,$W$4,$V$4),"m")<=60,LOOKUP(2,1/(I17>=INDEX(IF(E17="x",CCTT!$B$4:$E$64,CCTT!$F$4:$I$64),MATCH(DATEDIF(D17,DATE($X$4,$W$4,$V$4),"m"),CCTT!$A$4:$A$64,0),0)),CCTT!$B$3:$E$3),LOOKUP(2,1/(I17>=INDEX(IF(E17="x",CCTT!$B$70:$E$93,CCTT!$F$70:$I$93),MATCH(DATEDIF(D17,DATE($X$4,$W$4,$V$4),"m"),CCTT!$A$70:$A$93,0),0)),CCTT!B$69:E$69)) -> bt | K17: =IF(DATEDIF(D17,DATE($X$4,$W$4,$V$4),"m")<24,LOOKUP(2,1/(G17>=INDEX(IF(E17="x",CNTCC!$B$4:$F$134,CNTCC!$F$4),MATCH(I17,CNTCC!$A$4:$A$134,0),0)),CNTCC!$B$3:$F$3),IF(AND(DATEDIF(D17,DATE($X$4,$W$4,$V$4),"m")>=24,DATEDIF(D17,DATE($X$4,$W$4,$V$4),"m")<=60),LOOKUP(2,1/(G17>=INDEX(IF(E17="x",CNTCC!$B$141:$F$251,CNTCC!$G$141:$K$251),MATCH(I17,CNTCC!$A$141:$A$251,0),0)),CNTCC!$B$140:$F$140),0)) -> bt | L17: Bt | M17: Bt | N17: Bt | O17: Bt | P17: Bt | Q17: Bt | R17: I | S17: =PROPER(B17) -> Nguyễn Đại | T17: =DATEDIF(D17,DATE($X$4,$W$4,$V$4),"m") -> 22 | U17: =G17/(I17/100)^2 -> 17.832647
A18: 9 | B18: Lê Hoàng Nhật | C18: Minh | D18: 45709 | E18: x | G18: 10.7 | H18: =IF(DATEDIF(D18,DATE($X$4,$W$4,$V$4),"m")<=60,LOOKUP(2,1/(G18>=INDEX(IF(E18="x",CNTT!$B$4:$E$64,CNTT!$F$4:$I$64),MATCH(DATEDIF(D18,DATE($X$4,$W$4,$V$4),"m"),CNTT!$A$4:$A$64,0),0)),CNTT!$B$3:$E$3),LOOKUP(2,1/(G18>=INDEX(IF(E18="x",CNTT!$B$70:$E$93,CNTT!$F$70:$I$93),MATCH(DATEDIF(D18,DATE($X$4,$W$4,$V$4),"m"),CNTT!$A$70:$A$93,0),0)),CNTT!$B$69:$E$69)) -> bt | I18: 78 | J18: =IF(DATEDIF(D18,DATE($X$4,$W$4,$V$4),"m")<=60,LOOKUP(2,1/(I18>=INDEX(IF(E18="x",CCTT!$B$4:$E$64,CCTT!$F$4:$I$64),MATCH(DATEDIF(D18,DATE($X$4,$W$4,$V$4),"m"),CCTT!$A$4:$A$64,0),0)),CCTT!$B$3:$E$3),LOOKUP(2,1/(I18>=INDEX(IF(E18="x",CCTT!$B$70:$E$93,CCTT!$F$70:$I$93),MATCH(DATEDIF(D18,DATE($X$4,$W$4,$V$4),"m"),CCTT!$A$70:$A$93,0),0)),CCTT!B$69:E$69)) -> bt | K18: =IF(DATEDIF(D18,DATE($X$4,$W$4,$V$4),"m")<24,LOOKUP(2,1/(G18>=INDEX(IF(E18="x",CNTCC!$B$4:$F$134,CNTCC!$F$4),MATCH(I18,CNTCC!$A$4:$A$134,0),0)),CNTCC!$B$3:$F$3),IF(AND(DATEDIF(D18,DATE($X$4,$W$4,$V$4),"m")>=24,DATEDIF(D18,DATE($X$4,$W$4,$V$4),"m")<=60),LOOKUP(2,1/(G18>=INDEX(IF(E18="x",CNTCC!$B$141:$F$251,CNTCC!$G$141:$K$251),MATCH(I18,CNTCC!$A$141:$A$251,0),0)),CNTCC!$B$140:$F$140),0)) -> bt | L18: Bt | M18: Bt | N18: Bt | O18: Bt | P18: Bt | Q18: Bt | R18: I | S18: =PROPER(B18) -> Lê Hoàng Nhật | T18: =DATEDIF(D18,DATE($X$4,$W$4,$V$4),"m") -> 18 | U18: =G18/(I18/100)^2 -> 17.587114
A19: 10 | B19: Dương Thành | C19: Phát | D19: 45626 | E19: x | G19: 12.2 | H19: =IF(DATEDIF(D19,DATE($X$4,$W$4,$V$4),"m")<=60,LOOKUP(2,1/(G19>=INDEX(IF(E19="x",CNTT!$B$4:$E$64,CNTT!$F$4:$I$64),MATCH(DATEDIF(D19,DATE($X$4,$W$4,$V$4),"m"),CNTT!$A$4:$A$64,0),0)),CNTT!$B$3:$E$3),LOOKUP(2,1/(G19>=INDEX(IF(E19="x",CNTT!$B$70:$E$93,CNTT!$F$70:$I$93),MATCH(DATEDIF(D19,DATE($X$4,$W$4,$V$4),"m"),CNTT!$A$70:$A$93,0),0)),CNTT!$B$69:$E$69)) -> bt | I19: 81 | J19: =IF(DATEDIF(D19,DATE($X$4,$W$4,$V$4),"m")<=60,LOOKUP(2,1/(I19>=INDEX(IF(E19="x",CCTT!$B$4:$E$64,CCTT!$F$4:$I$64),MATCH(DATEDIF(D19,DATE($X$4,$W$4,$V$4),"m"),CCTT!$A$4:$A$64,0),0)),CCTT!$B$3:$E$3),LOOKUP(2,1/(I19>=INDEX(IF(E19="x",CCTT!$B$70:$E$93,CCTT!$F$70:$I$93),MATCH(DATEDIF(D19,DATE($X$4,$W$4,$V$4),"m"),CCTT!$A$70:$A$93,0),0)),CCTT!B$69:E$69)) -> bt | K19: =IF(DATEDIF(D19,DATE($X$4,$W$4,$V$4),"m")<24,LOOKUP(2,1/(G19>=INDEX(IF(E19="x",CNTCC!$B$4:$F$134,CNTCC!$F$4),MATCH(I19,CNTCC!$A$4:$A$134,0),0)),CNTCC!$B$3:$F$3),IF(AND(DATEDIF(D19,DATE($X$4,$W$4,$V$4),"m")>=24,DATEDIF(D19,DATE($X$4,$W$4,$V$4),"m")<=60),LOOKUP(2,1/(G19>=INDEX(IF(E19="x",CNTCC!$B$141:$F$251,CNTCC!$G$141:$K$251),MATCH(I19,CNTCC!$A$141:$A$251,0),0)),CNTCC!$B$140:$F$140),0)) -> bt | L19: Bt | M19: Bt | N19: Bt | O19: Bt | P19: Bt | Q19: Bt | R19: I | S19: =PROPER(B19) -> Dương Thành | T19: =DATEDIF(D19,DATE($X$4,$W$4,$V$4),"m") -> 21 | U19: =G19/(I19/100)^2 -> 18.594726
A20: 11 | B20: Trần Chí | C20: Thanh | D20: 45628 | E20: x | G20: 12 | H20: =IF(DATEDIF(D20,DATE($X$4,$W$4,$V$4),"m")<=60,LOOKUP(2,1/(G20>=INDEX(IF(E20="x",CNTT!$B$4:$E$64,CNTT!$F$4:$I$64),MATCH(DATEDIF(D20,DATE($X$4,$W$4,$V$4),"m"),CNTT!$A$4:$A$64,0),0)),CNTT!$B$3:$E$3),LOOKUP(2,1/(G20>=INDEX(IF(E20="x",CNTT!$B$70:$E$93,CNTT!$F$70:$I$93),MATCH(DATEDIF(D20,DATE($X$4,$W$4,$V$4),"m"),CNTT!$A$70:$A$93,0),0)),CNTT!$B$69:$E$69)) -> bt | I20: 83 | J20: =IF(DATEDIF(D20,DATE($X$4,$W$4,$V$4),"m")<=60,LOOKUP(2,1/(I20>=INDEX(IF(E20="x",CCTT!$B$4:$E$64,CCTT!$F$4:$I$64),MATCH(DATEDIF(D20,DATE($X$4,$W$4,$V$4),"m"),CCTT!$A$4:$A$64,0),0)),CCTT!$B$3:$E$3),LOOKUP(2,1/(I20>=INDEX(IF(E20="x",CCTT!$B$70:$E$93,CCTT!$F$70:$I$93),MATCH(DATEDIF(D20,DATE($X$4,$W$4,$V$4),"m"),CCTT!$A$70:$A$93,0),0)),CCTT!B$69:E$69)) -> bt | K20: =IF(DATEDIF(D20,DATE($X$4,$W$4,$V$4),"m")<24,LOOKUP(2,1/(G20>=INDEX(IF(E20="x",CNTCC!$B$4:$F$134,CNTCC!$F$4),MATCH(I20,CNTCC!$A$4:$A$134,0),0)),CNTCC!$B$3:$F$3),IF(AND(DATEDIF(D20,DATE($X$4,$W$4,$V$4),"m")>=24,DATEDIF(D20,DATE($X$4,$W$4,$V$4),"m")<=60),LOOKUP(2,1/(G20>=INDEX(IF(E20="x",CNTCC!$B$141:$F$251,CNTCC!$G$141:$K$251),MATCH(I20,CNTCC!$A$141:$A$251,0),0)),CNTCC!$B$140:$F$140),0)) -> bt | L20: Bt | M20: Bt | N20: Bt | O20: Bt | P20: Bt | Q20: Bt | R20: I | S20: =PROPER(B20) -> Trần Chí | T20: =DATEDIF(D20,DATE($X$4,$W$4,$V$4),"m") -> 20 | U20: =G20/(I20/100)^2 -> 17.419074
A21: 12 | B21: Võ Thành | C21: Trí | D21: 45564 | E21: x | G21: 11.7 | H21: =IF(DATEDIF(D21,DATE($X$4,$W$4,$V$4),"m")<=60,LOOKUP(2,1/(G21>=INDEX(IF(E21="x",CNTT!$B$4:$E$64,CNTT!$F$4:$I$64),MATCH(DATEDIF(D21,DATE($X$4,$W$4,$V$4),"m"),CNTT!$A$4:$A$64,0),0)),CNTT!$B$3:$E$3),LOOKUP(2,1/(G21>=INDEX(IF(E21="x",CNTT!$B$70:$E$93,CNTT!$F$70:$I$93),MATCH(DATEDIF(D21,DATE($X$4,$W$4,$V$4),"m"),CNTT!$A$70:$A$93,0),0)),CNTT!$B$69:$E$69)) -> bt | I21: 83 | J21: =IF(DATEDIF(D21,DATE($X$4,$W$4,$V$4),"m")<=60,LOOKUP(2,1/(I21>=INDEX(IF(E21="x",CCTT!$B$4:$E$64,CCTT!$F$4:$I$64),MATCH(DATEDIF(D21,DATE($X$4,$W$4,$V$4),"m"),CCTT!$A$4:$A$64,0),0)),CCTT!$B$3:$E$3),LOOKUP(2,1/(I21>=INDEX(IF(E21="x",CCTT!$B$70:$E$93,CCTT!$F$70:$I$93),MATCH(DATEDIF(D21,DATE($X$4,$W$4,$V$4),"m"),CCTT!$A$70:$A$93,0),0)),CCTT!B$69:E$69)) -> bt | K21: =IF(DATEDIF(D21,DATE($X$4,$W$4,$V$4),"m")<24,LOOKUP(2,1/(G21>=INDEX(IF(E21="x",CNTCC!$B$4:$F$134,CNTCC!$F$4),MATCH(I21,CNTCC!$A$4:$A$134,0),0)),CNTCC!$B$3:$F$3),IF(AND(DATEDIF(D21,DATE($X$4,$W$4,$V$4),"m")>=24,DATEDIF(D21,DATE($X$4,$W$4,$V$4),"m")<=60),LOOKUP(2,1/(G21>=INDEX(IF(E21="x",CNTCC!$B$141:$F$251,CNTCC!$G$141:$K$251),MATCH(I21,CNTCC!$A$141:$A$251,0),0)),CNTCC!$B$140:$F$140),0)) -> bt | L21: Bt | M21: Bt | N21: Bt | O21: Bt | P21: Bt | Q21: Bt | R21: I | S21: =PROPER(B21) -> Võ Thành | T21: =DATEDIF(D21,DATE($X$4,$W$4,$V$4),"m") -> 23 | U21: =G21/(I21/100)^2 -> 16.983597
A22: 13 | B22: Cao Ngọc Bảo | C22: Uyên | D22: 45624 | F22: x | G22: 11.6 | H22: =IF(DATEDIF(D22,DATE($X$4,$W$4,$V$4),"m")<=60,LOOKUP(2,1/(G22>=INDEX(IF(E22="x",CNTT!$B$4:$E$64,CNTT!$F$4:$I$64),MATCH(DATEDIF(D22,DATE($X$4,$W$4,$V$4),"m"),CNTT!$A$4:$A$64,0),0)),CNTT!$B$3:$E$3),LOOKUP(2,1/(G22>=INDEX(IF(E22="x",CNTT!$B$70:$E$93,CNTT!$F$70:$I$93),MATCH(DATEDIF(D22,DATE($X$4,$W$4,$V$4),"m"),CNTT!$A$70:$A$93,0),0)),CNTT!$B$69:$E$69)) -> bt | I22: 83 | J22: =IF(DATEDIF(D22,DATE($X$4,$W$4,$V$4),"m")<=60,LOOKUP(2,1/(I22>=INDEX(IF(E22="x",CCTT!$B$4:$E$64,CCTT!$F$4:$I$64),MATCH(DATEDIF(D22,DATE($X$4,$W$4,$V$4),"m"),CCTT!$A$4:$A$64,0),0)),CCTT!$B$3:$E$3),LOOKUP(2,1/(I22>=INDEX(IF(E22="x",CCTT!$B$70:$E$93,CCTT!$F$70:$I$93),MATCH(DATEDIF(D22,DATE($X$4,$W$4,$V$4),"m"),CCTT!$A$70:$A$93,0),0)),CCTT!B$69:E$69)) -> bt | K22: bt | L22: Bt | M22: Bt | N22: Bt | O22: Bt | P22: Bt | Q22: Bt | R22: I | S22: =PROPER(B22) -> Cao Ngọc Bảo | T22: =DATEDIF(D22,DATE($X$4,$W$4,$V$4),"m") -> 21 | U22: =G22/(I22/100)^2 -> 16.838438
D24: GHI CHÚ CHỮ VIẾT TẮT:
A26: bt | C26: : Bình thường | I26: SDDTTC | L26: : Suy dinh dưỡng thể thấp còi
A27: SDDTNC | C27: : Suy dinh dưỡng thể nhẹ cân | I27: SDDTTCMĐN | L27: : Suy dinh dưỡng thể thấp còi mức độ nặng
A28: TC | C28: : Thừa cân | I28: SDDTGC | L28: : Suy dinh dưỡng thể gầy còm
A29: BP | C29: : Béo phì | I29: SDDTGCMĐN | L29: : Suy dinh dưỡng thể gầy còm mức độ nặng
A30: CNC | C30: : Cân nặng cao | I30: CHT | L30: : Cao hơn tuổi
A31: VP | C31: : Viêm phổi | I31: VMH | L31: : Viêm mũi họng
A32: Sr | C32: : Sâu răng | I32: VMXT | L32: : Viêm mũi xuất tiết
A33: VHHT | C33: : Viêm hô hấp trên | I33: TKX | L33: : Tật khúc xa

Sheet 25-36
A1: BẢNG TỔNG HỢP KHÁM SỨC KHỎE HỌC SINH
A2: (Khám sức khỏe học sinh năm học 2026-2027 ngày 15 tháng 9 năm 2026)
V3: NGÀY CÂN ĐO
A4: TÊN ĐƠN VỊ | C4: : TRƯỜNG MẦM NON TƯ THỤC MINH ANH | J4: LỚP | K4: 25-36 THÁNG | W4: 9 | X4: 2026
A5: ĐỊA CHỈ | C5: : SỐ 15/6 TRẦN ĐƯỜNG - PHƯỜNG TÂY NHA TRANG - KHÁNH HÒA
A8: STT | B8: HỌ VÀ TÊN | D8: NGÀY SINH | E8: GIỚI TÍNH | G8: TÌNH TRẠNG DINH DƯỠNG | L8: KHÁM CHUYÊN KHOA | R8: PHÂN LOẠI SỨC KHỎE | T8: THÁNG
E9: Nam | F9: Nữ | G9: Cân nặng (kg) | H9: Kết quả | I9: Chiều cao (cm) | J9: Kết quả | K9: Cân nặng theo chiều cao | L9: NHI KHOA | M9: TAI MŨI HỌNG | N9: MẮT | O9: CƠ XƯƠNG KHỚP | P9: RĂNG HÀM MẶT | Q9: CHUYÊN KHOA KHÁC | Y9: bt | Z9: SDDTNC | AA9: CNC | AB9: bt | AC9: SDDTTC | AD9: CHT | AE9: bt | AF9: TC | AG9: BP | AH9: SDDTGC | AI9: I | AJ9: II | AK9: III
A10: 1 | B10: Nguyễn Quốc | C10: Anh | D10: 45352 | E10: x | G10: 13.2 | H10: =IF(DATEDIF(D10,DATE($X$4,$W$4,$V$4),"m")<=60,LOOKUP(2,1/(G10>=INDEX(IF(E10="x",CNTT!$B$4:$E$64,CNTT!$F$4:$I$64),MATCH(DATEDIF(D10,DATE($X$4,$W$4,$V$4),"m"),CNTT!$A$4:$A$64,0),0)),CNTT!$B$3:$E$3),LOOKUP(2,1/(G10>=INDEX(IF(E10="x",CNTT!$B$70:$E$93,CNTT!$F$70:$I$93),MATCH(DATEDIF(D10,DATE($X$4,$W$4,$V$4),"m"),CNTT!$A$70:$A$93,0),0)),CNTT!$B$69:$E$69)) -> bt | I10: 89 | J10: =IF(DATEDIF(D10,DATE($X$4,$W$4,$V$4),"m")<=60,LOOKUP(2,1/(I10>=INDEX(IF(E10="x",CCTT!$B$4:$E$64,CCTT!$F$4:$I$64),MATCH(DATEDIF(D10,DATE($X$4,$W$4,$V$4),"m"),CCTT!$A$4:$A$64,0),0)),CCTT!$B$3:$E$3),LOOKUP(2,1/(I10>=INDEX(IF(E10="x",CCTT!$B$70:$E$93,CCTT!$F$70:$I$93),MATCH(DATEDIF(D10,DATE($X$4,$W$4,$V$4),"m"),CCTT!$A$70:$A$93,0),0)),CCTT!B$69:E$69)) -> bt | K10: =IF(DATEDIF(D10,DATE($X$4,$W$4,$V$4),"m")<24,LOOKUP(2,1/(G10>=INDEX(IF(E10="x",CNTCC!$B$4:$F$134,CNTCC!$F$4),MATCH(I10,CNTCC!$A$4:$A$134,0),0)),CNTCC!$B$3:$F$3),IF(AND(DATEDIF(D10,DATE($X$4,$W$4,$V$4),"m")>=24,DATEDIF(D10,DATE($X$4,$W$4,$V$4),"m")<=60),LOOKUP(2,1/(G10>=INDEX(IF(E10="x",CNTCC!$B$141:$F$251,CNTCC!$G$141:$K$251),MATCH(I10,CNTCC!$A$141:$A$251,0),0)),CNTCC!$B$140:$F$140),0)) -> bt | L10: Bt | M10: Bt | N10: Bt | O10: Bt | P10: Bt | Q10: Bt | R10: I | S10: =PROPER(B10) -> Nguyễn Quốc | T10: =DATEDIF(D10,DATE($X$4,$W$4,$V$4),"m") -> 29 | U10: =G10/(I10/100)^2 -> 16.664563 | Y10: =COUNTIF(H10:H22,Y9) -> 13 | Z10: =COUNTIF(H10:H22,Z9) -> 0 | AA10: =COUNTIF(H10:H22,AA9) -> 0 | AB10: =COUNTIF(J10:J22,AB9) -> 11 | AC10: =COUNTIF(J10:J22,AC9) -> 2 | AD10: =COUNTIF(J10:J22,AD9) -> 0 | AE10: =COUNTIF(K10:K22,AE9) -> 13 | AF10: =COUNTIF(K10:K22,AF9) -> 0 | AG10: =COUNTIF(K10:K22,AG9) -> 0 | AH10: =COUNTIF(K10:K22,AH9) -> 0 | AI10: =COUNTIF(R10:R22,AI9) -> 11 | AJ10: =COUNTIF(R10:R22,AJ9) -> 2 | AK10: =COUNTIF(R10:R22,AK9) -> 0
A11: 2 | B11: Nguyễn Diệp | C11: Anh | D11: 45393 | F11: x | G11: 11.2 | H11: =IF(DATEDIF(D11,DATE($X$4,$W$4,$V$4),"m")<=60,LOOKUP(2,1/(G11>=INDEX(IF(E11="x",CNTT!$B$4:$E$64,CNTT!$F$4:$I$64),MATCH(DATEDIF(D11,DATE($X$4,$W$4,$V$4),"m"),CNTT!$A$4:$A$64,0),0)),CNTT!$B$3:$E$3),LOOKUP(2,1/(G11>=INDEX(IF(E11="x",CNTT!$B$70:$E$93,CNTT!$F$70:$I$93),MATCH(DATEDIF(D11,DATE($X$4,$W$4,$V$4),"m"),CNTT!$A$70:$A$93,0),0)),CNTT!$B$69:$E$69)) -> bt | I11: 82 | J11: bt | K11: =IF(DATEDIF(D11,DATE($X$4,$W$4,$V$4),"m")<24,LOOKUP(2,1/(G11>=INDEX(IF(E11="x",CNTCC!$B$4:$F$134,CNTCC!$F$4),MATCH(I11,CNTCC!$A$4:$A$134,0),0)),CNTCC!$B$3:$F$3),IF(AND(DATEDIF(D11,DATE($X$4,$W$4,$V$4),"m")>=24,DATEDIF(D11,DATE($X$4,$W$4,$V$4),"m")<=60),LOOKUP(2,1/(G11>=INDEX(IF(E11="x",CNTCC!$B$141:$F$251,CNTCC!$G$141:$K$251),MATCH(I11,CNTCC!$A$141:$A$251,0),0)),CNTCC!$B$140:$F$140),0)) -> bt | L11: Bt | M11: Bt | N11: Bt | O11: Bt | P11: Bt | Q11: Bt | R11: I | S11: =PROPER(B11) -> Nguyễn Diệp | T11: =DATEDIF(D11,DATE($X$4,$W$4,$V$4),"m") -> 28 | U11: =G11/(I11/100)^2 -> 16.656752 | Y11: =SUM(Y10:AA10) -> 13
A12: 3 | B12: Trương Gia | C12: Hưng | D12: 45380 | E12: x | G12: 12.9 | H12: =IF(DATEDIF(D12,DATE($X$4,$W$4,$V$4),"m")<=60,LOOKUP(2,1/(G12>=INDEX(IF(E12="x",CNTT!$B$4:$E$64,CNTT!$F$4:$I$64),MATCH(DATEDIF(D12,DATE($X$4,$W$4,$V$4),"m"),CNTT!$A$4:$A$64,0),0)),CNTT!$B$3:$E$3),LOOKUP(2,1/(G12>=INDEX(IF(E12="x",CNTT!$B$70:$E$93,CNTT!$F$70:$I$93),MATCH(DATEDIF(D12,DATE($X$4,$W$4,$V$4),"m"),CNTT!$A$70:$A$93,0),0)),CNTT!$B$69:$E$69)) -> bt | I12: 90 | J12: =IF(DATEDIF(D12,DATE($X$4,$W$4,$V$4),"m")<=60,LOOKUP(2,1/(I12>=INDEX(IF(E12="x",CCTT!$B$4:$E$64,CCTT!$F$4:$I$64),MATCH(DATEDIF(D12,DATE($X$4,$W$4,$V$4),"m"),CCTT!$A$4:$A$64,0),0)),CCTT!$B$3:$E$3),LOOKUP(2,1/(I12>=INDEX(IF(E12="x",CCTT!$B$70:$E$93,CCTT!$F$70:$I$93),MATCH(DATEDIF(D12,DATE($X$4,$W$4,$V$4),"m"),CCTT!$A$70:$A$93,0),0)),CCTT!B$69:E$69)) -> bt | K12: =IF(DATEDIF(D12,DATE($X$4,$W$4,$V$4),"m")<24,LOOKUP(2,1/(G12>=INDEX(IF(E12="x",CNTCC!$B$4:$F$134,CNTCC!$F$4),MATCH(I12,CNTCC!$A$4:$A$134,0),0)),CNTCC!$B$3:$F$3),IF(AND(DATEDIF(D12,DATE($X$4,$W$4,$V$4),"m")>=24,DATEDIF(D12,DATE($X$4,$W$4,$V$4),"m")<=60),LOOKUP(2,1/(G12>=INDEX(IF(E12="x",CNTCC!$B$141:$F$251,CNTCC!$G$141:$K$251),MATCH(I12,CNTCC!$A$141:$A$251,0),0)),CNTCC!$B$140:$F$140),0)) -> bt | L12: Bt | M12: Bt | N12: Bt | O12: Bt | P12: Bt | Q12: Bt | R12: I | S12: =PROPER(B12) -> Trương Gia | T12: =DATEDIF(D12,DATE($X$4,$W$4,$V$4),"m") -> 29 | U12: =G12/(I12/100)^2 -> 15.925926 | Y12: =SUM(AB10:AD10) -> 13
A13: 4 | B13: Macdonald Gia | C13: Khang | D13: 45434 | E13: x | G13: 15.2 | H13: =IF(DATEDIF(D13,DATE($X$4,$W$4,$V$4),"m")<=60,LOOKUP(2,1/(G13>=INDEX(IF(E13="x",CNTT!$B$4:$E$64,CNTT!$F$4:$I$64),MATCH(DATEDIF(D13,DATE($X$4,$W$4,$V$4),"m"),CNTT!$A$4:$A$64,0),0)),CNTT!$B$3:$E$3),LOOKUP(2,1/(G13>=INDEX(IF(E13="x",CNTT!$B$70:$E$93,CNTT!$F$70:$I$93),MATCH(DATEDIF(D13,DATE($X$4,$W$4,$V$4),"m"),CNTT!$A$70:$A$93,0),0)),CNTT!$B$69:$E$69)) -> bt | I13: 94 | J13: =IF(DATEDIF(D13,DATE($X$4,$W$4,$V$4),"m")<=60,LOOKUP(2,1/(I13>=INDEX(IF(E13="x",CCTT!$B$4:$E$64,CCTT!$F$4:$I$64),MATCH(DATEDIF(D13,DATE($X$4,$W$4,$V$4),"m"),CCTT!$A$4:$A$64,0),0)),CCTT!$B$3:$E$3),LOOKUP(2,1/(I13>=INDEX(IF(E13="x",CCTT!$B$70:$E$93,CCTT!$F$70:$I$93),MATCH(DATEDIF(D13,DATE($X$4,$W$4,$V$4),"m"),CCTT!$A$70:$A$93,0),0)),CCTT!B$69:E$69)) -> bt | K13: =IF(DATEDIF(D13,DATE($X$4,$W$4,$V$4),"m")<24,LOOKUP(2,1/(G13>=INDEX(IF(E13="x",CNTCC!$B$4:$F$134,CNTCC!$F$4),MATCH(I13,CNTCC!$A$4:$A$134,0),0)),CNTCC!$B$3:$F$3),IF(AND(DATEDIF(D13,DATE($X$4,$W$4,$V$4),"m")>=24,DATEDIF(D13,DATE($X$4,$W$4,$V$4),"m")<=60),LOOKUP(2,1/(G13>=INDEX(IF(E13="x",CNTCC!$B$141:$F$251,CNTCC!$G$141:$K$251),MATCH(I13,CNTCC!$A$141:$A$251,0),0)),CNTCC!$B$140:$F$140),0)) -> bt | L13: Bt | M13: Bt | N13: Bt | O13: Bt | P13: Bt | Q13: Bt | R13: I | S13: =PROPER(B13) -> Macdonald Gia | T13: =DATEDIF(D13,DATE($X$4,$W$4,$V$4),"m") -> 27 | U13: =G13/(I13/100)^2 -> 17.202354 | Y13: =SUM(AE10:AH10) -> 13
A14: 5 | B14: Phạm Đăng | C14: Khoa | D14: 45296 | E14: x | G14: 11.8 | H14: =IF(DATEDIF(D14,DATE($X$4,$W$4,$V$4),"m")<=60,LOOKUP(2,1/(G14>=INDEX(IF(E14="x",CNTT!$B$4:$E$64,CNTT!$F$4:$I$64),MATCH(DATEDIF(D14,DATE($X$4,$W$4,$V$4),"m"),CNTT!$A$4:$A$64,0),0)),CNTT!$B$3:$E$3),LOOKUP(2,1/(G14>=INDEX(IF(E14="x",CNTT!$B$70:$E$93,CNTT!$F$70:$I$93),MATCH(DATEDIF(D14,DATE($X$4,$W$4,$V$4),"m"),CNTT!$A$70:$A$93,0),0)),CNTT!$B$69:$E$69)) -> bt | I14: 88 | J14: =IF(DATEDIF(D14,DATE($X$4,$W$4,$V$4),"m")<=60,LOOKUP(2,1/(I14>=INDEX(IF(E14="x",CCTT!$B$4:$E$64,CCTT!$F$4:$I$64),MATCH(DATEDIF(D14,DATE($X$4,$W$4,$V$4),"m"),CCTT!$A$4:$A$64,0),0)),CCTT!$B$3:$E$3),LOOKUP(2,1/(I14>=INDEX(IF(E14="x",CCTT!$B$70:$E$93,CCTT!$F$70:$I$93),MATCH(DATEDIF(D14,DATE($X$4,$W$4,$V$4),"m"),CCTT!$A$70:$A$93,0),0)),CCTT!B$69:E$69)) -> bt | K14: =IF(DATEDIF(D14,DATE($X$4,$W$4,$V$4),"m")<24,LOOKUP(2,1/(G14>=INDEX(IF(E14="x",CNTCC!$B$4:$F$134,CNTCC!$F$4),MATCH(I14,CNTCC!$A$4:$A$134,0),0)),CNTCC!$B$3:$F$3),IF(AND(DATEDIF(D14,DATE($X$4,$W$4,$V$4),"m")>=24,DATEDIF(D14,DATE($X$4,$W$4,$V$4),"m")<=60),LOOKUP(2,1/(G14>=INDEX(IF(E14="x",CNTCC!$B$141:$F$251,CNTCC!$G$141:$K$251),MATCH(I14,CNTCC!$A$141:$A$251,0),0)),CNTCC!$B$140:$F$140),0)) -> bt | L14: Bt | M14: Bt | N14: Bt | O14: Bt | P14: Bt | Q14: Bt | R14: I | S14: =PROPER(B14) -> Phạm Đăng | T14: =DATEDIF(D14,DATE($X$4,$W$4,$V$4),"m") -> 31 | U14: =G14/(I14/100)^2 -> 15.237603 | Y14: =SUM(AI10:AK10) -> 13
A15: 6 | B15: Ngô Quân | C15: Khôi | D15: 45476 | E15: x | G15: 11.1 | H15: =IF(DATEDIF(D15,DATE($X$4,$W$4,$V$4),"m")<=60,LOOKUP(2,1/(G15>=INDEX(IF(E15="x",CNTT!$B$4:$E$64,CNTT!$F$4:$I$64),MATCH(DATEDIF(D15,DATE($X$4,$W$4,$V$4),"m"),CNTT!$A$4:$A$64,0),0)),CNTT!$B$3:$E$3),LOOKUP(2,1/(G15>=INDEX(IF(E15="x",CNTT!$B$70:$E$93,CNTT!$F$70:$I$93),MATCH(DATEDIF(D15,DATE($X$4,$W$4,$V$4),"m"),CNTT!$A$70:$A$93,0),0)),CNTT!$B$69:$E$69)) -> bt | I15: 85 | J15: =IF(DATEDIF(D15,DATE($X$4,$W$4,$V$4),"m")<=60,LOOKUP(2,1/(I15>=INDEX(IF(E15="x",CCTT!$B$4:$E$64,CCTT!$F$4:$I$64),MATCH(DATEDIF(D15,DATE($X$4,$W$4,$V$4),"m"),CCTT!$A$4:$A$64,0),0)),CCTT!$B$3:$E$3),LOOKUP(2,1/(I15>=INDEX(IF(E15="x",CCTT!$B$70:$E$93,CCTT!$F$70:$I$93),MATCH(DATEDIF(D15,DATE($X$4,$W$4,$V$4),"m"),CCTT!$A$70:$A$93,0),0)),CCTT!B$69:E$69)) -> bt | K15: =IF(DATEDIF(D15,DATE($X$4,$W$4,$V$4),"m")<24,LOOKUP(2,1/(G15>=INDEX(IF(E15="x",CNTCC!$B$4:$F$134,CNTCC!$F$4),MATCH(I15,CNTCC!$A$4:$A$134,0),0)),CNTCC!$B$3:$F$3),IF(AND(DATEDIF(D15,DATE($X$4,$W$4,$V$4),"m")>=24,DATEDIF(D15,DATE($X$4,$W$4,$V$4),"m")<=60),LOOKUP(2,1/(G15>=INDEX(IF(E15="x",CNTCC!$B$141:$F$251,CNTCC!$G$141:$K$251),MATCH(I15,CNTCC!$A$141:$A$251,0),0)),CNTCC!$B$140:$F$140),0)) -> bt | L15: Bt | M15: Bt | N15: Bt | O15: Bt | P15: Bt | Q15: Bt | R15: I | S15: =PROPER(B15) -> Ngô Quân | T15: =DATEDIF(D15,DATE($X$4,$W$4,$V$4),"m") -> 25 | U15: =G15/(I15/100)^2 -> 15.363322
A16: 7 | B16: Nguyễn Ngọc Tuệ | C16: Lâm | D16: 45502 | F16: x | G16: 9.3 | H16: =IF(DATEDIF(D16,DATE($X$4,$W$4,$V$4),"m")<=60,LOOKUP(2,1/(G16>=INDEX(IF(E16="x",CNTT!$B$4:$E$64,CNTT!$F$4:$I$64),MATCH(DATEDIF(D16,DATE($X$4,$W$4,$V$4),"m"),CNTT!$A$4:$A$64,0),0)),CNTT!$B$3:$E$3),LOOKUP(2,1/(G16>=INDEX(IF(E16="x",CNTT!$B$70:$E$93,CNTT!$F$70:$I$93),MATCH(DATEDIF(D16,DATE($X$4,$W$4,$V$4),"m"),CNTT!$A$70:$A$93,0),0)),CNTT!$B$69:$E$69)) -> bt | I16: 84 | J16: SDDTTC | K16: bt | L16: Bt | M16: Bt | N16: Bt | O16: Bt | P16: Bt | Q16: Bt | R16: II | S16: =PROPER(B16) -> Nguyễn Ngọc Tuệ | T16: =DATEDIF(D16,DATE($X$4,$W$4,$V$4),"m") -> 25 | U16: =G16/(I16/100)^2 -> 13.180272
A17: 8 | B17: Huỳnh Ngọc Phương | C17: Linh | D17: 45298 | F17: x | G17: 13.2 | H17: =IF(DATEDIF(D17,DATE($X$4,$W$4,$V$4),"m")<=60,LOOKUP(2,1/(G17>=INDEX(IF(E17="x",CNTT!$B$4:$E$64,CNTT!$F$4:$I$64),MATCH(DATEDIF(D17,DATE($X$4,$W$4,$V$4),"m"),CNTT!$A$4:$A$64,0),0)),CNTT!$B$3:$E$3),LOOKUP(2,1/(G17>=INDEX(IF(E17="x",CNTT!$B$70:$E$93,CNTT!$F$70:$I$93),MATCH(DATEDIF(D17,DATE($X$4,$W$4,$V$4),"m"),CNTT!$A$70:$A$93,0),0)),CNTT!$B$69:$E$69)) -> bt | I17: 94 | J17: =IF(DATEDIF(D17,DATE($X$4,$W$4,$V$4),"m")<=60,LOOKUP(2,1/(I17>=INDEX(IF(E17="x",CCTT!$B$4:$E$64,CCTT!$F$4:$I$64),MATCH(DATEDIF(D17,DATE($X$4,$W$4,$V$4),"m"),CCTT!$A$4:$A$64,0),0)),CCTT!$B$3:$E$3),LOOKUP(2,1/(I17>=INDEX(IF(E17="x",CCTT!$B$70:$E$93,CCTT!$F$70:$I$93),MATCH(DATEDIF(D17,DATE($X$4,$W$4,$V$4),"m"),CCTT!$A$70:$A$93,0),0)),CCTT!B$69:E$69)) -> bt | K17: =IF(DATEDIF(D17,DATE($X$4,$W$4,$V$4),"m")<24,LOOKUP(2,1/(G17>=INDEX(IF(E17="x",CNTCC!$B$4:$F$134,CNTCC!$F$4),MATCH(I17,CNTCC!$A$4:$A$134,0),0)),CNTCC!$B$3:$F$3),IF(AND(DATEDIF(D17,DATE($X$4,$W$4,$V$4),"m")>=24,DATEDIF(D17,DATE($X$4,$W$4,$V$4),"m")<=60),LOOKUP(2,1/(G17>=INDEX(IF(E17="x",CNTCC!$B$141:$F$251,CNTCC!$G$141:$K$251),MATCH(I17,CNTCC!$A$141:$A$251,0),0)),CNTCC!$B$140:$F$140),0)) -> bt | L17: Bt | M17: Bt | N17: Bt | O17: Bt | P17: Bt | Q17: Bt | R17: I | S17: =PROPER(B17) -> Huỳnh Ngọc Phương | T17: =DATEDIF(D17,DATE($X$4,$W$4,$V$4),"m") -> 31 | U17: =G17/(I17/100)^2 -> 14.938886
A18: 9 | B18: Nguyễn Quốc | C18: Nhân | D18: 45335 | E18: x | G18: 14.9 | H18: =IF(DATEDIF(D18,DATE($X$4,$W$4,$V$4),"m")<=60,LOOKUP(2,1/(G18>=INDEX(IF(E18="x",CNTT!$B$4:$E$64,CNTT!$F$4:$I$64),MATCH(DATEDIF(D18,DATE($X$4,$W$4,$V$4),"m"),CNTT!$A$4:$A$64,0),0)),CNTT!$B$3:$E$3),LOOKUP(2,1/(G18>=INDEX(IF(E18="x",CNTT!$B$70:$E$93,CNTT!$F$70:$I$93),MATCH(DATEDIF(D18,DATE($X$4,$W$4,$V$4),"m"),CNTT!$A$70:$A$93,0),0)),CNTT!$B$69:$E$69)) -> bt | I18: 94 | J18: =IF(DATEDIF(D18,DATE($X$4,$W$4,$V$4),"m")<=60,LOOKUP(2,1/(I18>=INDEX(IF(E18="x",CCTT!$B$4:$E$64,CCTT!$F$4:$I$64),MATCH(DATEDIF(D18,DATE($X$4,$W$4,$V$4),"m"),CCTT!$A$4:$A$64,0),0)),CCTT!$B$3:$E$3),LOOKUP(2,1/(I18>=INDEX(IF(E18="x",CCTT!$B$70:$E$93,CCTT!$F$70:$I$93),MATCH(DATEDIF(D18,DATE($X$4,$W$4,$V$4),"m"),CCTT!$A$70:$A$93,0),0)),CCTT!B$69:E$69)) -> bt | K18: =IF(DATEDIF(D18,DATE($X$4,$W$4,$V$4),"m")<24,LOOKUP(2,1/(G18>=INDEX(IF(E18="x",CNTCC!$B$4:$F$134,CNTCC!$F$4),MATCH(I18,CNTCC!$A$4:$A$134,0),0)),CNTCC!$B$3:$F$3),IF(AND(DATEDIF(D18,DATE($X$4,$W$4,$V$4),"m")>=24,DATEDIF(D18,DATE($X$4,$W$4,$V$4),"m")<=60),LOOKUP(2,1/(G18>=INDEX(IF(E18="x",CNTCC!$B$141:$F$251,CNTCC!$G$141:$K$251),MATCH(I18,CNTCC!$A$141:$A$251,0),0)),CNTCC!$B$140:$F$140),0)) -> bt | L18: Bt | M18: Bt | N18: Bt | O18: Bt | P18: Bt | Q18: Bt | R18: I | S18: =PROPER(B18) -> Nguyễn Quốc | T18: =DATEDIF(D18,DATE($X$4,$W$4,$V$4),"m") -> 30 | U18: =G18/(I18/100)^2 -> 16.862834
A19: 10 | B19: Phan Hoàng Anh | C19: Nhi | D19: 45403 | F19: x | G19: 11.2 | H19: =IF(DATEDIF(D19,DATE($X$4,$W$4,$V$4),"m")<=60,LOOKUP(2,1/(G19>=INDEX(IF(E19="x",CNTT!$B$4:$E$64,CNTT!$F$4:$I$64),MATCH(DATEDIF(D19,DATE($X$4,$W$4,$V$4),"m"),CNTT!$A$4:$A$64,0),0)),CNTT!$B$3:$E$3),LOOKUP(2,1/(G19>=INDEX(IF(E19="x",CNTT!$B$70:$E$93,CNTT!$F$70:$I$93),MATCH(DATEDIF(D19,DATE($X$4,$W$4,$V$4),"m"),CNTT!$A$70:$A$93,0),0)),CNTT!$B$69:$E$69)) -> bt | I19: 84 | J19: SDDTTC | K19: =IF(DATEDIF(D19,DATE($X$4,$W$4,$V$4),"m")<24,LOOKUP(2,1/(G19>=INDEX(IF(E19="x",CNTCC!$B$4:$F$134,CNTCC!$F$4),MATCH(I19,CNTCC!$A$4:$A$134,0),0)),CNTCC!$B$3:$F$3),IF(AND(DATEDIF(D19,DATE($X$4,$W$4,$V$4),"m")>=24,DATEDIF(D19,DATE($X$4,$W$4,$V$4),"m")<=60),LOOKUP(2,1/(G19>=INDEX(IF(E19="x",CNTCC!$B$141:$F$251,CNTCC!$G$141:$K$251),MATCH(I19,CNTCC!$A$141:$A$251,0),0)),CNTCC!$B$140:$F$140),0)) -> bt | L19: Bt | M19: Bt | N19: Bt | O19: Bt | P19: Bt | Q19: Bt | R19: II | S19: =PROPER(B19) -> Phan Hoàng Anh | T19: =DATEDIF(D19,DATE($X$4,$W$4,$V$4),"m") -> 28 | U19: =G19/(I19/100)^2 -> 15.873016
A20: 11 | B20: Nguyễn Huỳnh An | C20: Nhi | D20: 45329 | E20: x | G20: 11.7 | H20: =IF(DATEDIF(D20,DATE($X$4,$W$4,$V$4),"m")<=60,LOOKUP(2,1/(G20>=INDEX(IF(E20="x",CNTT!$B$4:$E$64,CNTT!$F$4:$I$64),MATCH(DATEDIF(D20,DATE($X$4,$W$4,$V$4),"m"),CNTT!$A$4:$A$64,0),0)),CNTT!$B$3:$E$3),LOOKUP(2,1/(G20>=INDEX(IF(E20="x",CNTT!$B$70:$E$93,CNTT!$F$70:$I$93),MATCH(DATEDIF(D20,DATE($X$4,$W$4,$V$4),"m"),CNTT!$A$70:$A$93,0),0)),CNTT!$B$69:$E$69)) -> bt | I20: 90 | J20: =IF(DATEDIF(D20,DATE($X$4,$W$4,$V$4),"m")<=60,LOOKUP(2,1/(I20>=INDEX(IF(E20="x",CCTT!$B$4:$E$64,CCTT!$F$4:$I$64),MATCH(DATEDIF(D20,DATE($X$4,$W$4,$V$4),"m"),CCTT!$A$4:$A$64,0),0)),CCTT!$B$3:$E$3),LOOKUP(2,1/(I20>=INDEX(IF(E20="x",CCTT!$B$70:$E$93,CCTT!$F$70:$I$93),MATCH(DATEDIF(D20,DATE($X$4,$W$4,$V$4),"m"),CCTT!$A$70:$A$93,0),0)),CCTT!B$69:E$69)) -> bt | K20: =IF(DATEDIF(D20,DATE($X$4,$W$4,$V$4),"m")<24,LOOKUP(2,1/(G20>=INDEX(IF(E20="x",CNTCC!$B$4:$F$134,CNTCC!$F$4),MATCH(I20,CNTCC!$A$4:$A$134,0),0)),CNTCC!$B$3:$F$3),IF(AND(DATEDIF(D20,DATE($X$4,$W$4,$V$4),"m")>=24,DATEDIF(D20,DATE($X$4,$W$4,$V$4),"m")<=60),LOOKUP(2,1/(G20>=INDEX(IF(E20="x",CNTCC!$B$141:$F$251,CNTCC!$G$141:$K$251),MATCH(I20,CNTCC!$A$141:$A$251,0),0)),CNTCC!$B$140:$F$140),0)) -> bt | L20: Bt | M20: Bt | N20: Bt | O20: Bt | P20: Bt | Q20: Bt | R20: I | S20: =PROPER(B20) -> Nguyễn Huỳnh An | T20: =DATEDIF(D20,DATE($X$4,$W$4,$V$4),"m") -> 30 | U20: =G20/(I20/100)^2 -> 14.444444
A21: 12 | B21: Phạm Duy | C21: Phúc | D21: 45391 | E21: x | G21: 11.2 | H21: =IF(DATEDIF(D21,DATE($X$4,$W$4,$V$4),"m")<=60,LOOKUP(2,1/(G21>=INDEX(IF(E21="x",CNTT!$B$4:$E$64,CNTT!$F$4:$I$64),MATCH(DATEDIF(D21,DATE($X$4,$W$4,$V$4),"m"),CNTT!$A$4:$A$64,0),0)),CNTT!$B$3:$E$3),LOOKUP(2,1/(G21>=INDEX(IF(E21="x",CNTT!$B$70:$E$93,CNTT!$F$70:$I$93),MATCH(DATEDIF(D21,DATE($X$4,$W$4,$V$4),"m"),CNTT!$A$70:$A$93,0),0)),CNTT!$B$69:$E$69)) -> bt | I21: 86 | J21: =IF(DATEDIF(D21,DATE($X$4,$W$4,$V$4),"m")<=60,LOOKUP(2,1/(I21>=INDEX(IF(E21="x",CCTT!$B$4:$E$64,CCTT!$F$4:$I$64),MATCH(DATEDIF(D21,DATE($X$4,$W$4,$V$4),"m"),CCTT!$A$4:$A$64,0),0)),CCTT!$B$3:$E$3),LOOKUP(2,1/(I21>=INDEX(IF(E21="x",CCTT!$B$70:$E$93,CCTT!$F$70:$I$93),MATCH(DATEDIF(D21,DATE($X$4,$W$4,$V$4),"m"),CCTT!$A$70:$A$93,0),0)),CCTT!B$69:E$69)) -> bt | K21: =IF(DATEDIF(D21,DATE($X$4,$W$4,$V$4),"m")<24,LOOKUP(2,1/(G21>=INDEX(IF(E21="x",CNTCC!$B$4:$F$134,CNTCC!$F$4),MATCH(I21,CNTCC!$A$4:$A$134,0),0)),CNTCC!$B$3:$F$3),IF(AND(DATEDIF(D21,DATE($X$4,$W$4,$V$4),"m")>=24,DATEDIF(D21,DATE($X$4,$W$4,$V$4),"m")<=60),LOOKUP(2,1/(G21>=INDEX(IF(E21="x",CNTCC!$B$141:$F$251,CNTCC!$G$141:$K$251),MATCH(I21,CNTCC!$A$141:$A$251,0),0)),CNTCC!$B$140:$F$140),0)) -> bt | L21: Bt | M21: Bt | N21: Bt | O21: Bt | P21: Bt | Q21: Bt | R21: I | S21: =PROPER(B21) -> Phạm Duy | T21: =DATEDIF(D21,DATE($X$4,$W$4,$V$4),"m") -> 28 | U21: =G21/(I21/100)^2 -> 15.143321
