Workbook

Sheet CCTT
B1: Nam | F1: Nữ
A2: Tháng tuổi | B2: SDDTTC MĐN | C2: SDDTTC | D2: bt | E2: CHT | F2: SDDTTC MĐN | G2: SDDTTC | H2: bt | I2: CHT
A3: 61 | B3: 0 | C3: 96.5 | D3: 101.1 | E3: 119.4 | F3: 0 | G3: 95.3 | H3: 100.1 | I3: 119.1
A4: 62 | B4: 0 | C4: 96.9 | D4: 101.6 | E4: 120 | F4: 0 | G4: 95.7 | H4: 100.5 | I4: 119.7
A5: 63 | B5: 0 | C5: 97.4 | D5: 102 | E5: 120.6 | F5: 0 | G5: 96.1 | H5: 101 | I5: 120.3
A6: 64 | B6: 0 | C6: 97.8 | D6: 102.5 | E6: 121.2 | F6: 0 | G6: 96.5 | H6: 101.4 | I6: 120.9
A7: 65 | B7: 0 | C7: 98.2 | D7: 103 | E7: 121.8 | F7: 0 | G7: 97 | H7: 101.9 | I7: 121.5
A8: 66 | B8: 0 | C8: 98.7 | D8: 103.4 | E8: 122.4 | F8: 0 | G8: 97.4 | H8: 102.3 | I8: 122
A9: 67 | B9: 0 | C9: 99.1 | D9: 103.9 | E9: 123 | F9: 0 | G9: 97.8 | H9: 102.7 | I9: 122.6
A10: 68 | B10: 0 | C10: 99.5 | D10: 104.3 | E10: 123.6 | F10: 0 | G10: 98.2 | H10: 103.2 | I10: 123.2
A11: 69 | B11: 0 | C11: 99.9 | D11: 104.8 | E11: 124.1 | F11: 0 | G11: 98.6 | H11: 103.6 | I11: 123.7
A12: 70 | B12: 0 | C12: 100.4 | D12: 105.2 | E12: 124.7 | F12: 0 | G12: 99 | H12: 104 | I12: 124.3
A13: 71 | B13: 0 | C13: 100.8 | D13: 105.7 | E13: 125.2 | F13: 0 | G13: 99.4 | H13: 104.5 | I13: 124.8
A14: 72 | B14: 0 | C14: 101.2 | D14: 106.1 | E14: 125.8 | F14: 0 | G14: 99.8 | H14: 104.9 | I14: 125.4
... A170: 228 | B170: 0 | C170: 154.6 | D170: 161.9 | E170: 191.1 | F170: 0 | G170: 143.5 | H170: 150.1 | I170: 176.2

Sheet BMI
B1: Nam | G1: Nữ
A2: Tháng tuổi | B2: SDDTGC MĐN | C2: SDDTGC | D2: bt | E2: TC | F2: BP | G2: SDDTGC MĐN | H2: SDDTGC | I2: bt | J2: TC | K2: BP
A3: 61 | B3: 0 | C3: 12.1 | D3: 13 | E3: 16.6 | F3: 18.3 | G3: 0 | H3: 11.8 | I3: 12.7 | J3: 16.9 | K3: 18.9
A4: 62 | B4: 0 | C4: 12.1 | D4: 13 | E4: 16.6 | F4: 18.3 | G4: 0 | H4: 11.8 | I4: 12.7 | J4: 16.9 | K4: 18.9
A5: 63 | B5: 0 | C5: 12.1 | D5: 13 | E5: 16.7 | F5: 18.3 | G5: 0 | H5: 11.8 | I5: 12.7 | J5: 16.9 | K5: 18.9
A6: 64 | B6: 0 | C6: 12.1 | D6: 13 | E6: 16.7 | F6: 18.3 | G6: 0 | H6: 11.8 | I6: 12.7 | J6: 16.9 | K6: 18.9
A7: 65 | B7: 0 | C7: 12.1 | D7: 13 | E7: 16.7 | F7: 18.3 | G7: 0 | H7: 11.7 | I7: 12.7 | J7: 16.9 | K7: 19
A8: 66 | B8: 0 | C8: 12.1 | D8: 13 | E8: 16.7 | F8: 18.4 | G8: 0 | H8: 11.7 | I8: 12.7 | J8: 16.9 | K8: 19
A9: 67 | B9: 0 | C9: 12.1 | D9: 13 | E9: 16.7 | F9: 18.4 | G9: 0 | H9: 11.7 | I9: 12.7 | J9: 16.9 | K9: 19
A10: 68 | B10: 0 | C10: 12.1 | D10: 13 | E10: 16.7 | F10: 18.4 | G10: 0 | H10: 11.7 | I10: 12.7 | J10: 17 | K10: 19.1
A11: 69 | B11: 0 | C11: 12.1 | D11: 13 | E11: 16.7 | F11: 18.4 | G11: 0 | H11: 11.7 | I11: 12.7 | J11: 17 | K11: 19.1
A12: 70 | B12: 0 | C12: 12.1 | D12: 13 | E12: 16.7 | F12: 18.5 | G12: 0 | H12: 11.7 | I12: 12.7 | J12: 17 | K12: 19.1
A13: 71 | B13: 0 | C13: 12.1 | D13: 13 | E13: 16.7 | F13: 18.5 | G13: 0 | H13: 11.7 | I13: 12.7 | J13: 17 | K13: 19.2
A14: 72 | B14: 0 | C14: 12.1 | D14: 13 | E14: 16.8 | F14: 18.5 | G14: 0 | H14: 11.7 | I14: 12.7 | J14: 17 | K14: 19.2
... A170: 228 | B170: 0 | C170: 15.9 | D170: 17.6 | E170: 25.4 | F170: 29.7 | G170: 0 | H170: 14.7 | I170: 16.5 | J170: 25 | K170: 29.7

Sheet mau chuan
A1: BẢNG TỔNG HỢP KHÁM SỨC KHỎE HỌC SINH
A2: (Khám sức khỏe học sinh năm học 2021 - 2022 ngày 03 tháng 03 năm 2022)
A4: TÊN ĐƠN VỊ | C4: : TRƯỜNG THCS CAO THẮNG – LỚP
A5: ĐỊA CHỈ | C5: : Số 429 Lương Định Của – xã Vĩnh Ngọc – thành phố Nha Trang, tỉnh Khánh Hòa
A7: STT | B7: HỌ VÀ TÊN | D7: NGÀY SINH | E7: Giới tính | G7: Lớp | H7: Ngày tháng phát hiện | I7: TÌNH TRẠNG DINH DƯỠNG | N7: Huyết áp (mmHg) | O7: Nhịp tim (l/p) | P7: Thị lực | V7: KHÁM CHUYÊN KHOA | W7: PHÂN LOẠI SỨC KHỎE | Z7: Tình trạng dinh dưỡng | AI7: Khám chuyên khoa | AM7: Phân loại sức khỏe
E8: Nam | F8: Nữ | I8: Cân nặng (kg) | J8: Chiều cao (cm) | K8: Kết quả CCTT | L8: BMI | M8: Kết quả BMI | Q8: Mắt | R8: TMH | S8: RHM | T8: Khác | Z8: SDDTTC MĐN | AA8: SDDTTC | AB8: bt | AC8: CHT | AD8: SDDTGC MĐN | AE8: SDDTGC | AF8: bt | AG8: TC | AH8: BP | AI8: MẮT | AJ8: TAI MŨI HỌNG | AK8: RĂNG HÀM MẶT | AL8: KHÁC | AM8: I | AN8: II | AO8: III
C9: =COUNTA(C10:C56) -> 0 | D9: =COUNTA(D10:D56) -> 0 | I9: =COUNTA(I10:I56) -> 0 | J9: =COUNTA(J10:J56) -> 0 | K9: =LOOKUP(2,1/(J9>=INDEX(IF(F9="x",CCTT!$F$3:$I$170,CCTT!$B$3:$E$170),MATCH(DATEDIF(D9,DATE(2022,1,3),"m"),CCTT!$A$3:$A$170,0),0)),CCTT!$F$2:$I$2) -> #N/A | L9: =(I9/J9^2)*10^4 -> #DIV/0! | M9: =LOOKUP(2,1/(L9>=INDEX(IF(F9="x",BMI!$G$3:$K$170,BMI!$B$3:$F$170),MATCH(DATEDIF(D9,DATE(2022,1,3),"m"),BMI!$A$3:$A$170,0),0)),BMI!$G$2:$K$2) -> #DIV/0! | N9: =COUNTA(N10:N56) -> 0 | O9: =COUNTA(O10:O56) -> 0 | P9: =COUNTA(P10:P56) -> 0 | Q9: =$C9-COUNTIF(Q10:Q56,"bt") -> 0 | R9: =$C9-COUNTIF(R10:R56,"bt") -> 0 | S9: =$C9-COUNTIF(S10:S56,"bt") -> 0 | T9: =$C9-COUNTIF(T10:T56,"bt") -> 0 | U9: =Q9&"; "&R9&"; "&S9&"; "&T9 -> 0; 0; 0; 0 | W9: =ROMAN(MAX(IF(OR(K9=$Z$8,M9=$AD$8,M9=$AH$8),3,IF(OR(K9=$AA$8,M9=$AE$8,M9=$AG$8),2,1)),IF(V9="bt",1,2)),0) -> #N/A
A10: 1 | K10: =LOOKUP(2,1/(J10>=INDEX(IF(F10="x",CCTT!$F$3:$I$170,CCTT!$B$3:$E$170),MATCH(DATEDIF(D10,DATE(2022,1,3),"m"),CCTT!$A$3:$A$170,0),0)),CCTT!$F$2:$I$2) -> #N/A | L10: =(I10/J10^2)*10^4 -> #DIV/0! | M10: =LOOKUP(2,1/(L10>=INDEX(IF(F10="x",BMI!$G$3:$K$170,BMI!$B$3:$F$170),MATCH(DATEDIF(D10,DATE(2022,1,3),"m"),BMI!$A$3:$A$170,0),0)),BMI!$G$2:$K$2) -> #DIV/0! | U10: =Q10&"; "&R10&"; "&S10&"; "&T10 -> ; ; ; | Y10: Số lượng | Z10: =COUNTIF($K$10:$K$56,Z8) -> 0 | AA10: =COUNTIF($K$10:$K$56,AA8) -> 0 | AB10: =COUNTIF($K$10:$K$56,AB8) -> 0 | AC10: =COUNTIF($K$10:$K$56,AC8) -> 0 | AD10: =COUNTIF($M$10:$M$56,AD8) -> 0 | AE10: =COUNTIF($M$10:$M$56,AE8) -> 0 | AF10: =COUNTIF($M$10:$M$56,AF8) -> 0 | AG10: =COUNTIF($M$10:$M$56,AG8) -> 0 | AH10: =COUNTIF($M$10:$M$56,AH8) -> 0 | AI10: =Q9 -> 0 | AJ10: =R9 -> 0 | AK10: =S9 -> 0 | AL10: =T9 -> 0 | AM10: =COUNTIF($W$10:$W$56,AM8) -> 0 | AN10: =COUNTIF($W$10:$W$56,AN8) -> 0 | AO10: =COUNTIF($W$10:$W$56,AO8) -> 0
A11: 2 | Y11: Tổng: | Z11: =SUM(Z10:AC10) -> 0
A12: 3 | Y12: Tổng: | Z12: =SUM(AD10:AH10) -> 0
A13: 4 | Y13: Tổng: | Z13: =SUM(AM10:AO10) -> 0
A14: 5
A15: 6
A16: 7
A17: 8
A18: 9
A19: 10
A20: 11
A21: 12
A22: 13
A23: 14
A24: 15
A25: 16
... A56: 47

Sheet TỔNG DS
A2: TÊN ĐƠN VỊ | C2: : TRƯỜNG THCS MAI XUÂN THƯỞNG
A3: ĐỊA CHỈ | C3: :
A5: STT | B5: HỌ VÀ TÊN | D5: NGÀY SINH | E5: Giới tính | G5: Lớp | J5: NGÀY SINH | K5: NGÀY SINH | M5: TÌNH TRẠNG DINH DƯỠNG | R5: Huyết áp (mmHg) | S5: Nhịp tim (l/p) | W5: Thị lực
E6: Nam | F6: Nữ | M6: Cân nặng (kg) | O6: Chiều cao (cm) | P6: BMI | Q6: Kết quả BMI
C7: =COUNTA(C8:C2022) -> 2015 | J7: =COUNTA(J8:J586) -> 579 | K7: =COUNTA(K8:K586) -> 579 | M7: =COUNTA(M8:M586) -> 578 | O7: =COUNTA(O8:O586) -> 578 | P7: =(M7/O7^2)*10^4 -> 17.301038 | Q7: =LOOKUP(2,1/(P7>=INDEX(IF(#REF!="x",BMI!$G$3:$K$170,BMI!$B$3:$F$170),MATCH(DATEDIF(J7,DATE(2022,2,28),"m"),BMI!$A$3:$A$170,0),0)),BMI!$G$2:$K$2) -> #REF! | R7: =COUNTA(R8:R586) -> 579 | S7: =COUNTA(S8:S586) -> 579 | W7: =COUNTA(W8:W586) -> 579
A8: 1 | B8: =LEFT(H8,LEN(H8)-LEN(C8)) -> #VALUE! | C8: =RIGHT(H8,LEN(H8)-FIND("@",SUBSTITUTE(H8," ","@",LEN(H8)-LEN(SUBSTITUTE(H8," ",""))))) -> #VALUE! | D8: =TEXT(J8,"DD/MM/YYYY") -> 17/10/2013 | E8: =IF(TRIM(L8)="Nam","X","") | F8: =IF(TRIM(L8)="Nữ","X","") | I8: 17/10/2013 | J8: 41564 | K8: 41564 | M8: 24 | N8: =O8*100 -> 138 | O8: 1.38 | P8: 12.602394 | Q8: Gầy | R8: 110/60 | S8: 80 | T8: 10;10 | U8: =REPLACE(T8,FIND(";",T8),1,"/") -> 10/10 | V8: =IF(U8="10/10",U8,"MPT "&U8) -> 10/10 | W8: 10/10;10/10
A9: 2 | B9: =LEFT(H9,LEN(H9)-LEN(C9)) -> #VALUE! | C9: =RIGHT(H9,LEN(H9)-FIND("@",SUBSTITUTE(H9," ","@",LEN(H9)-LEN(SUBSTITUTE(H9," ",""))))) -> #VALUE! | D9: =TEXT(J9,"DD/MM/YYYY") -> 27/07/2013 | E9: =IF(TRIM(L9)="Nam","X","") | F9: =IF(TRIM(L9)="Nữ","X","") | I9: 27/07/2013 | J9: 41482 | K9: 41482 | M9: 60 | N9: =O9*100 -> 159 | O9: 1.59 | P9: 23.733238 | Q9: Thừa cân | R9: 110/60 | S9: 78 | T9: 10;10 | U9: =REPLACE(T9,FIND(";",T9),1,"/") -> 10/10 | V9: =IF(U9="10/10",U9,"MPT "&U9) -> 10/10 | W9: 10/10;10/10
A10: 3 | B10: =LEFT(H10,LEN(H10)-LEN(C10)) -> #VALUE! | C10: =RIGHT(H10,LEN(H10)-FIND("@",SUBSTITUTE(H10," ","@",LEN(H10)-LEN(SUBSTITUTE(H10," ",""))))) -> #VALUE! | D10: =TEXT(J10,"DD/MM/YYYY") -> 03/01/2013 | E10: =IF(TRIM(L10)="Nam","X","") | F10: =IF(TRIM(L10)="Nữ","X","") | I10: 03/01/2013 | J10: 03/01/2013 | K10: 03/01/2013 | M10: 37 | N10: =O10*100 -> 157 | O10: 1.57 | P10: 15.010751 | Q10: B.thường | R10: 100/60 | S10: 78 | T10: 8;7 | U10: =REPLACE(T10,FIND(";",T10),1,"/") -> 8/7 | V10: =IF(U10="10/10",U10,"MPT "&U10) -> MPT 8/7 | W10: 8/10;7/10
A11: 4 | B11: =LEFT(H11,LEN(H11)-LEN(C11)) -> #VALUE! | C11: =RIGHT(H11,LEN(H11)-FIND("@",SUBSTITUTE(H11," ","@",LEN(H11)-LEN(SUBSTITUTE(H11," ",""))))) -> #VALUE! | D11: =TEXT(J11,"DD/MM/YYYY") -> 11/03/2013 | E11: =IF(TRIM(L11)="Nam","X","") | F11: =IF(TRIM(L11)="Nữ","X","") | I11: 11/03/2013 | J11: 11/03/2013 | K11: 11/03/2013 | M11: 41 | N11: =O11*100 -> 148 | O11: 1.48 | P11: 18.718042 | Q11: B.thường | R11: 110/60 | S11: 80 | T11: 10;10 | U11: =REPLACE(T11,FIND(";",T11),1,"/") -> 10/10 | V11: =IF(U11="10/10",U11,"MPT "&U11) -> 10/10 | W11: 10/10;10/10
A12: 5 | B12: =LEFT(H12,LEN(H12)-LEN(C12)) -> #VALUE! | C12: =RIGHT(H12,LEN(H12)-FIND("@",SUBSTITUTE(H12," ","@",LEN(H12)-LEN(SUBSTITUTE(H12," ",""))))) -> #VALUE! | D12: =TEXT(J12,"DD/MM/YYYY") -> 27/06/2013 | E12: =IF(TRIM(L12)="Nam","X","") | F12: =IF(TRIM(L12)="Nữ","X","") | I12: 27/06/2013 | J12: 41452 | K12: 41452 | M12: 42 | N12: =O12*100 -> 142 | O12: 1.42 | P12: 20.829201 | Q12: B.thường | R12: 110/70 | S12: 82 | T12: 5;5 | U12: =REPLACE(T12,FIND(";",T12),1,"/") -> 5/5 | V12: =IF(U12="10/10",U12,"MPT "&U12) -> MPT 5/5 | W12: 5/10;5/10
A13: 6 | B13: =LEFT(H13,LEN(H13)-LEN(C13)) -> #VALUE! | C13: =RIGHT(H13,LEN(H13)-FIND("@",SUBSTITUTE(H13," ","@",LEN(H13)-LEN(SUBSTITUTE(H13," ",""))))) -> #VALUE! | D13: =TEXT(J13,"DD/MM/YYYY") -> 15/11/2013 | E13: =IF(TRIM(L13)="Nam","X","") | F13: =IF(TRIM(L13)="Nữ","X","") | I13: 15/11/2013 | J13: 41593 | K13: 41593 | M13: 36 | N13: =O13*100 -> 135 | O13: 1.35 | P13: 19.753086 | Q13: B.thường | R13: 100/60 | S13: 84 | T13: 10;10 | U13: =REPLACE(T13,FIND(";",T13),1,"/") -> 10/10 | V13: =IF(U13="10/10",U13,"MPT "&U13) -> 10/10 | W13: 10/10;10/10
A14: 7 | B14: =LEFT(H14,LEN(H14)-LEN(C14)) -> #VALUE! | C14: =RIGHT(H14,LEN(H14)-FIND("@",SUBSTITUTE(H14," ","@",LEN(H14)-LEN(SUBSTITUTE(H14," ",""))))) -> #VALUE! | D14: =TEXT(J14,"DD/MM/YYYY") -> 31/07/2013 | E14: =IF(TRIM(L14)="Nam","X","") | F14: =IF(TRIM(L14)="Nữ","X","") | I14: 31/07/2013 | J14: 41486 | K14: 41486 | M14: 48 | N14: =O14*100 -> 150 | O14: 1.5 | P14: 21.333333 | Q14: Thừa cân | R14: 100/60 | S14: 81 | T14: 10;10 | U14: =REPLACE(T14,FIND(";",T14),1,"/") -> 10/10 | V14: =IF(U14="10/10",U14,"MPT "&U14) -> 10/10 | W14: 10/10;10/10
A15: 8 | B15: =LEFT(H15,LEN(H15)-LEN(C15)) -> #VALUE! | C15: =RIGHT(H15,LEN(H15)-FIND("@",SUBSTITUTE(H15," ","@",LEN(H15)-LEN(SUBSTITUTE(H15," ",""))))) -> #VALUE! | D15: =TEXT(J15,"DD/MM/YYYY") -> 31/01/2013 | E15: =IF(TRIM(L15)="Nam","X","") | F15: =IF(TRIM(L15)="Nữ","X","") | I15: 31/01/2013 | J15: 41305 | K15: 41305 | M15: 56 | N15: =O15*100 -> 151 | O15: 1.51 | P15: 24.560326 | Q15: Béo | R15: 110/60 | S15: 83 | T15: 10;10 | U15: =REPLACE(T15,FIND(";",T15),1,"/") -> 10/10 | V15: =IF(U15="10/10",U15,"MPT "&U15) -> 10/10 | W15: 10/10;10/10
A16: 9 | B16: =LEFT(H16,LEN(H16)-LEN(C16)) -> #VALUE! | C16: =RIGHT(H16,LEN(H16)-FIND("@",SUBSTITUTE(H16," ","@",LEN(H16)-LEN(SUBSTITUTE(H16," ",""))))) -> #VALUE! | D16: =TEXT(J16,"DD/MM/YYYY") -> 23/04/2013 | E16: =IF(TRIM(L16)="Nam","X","") | F16: =IF(TRIM(L16)="Nữ","X","") | I16: 23/04/2013 | J16: 41387 | K16: 41387 | M16: 53 | N16: =O16*100 -> 156 | O16: 1.56 | P16: 21.778435 | Q16: Thừa cân | R16: 110/60 | S16: 80 | T16: 10;10 | U16: =REPLACE(T16,FIND(";",T16),1,"/") -> 10/10 | V16: =IF(U16="10/10",U16,"MPT "&U16) -> 10/10 | W16: 10/10;10/10
A17: 10 | B17: =LEFT(H17,LEN(H17)-LEN(C17)) -> #VALUE! | C17: =RIGHT(H17,LEN(H17)-FIND("@",SUBSTITUTE(H17," ","@",LEN(H17)-LEN(SUBSTITUTE(H17," ",""))))) -> #VALUE! | D17: =TEXT(J17,"DD/MM/YYYY") -> 23/05/2013 | E17: =IF(TRIM(L17)="Nam","X","") | F17: =IF(TRIM(L17)="Nữ","X","") | I17: 23/05/2013 | J17: 41417 | K17: 41417 | M17: 49 | N17: =O17*100 -> 159 | O17: 1.59 | P17: 19.382145 | Q17: B.thường | R17: 110/60 | S17: 76 | T17: 10;10 | U17: =REPLACE(T17,FIND(";",T17),1,"/") -> 10/10 | V17: =IF(U17="10/10",U17,"MPT "&U17) -> 10/10 | W17: 10/10;10/10
A18: 11 | B18: =LEFT(H18,LEN(H18)-LEN(C18)) -> #VALUE! | C18: =RIGHT(H18,LEN(H18)-FIND("@",SUBSTITUTE(H18," ","@",LEN(H18)-LEN(SUBSTITUTE(H18," ",""))))) -> #VALUE! | D18: =TEXT(J18,"DD/MM/YYYY") -> 14/10/2013 | E18: =IF(TRIM(L18)="Nam","X","") | F18: =IF(TRIM(L18)="Nữ","X","") | I18: 14/10/2013 | J18: 41561 | K18: 41561 | M18: 45 | N18: =O18*100 -> 153 | O18: 1.53 | P18: 19.223376 | Q18: B.thường | R18: 110/60 | S18: 80 | T18: 10;10 | U18: =REPLACE(T18,FIND(";",T18),1,"/") -> 10/10 | V18: =IF(U18="10/10",U18,"MPT "&U18) -> 10/10 | W18: 10/10;10/10
A19: 12 | B19: =LEFT(H19,LEN(H19)-LEN(C19)) -> #VALUE! | C19: =RIGHT(H19,LEN(H19)-FIND("@",SUBSTITUTE(H19," ","@",LEN(H19)-LEN(SUBSTITUTE(H19," ",""))))) -> #VALUE! | D19: =TEXT(J19,"DD/MM/YYYY") -> 07/06/2013 | E19: =IF(TRIM(L19)="Nam","X","") | F19: =IF(TRIM(L19)="Nữ","X","") | I19: 07/06/2013 | J19: 07/06/2013 | K19: 07/06/2013 | M19: 47 | N19: =O19*100 -> 145 | O19: 1.45 | P19: 22.35434 | Q19: Thừa cân | R19: 110/70 | S19: 81 | T19: 10;10 | U19: =REPLACE(T19,FIND(";",T19),1,"/") -> 10/10 | V19: =IF(U19="10/10",U19,"MPT "&U19) -> 10/10 | W19: 10/10;10/10
A20: 13 | B20: =LEFT(H20,LEN(H20)-LEN(C20)) -> #VALUE! | C20: =RIGHT(H20,LEN(H20)-FIND("@",SUBSTITUTE(H20," ","@",LEN(H20)-LEN(SUBSTITUTE(H20," ",""))))) -> #VALUE! | D20: =TEXT(J20,"DD/MM/YYYY") -> 16/06/2013 | E20: =IF(TRIM(L20)="Nam","X","") | F20: =IF(TRIM(L20)="Nữ","X","") | I20: 16/06/2013 | J20: 41441 | K20: 16/06/2013 | M20: 41 | N20: =O20*100 -> 155 | O20: 1.55 | P20: 17.065557 | Q20: B.thường | R20: 120/70 | S20: 84 | T20: 10;10 | U20: =REPLACE(T20,FIND(";",T20),1,"/") -> 10/10 | V20: =IF(U20="10/10",U20,"MPT "&U20) -> 10/10 | W20: 10/10;10/10
A21: 14 | B21: =LEFT(H21,LEN(H21)-LEN(C21)) -> #VALUE! | C21: =RIGHT(H21,LEN(H21)-FIND("@",SUBSTITUTE(H21," ","@",LEN(H21)-LEN(SUBSTITUTE(H21," ",""))))) -> #VALUE! | D21: =TEXT(J21,"DD/MM/YYYY") -> 24/06/2013 | E21: =IF(TRIM(L21)="Nam","X","") | F21: =IF(TRIM(L21)="Nữ","X","") | I21: 24/06/2013 | J21: 24/06/2013 | K21: 24/06/2013 | M21: 35 | N21: =O21*100 -> 145 | O21: 1.45 | P21: 16.646849 | Q21: B.thường | R21: 110/70 | S21: 86 | T21: 10;10 | U21: =REPLACE(T21,FIND(";",T21),1,"/") -> 10/10 | V21: =IF(U21="10/10",U21,"MPT "&U21) -> 10/10 | W21: 10/10;10/10
A22: 15 | B22: =LEFT(H22,LEN(H22)-LEN(C22)) -> #VALUE! | C22: =RIGHT(H22,LEN(H22)-FIND("@",SUBSTITUTE(H22," ","@",LEN(H22)-LEN(SUBSTITUTE(H22," ",""))))) -> #VALUE! | D22: =TEXT(J22,"DD/MM/YYYY") -> 11/03/2013 | E22: =IF(TRIM(L22)="Nam","X","") | F22: =IF(TRIM(L22)="Nữ","X","") | I22: 11/03/2013 | J22: 11/03/2013 | K22: 11/03/2013 | M22: 46 | N22: =O22*100 -> 150 | O22: 1.5 | P22: 20.444444 | Q22: B.thường | R22: 120/70 | S22: 84 | T22: 10;10 | U22: =REPLACE(T22,FIND(";",T22),1,"/") -> 10/10 | V22: =IF(U22="10/10",U22,"MPT "&U22) -> 10/10 | W22: 10/10;10/10
A23: 16 | B23: =LEFT(H23,LEN(H23)-LEN(C23)) -> #VALUE! | C23: =RIGHT(H23,LEN(H23)-FIND("@",SUBSTITUTE(H23," ","@",LEN(H23)-LEN(SUBSTITUTE(H23," ",""))))) -> #VALUE! | D23: =TEXT(J23,"DD/MM/YYYY") -> 11/05/2013 | E23: =IF(TRIM(L23)="Nam","X","") | F23: =IF(TRIM(L23)="Nữ","X","") | I23: 11/05/2013 | J23: 11/05/2013 | K23: 11/05/2013 | M23: 67 | N23: =O23*100 -> 160 | O23: 1.6 | P23: 26.171875 | Q23: Béo | R23: 120/70 | S23: 83 | T23: 5;6 | U23: =REPLACE(T23,FIND(";",T23),1,"/") -> 5/6 | V23: =IF(U23="10/10",U23,"MPT "&U23) -> MPT 5/6 | W23: 5/10;6/10
A24: 17 | B24: =LEFT(H24,LEN(H24)-LEN(C24)) -> #VALUE! | C24: =RIGHT(H24,LEN(H24)-FIND("@",SUBSTITUTE(H24," ","@",LEN(H24)-LEN(SUBSTITUTE(H24," ",""))))) -> #VALUE! | D24: =TEXT(J24,"DD/MM/YYYY") -> 01/11/2013 | E24: =IF(TRIM(L24)="Nam","X","") | F24: =IF(TRIM(L24)="Nữ","X","") | I24: 01/11/2013 | J24: 01/11/2013 | K24: 01/11/2013 | M24: 28 | N24: =O24*100 -> 143 | O24: 1.43 | P24: 13.692601 | Q24: Gầy | R24: 110/70 | S24: 86 | T24: 10;10 | U24: =REPLACE(T24,FIND(";",T24),1,"/") -> 10/10 | V24: =IF(U24="10/10",U24,"MPT "&U24) -> 10/10 | W24: 10/10;10/10
A25: 18 | B25: =LEFT(H25,LEN(H25)-LEN(C25)) -> #VALUE! | C25: =RIGHT(H25,LEN(H25)-FIND("@",SUBSTITUTE(H25," ","@",LEN(H25)-LEN(SUBSTITUTE(H25," ",""))))) -> #VALUE! | D25: =TEXT(J25,"DD/MM/YYYY") -> 28/01/2013 | E25: =IF(TRIM(L25)="Nam","X","") | F25: =IF(TRIM(L25)="Nữ","X","") | I25: 28/01/2013 | J25: 28/01/2013 | K25: 28/01/2013 | M25: 30 | N25: =O25*100 -> 143 | O25: 1.43 | P25: 14.670644 | Q25: Gầy | R25: 110/70 | S25: 85 | T25: 10;10 | U25: =REPLACE(T25,FIND(";",T25),1,"/") -> 10/10 | V25: =IF(U25="10/10",U25,"MPT "&U25) -> 10/10 | W25: 10/10;10/10
A26: 19 | B26: =LEFT(H26,LEN(H26)-LEN(C26)) -> #VALUE! | C26: =RIGHT(H26,LEN(H26)-FIND("@",SUBSTITUTE(H26," ","@",LEN(H26)-LEN(SUBSTITUTE(H26," ",""))))) -> #VALUE! | D26: =TEXT(J26,"DD/MM/YYYY") -> 01/07/2013 | E26: =IF(TRIM(L26)="Nam","X","") | F26: =IF(TRIM(L26)="Nữ","X","") | I26: 01/07/2013 | J26: 01/07/2013 | K26: 01/07/2013 | M26: 65 | N26: =O26*100 -> 157 | O26: 1.57 | P26: 26.370238 | Q26: Béo | R26: 110/70 | S26: 83 | T26: 10;10 | U26: =REPLACE(T26,FIND(";",T26),1,"/") -> 10/10 | V26: =IF(U26="10/10",U26,"MPT "&U26) -> 10/10 | W26: 10/10;10/10
A27: 20 | B27: =LEFT(H27,LEN(H27)-LEN(C27)) -> #VALUE! | C27: =RIGHT(H27,LEN(H27)-FIND("@",SUBSTITUTE(H27," ","@",LEN(H27)-LEN(SUBSTITUTE(H27," ",""))))) -> #VALUE! | D27: =TEXT(J27,"DD/MM/YYYY") -> 13/07/2013 | E27: =IF(TRIM(L27)="Nam","X","") | F27: =IF(TRIM(L27)="Nữ","X","") | I27: 13/07/2013 | J27: 13/07/2013 | K27: 13/07/2013 | M27: 45 | N27: =O27*100 -> 152 | O27: 1.52 | P27: 19.477147 | Q27: B.thường | R27: 110/70 | S27: 81 | T27: 10;10 | U27: =REPLACE(T27,FIND(";",T27),1,"/") -> 10/10 | V27: =IF(U27="10/10",U27,"MPT "&U27) -> 10/10 | W27: 10/10;10/10
A28: 21 | B28: =LEFT(H28,LEN(H28)-LEN(C28)) -> #VALUE! | C28: =RIGHT(H28,LEN(H28)-FIND("@",SUBSTITUTE(H28," ","@",LEN(H28)-LEN(SUBSTITUTE(H28," ",""))))) -> #VALUE! | D28: =TEXT(J28,"DD/MM/YYYY") -> 01/07/2013 | E28: =IF(TRIM(L28)="Nam","X","") | F28: =IF(TRIM(L28)="Nữ","X","") | I28: 01/07/2013 | J28: 01/07/2013 | K28: 01/07/2013 | N28: =O28*100 -> 0 | P28: 0 | Q28: B.thường | R28: 110/70 | S28: 76 | T28: 10;10 | U28: =REPLACE(T28,FIND(";",T28),1,"/") -> 10/10 | V28: =IF(U28="10/10",U28,"MPT "&U28) -> 10/10 | W28: 10/10;10/10
A29: 22 | B29: =LEFT(H29,LEN(H29)-LEN(C29)) -> #VALUE! | C29: =RIGHT(H29,LEN(H29)-FIND("@",SUBSTITUTE(H29," ","@",LEN(H29)-LEN(SUBSTITUTE(H29," ",""))))) -> #VALUE! | D29: =TEXT(J29,"DD/MM/YYYY") -> 15/11/2013 | E29: =IF(TRIM(L29)="Nam","X","") | F29: =IF(TRIM(L29)="Nữ","X","") | I29: 15/11/2013 | J29: 15/11/2013 | K29: 15/11/2013 | M29: 32 | N29: =O29*100 -> 145 | O29: 1.45 | P29: 15.219976 | Q29: B.thường | R29: 110/60 | S29: 80 | T29: 10;10 | U29: =REPLACE(T29,FIND(";",T29),1,"/") -> 10/10 | V29: =IF(U29="10/10",U29,"MPT "&U29) -> 10/10 | W29: 10/10;10/10
A30: 23 | B30: =LEFT(H30,LEN(H30)-LEN(C30)) -> #VALUE! | C30: =RIGHT(H30,LEN(H30)-FIND("@",SUBSTITUTE(H30," ","@",LEN(H30)-LEN(SUBSTITUTE(H30," ",""))))) -> #VALUE! | D30: =TEXT(J30,"DD/MM/YYYY") -> 25/06/2013 | E30: =IF(TRIM(L30)="Nam","X","") | F30: =IF(TRIM(L30)="Nữ","X","") | I30: 25/06/2013 | J30: 25/06/2013 | K30: 25/06/2013 | M30: 56 | N30: =O30*100 -> 150 | O30: 1.5 | P30: 24.888889 | Q30: Béo | R30: 120/70 | S30: 82 | T30: 10;10 | U30: =REPLACE(T30,FIND(";",T30),1,"/") -> 10/10 | V30: =IF(U30="10/10",U30,"MPT "&U30) -> 10/10 | W30: 10/10;10/10
A31: 24 | B31: =LEFT(H31,LEN(H31)-LEN(C31)) -> #VALUE! | C31: =RIGHT(H31,LEN(H31)-FIND("@",SUBSTITUTE(H31," ","@",LEN(H31)-LEN(SUBSTITUTE(H31," ",""))))) -> #VALUE! | D31: =TEXT(J31,"DD/MM/YYYY") -> 02/01/2013 | E31: =IF(TRIM(L31)="Nam","X","") | F31: =IF(TRIM(L31)="Nữ","X","") | I31: 02/01/2013 | J31: 02/01/2013 | K31: 02/01/2013 | M31: 45 | N31: =O31*100 -> 148 | O31: 1.48 | P31: 20.544193 | Q31: B.thường | R31: 100/60 | S31: 85 | T31: 10;10 | U31: =REPLACE(T31,FIND(";",T31),1,"/") -> 10/10 | V31: =IF(U31="10/10",U31,"MPT "&U31) -> 10/10 | W31: 10/10;10/10
A32: 25 | B32: =LEFT(H32,LEN(H32)-LEN(C32)) -> #VALUE! | C32: =RIGHT(H32,LEN(H32)-FIND("@",SUBSTITUTE(H32," ","@",LEN(H32)-LEN(SUBSTITUTE(H32," ",""))))) -> #VALUE! | D32: =TEXT(J32,"DD/MM/YYYY") -> 13/09/2013 | E32: =IF(TRIM(L32)="Nam","X","") | F32: =IF(TRIM(L32)="Nữ","X","") | I32: 13/09/2013 | J32: 13/09/2013 | K32: 13/09/2013 | M32: 30 | N32: =O32*100 -> 145 | O32: 1.45 | P32: 14.268728 | Q32: Gầy | R32: 110/60 | S32: 82 | T32: 8;8 | U32: =REPLACE(T32,FIND(";",T32),1,"/") -> 8/8 | V32: =IF(U32="10/10",U32,"MPT "&U32) -> MPT 8/8 | W32: 8/10;8/10
A33: 26 | B33: =LEFT(H33,LEN(H33)-LEN(C33)) -> #VALUE! | C33: =RIGHT(H33,LEN(H33)-FIND("@",SUBSTITUTE(H33," ","@",LEN(H33)-LEN(SUBSTITUTE(H33," ",""))))) -> #VALUE! | D33: =TEXT(J33,"DD/MM/YYYY") -> 18/02/2013 | E33: =IF(TRIM(L33)="Nam","X","") | F33: =IF(TRIM(L33)="Nữ","X","") | I33: 18/02/2013 | J33: 18/02/2013 | K33: 18/02/2013 | M33: 29 | N33: =O33*100 -> 140 | O33: 1.4 | P33: 14.795918 | Q33: B.thường | R33: 110/70 | S33: 80 | T33: 10;10 | U33: =REPLACE(T33,FIND(";",T33),1,"/") -> 10/10 | V33: =IF(U33="10/10",U33,"MPT "&U33) -> 10/10 | W33: 10/10;10/10
A34: 27 | B34: =LEFT(H34,LEN(H34)-LEN(C34)) -> #VALUE! | C34: =RIGHT(H34,LEN(H34)-FIND("@",SUBSTITUTE(H34," ","@",LEN(H34)-LEN(SUBSTITUTE(H34," ",""))))) -> #VALUE! | D34: =TEXT(J34,"DD/MM/YYYY") -> 26/10/2013 | E34: =IF(TRIM(L34)="Nam","X","") | F34: =IF(TRIM(L34)="Nữ","X","") | I34: 26/10/2013 | J34: 26/10/2013 | K34: 26/10/2013 | M34: 30 | N34: =O34*100 -> 143 | O34: 1.43 | P34: 14.670644 | Q34: B.thường | R34: 120/70 | S34: 68 | T34: 10;10 | U34: =REPLACE(T34,FIND(";",T34),1,"/") -> 10/10 | V34: =IF(U34="10/10",U34,"MPT "&U34) -> 10/10 | W34: 10/10;10/10
A35: 28 | B35: =LEFT(H35,LEN(H35)-LEN(C35)) -> #VALUE! | C35: =RIGHT(H35,LEN(H35)-FIND("@",SUBSTITUTE(H35," ","@",LEN(H35)-LEN(SUBSTITUTE(H35," ",""))))) -> #VALUE! | D35: =TEXT(J35,"DD/MM/YYYY") -> 26/10/2013 | E35: =IF(TRIM(L35)="Nam","X","") | F35: =IF(TRIM(L35)="Nữ","X","") | I35: 26/10/2013 | J35: 26/10/2013 | K35: 26/10/2013 | M35: 42 | N35: =O35*100 -> 155 | O35: 1.55 | P35: 17.48179 | Q35: B.thường | R35: 100/60 | S35: 72 | T35: 10;10 | U35: =REPLACE(T35,FIND(";",T35),1,"/") -> 10/10 | V35: =IF(U35="10/10",U35,"MPT "&U35) -> 10/10 | W35: 10/10;10/10
A36: 29 | B36: =LEFT(H36,LEN(H36)-LEN(C36)) -> #VALUE! | C36: =RIGHT(H36,LEN(H36)-FIND("@",SUBSTITUTE(H36," ","@",LEN(H36)-LEN(SUBSTITUTE(H36," ",""))))) -> #VALUE! | D36: =TEXT(J36,"DD/MM/YYYY") -> 04/05/2013 | E36: =IF(TRIM(L36)="Nam","X","") | F36: =IF(TRIM(L36)="Nữ","X","") | I36: 04/05/2013 | J36: 04/05/2013 | K36: 04/05/2013 | M36: 38 | N36: =O36*100 -> 140 | O36: 1.4 | P36: 19.387755 | Q36: B.thường | R36: 100/60 | S36: 79 | T36: 7;5 | U36: =REPLACE(T36,FIND(";",T36),1,"/") -> 7/5 | V36: =IF(U36="10/10",U36,"MPT "&U36) -> MPT 7/5 | W36: 7/10;5/10
A37: 30 | B37: =LEFT(H37,LEN(H37)-LEN(C37)) -> #VALUE! | C37: =RIGHT(H37,LEN(H37)-FIND("@",SUBSTITUTE(H37," ","@",LEN(H37)-LEN(SUBSTITUTE(H37," ",""))))) -> #VALUE! | D37: =TEXT(J37,"DD/MM/YYYY") -> 13/12/2013 | E37: =IF(TRIM(L37)="Nam","X","") | F37: =IF(TRIM(L37)="Nữ","X","") | I37: 13/12/2013 | J37: 13/12/2013 | K37: 13/12/2013 | M37: 37 | N37: =O37*100 -> 157 | O37: 1.57 | P37: 15.010751 | Q37: B.thường | R37: 110/70 | S37: 82 | T37: 8;8 | U37: =REPLACE(T37,FIND(";",T37),1,"/") -> 8/8 | V37: =IF(U37="10/10",U37,"MPT "&U37) -> MPT 8/8 | W37: 8/10;8/10
A38: 31 | B38: =LEFT(H38,LEN(H38)-LEN(C38)) -> #VALUE! | C38: =RIGHT(H38,LEN(H38)-FIND("@",SUBSTITUTE(H38," ","@",LEN(H38)-LEN(SUBSTITUTE(H38," ",""))))) -> #VALUE! | D38: =TEXT(J38,"DD/MM/YYYY") -> 05/07/2013 | E38: =IF(TRIM(L38)="Nam","X","") | F38: =IF(TRIM(L38)="Nữ","X","") | I38: 05/07/2013 | J38: 05/07/2013 | K38: 05/07/2013 | M38: 29 | N38: =O38*100 -> 130 | O38: 1.3 | P38: 17.159763 | Q38: B.thường | R38: 110/70 | S38: 84 | T38: 7;7 | U38: =REPLACE(T38,FIND(";",T38),1,"/") -> 7/7 | V38: =IF(U38="10/10",U38,"MPT "&U38) -> MPT 7/7 | W38: 7/10;7/10
A39: 32 | B39: =LEFT(H39,LEN(H39)-LEN(C39)) -> #VALUE! | C39: =RIGHT(H39,LEN(H39)-FIND("@",SUBSTITUTE(H39," ","@",LEN(H39)-LEN(SUBSTITUTE(H39," ",""))))) -> #VALUE! | D39: =TEXT(J39,"DD/MM/YYYY") -> 02/10/2013 | E39: =IF(TRIM(L39)="Nam","X","") | F39: =IF(TRIM(L39)="Nữ","X","") | I39: 02/10/2013 | J39: 02/10/2013 | K39: 02/10/2013 | M39: 62 | N39: =O39*100 -> 145 | O39: 1.45 | P39: 29.488704 | Q39: Béo | R39: 110/60 | S39: 78 | T39: 10;10 | U39: =REPLACE(T39,FIND(";",T39),1,"/") -> 10/10 | V39: =IF(U39="10/10",U39,"MPT "&U39) -> 10/10 | W39: 10/10;10/10
A40: 33 | B40: =LEFT(H40,LEN(H40)-LEN(C40)) -> #VALUE! | C40: =RIGHT(H40,LEN(H40)-FIND("@",SUBSTITUTE(H40," ","@",LEN(H40)-LEN(SUBSTITUTE(H40," ",""))))) -> #VALUE! | D40: =TEXT(J40,"DD/MM/YYYY") -> 12/11/2009 | E40: =IF(TRIM(L40)="Nam","X","") | F40: =IF(TRIM(L40)="Nữ","X","") | I40: 12/11/2009 | J40: 12/11/2009 | K40: 12/11/2009 | M40: 36 | N40: =O40*100 -> 150 | O40: 1.5 | P40: 16 | Q40: B.thường | R40: 110/70 | S40: 78 | T40: 10;10 | U40: =REPLACE(T40,FIND(";",T40),1,"/") -> 10/10 | V40: =IF(U40="10/10",U40,"MPT "&U40) -> 10/10 | W40: 10/10;10/10
... A46: 39 | B46: =LEFT(H46,LEN(H46)-LEN(C46)) -> #VALUE! | C46: =RIGHT(H46,LEN(H46)-FIND("@",SUBSTITUTE(H46," ","@",LEN(H46)-LEN(SUBSTITUTE(H46," ",""))))) -> #VALUE! | D46: =TEXT(J46,"DD/MM/YYYY") -> 27/11/2013 | E46: =IF(TRIM(L46)="Nam","X","") | F46: =IF(TRIM(L46)="Nữ","X","") | I46: 27/11/2013 | J46: 27/11/2013 | K46: 27/11/2013 | M46: 34 | N46: =O46*100 -> 143 | O46: 1.43 | P46: 16.62673 | Q46: B.thường | R46: 100/60 | S46: 80 | T46: 10;10 | U46: =REPLACE(T46,FIND(";",T46),1,"/") -> 10/10 | V46: =IF(U46="10/10",U46,"MPT "&U46) -> 10/10 | W46: 10/10;10/10
A47: 40 | B47: =LEFT(H47,LEN(H47)-LEN(C47)) -> #VALUE! | C47: =RIGHT(H47,LEN(H47)-FIND("@",SUBSTITUTE(H47," ","@",LEN(H47)-LEN(SUBSTITUTE(H47," ",""))))) -> #VALUE! | D47: =TEXT(J47,"DD/MM/YYYY") -> 01/04/2013 | F47: =IF(TRIM(L47)="Nữ","X","") | I47: 01/04/2013 | J47: 01/04/2013 | K47: 01/04/2013 | M47: 48 | N47: =O47*100 -> 153 | O47: 1.53 | P47: 20.504934 | Q47: B.thường | R47: 100/60 | S47: 79 | T47: 10;10 | U47: =REPLACE(T47,FIND(";",T47),1,"/") -> 10/10 | V47: =IF(U47="10/10",U47,"MPT "&U47) -> 10/10 | W47: 10/10;10/10
...

Sheet TỔNG
A1: BẢNG TỔNG HỢP KHÁM SỨC KHỎE HỌC SINH
A2: 22
A4: TÊN ĐƠN VỊ | C4: : TRƯỜNG THCS NGUYỄN ĐÌNH CHIỂU | K4: 1
A5: ĐỊA CHỈ | C5: : xã Vĩnh Trung – thành phố Nha Trang, tỉnh Khánh Hòa
A7: STT | B7: HỌ VÀ TÊN | D7: NGÀY SINH | E7: Giới tính | G7: Lớp | H7: Ngày tháng phát hiện | I7: TÌNH TRẠNG DINH DƯỠNG | N7: Huyết áp (mmHg) | O7: Nhịp tim (l/p) | P7: Thị lực | V7: KHÁM CHUYÊN KHOA | W7: PHÂN LOẠI SỨC KHỎE | Z7: Tình trạng dinh dưỡng | AI7: Khám chuyên khoa | AM7: Phân loại sức khỏe
E8: Nam | F8: Nữ | I8: Cân nặng (kg) | J8: Chiều cao (cm) | K8: Kết quả CCTT | L8: BMI | M8: Kết quả BMI | Q8: Mắt | R8: TMH | S8: RHM | T8: Khác | Z8: SDDTTC MĐN | AA8: SDDTTC | AB8: bt | AC8: CHT | AD8: SDDTGC MĐN | AE8: SDDTGC | AF8: bt | AG8: TC | AH8: BP | AI8: MẮT | AJ8: TAI MŨI HỌNG | AK8: RĂNG HÀM MẶT | AL8: KHÁC | AM8: I | AN8: II | AO8: III
C9: =COUNTA(C10:C495) -> 486 | D9: =COUNTA(D10:D495) -> 476 | E9: =COUNTA(E10:E495) -> 267 | F9: =COUNTA(F10:F495) -> 218 | I9: =COUNTA(I10:I495) -> 411 | J9: =COUNTA(J10:J495) -> 411 | K9: =COUNTA(K10:K495) -> 486 | L9: =COUNTA(L10:L495) -> 486 | M9: =COUNTA(M10:M495) -> 486 | N9: =COUNTA(N10:N495) -> 486 | O9: =COUNTA(O10:O495) -> 486 | P9: =COUNTA(P10:P495) -> 486 | ... T9: =COUNTA(T10:T495) -> 486 | U9: =Q9&"; "&R9&"; "&S9&"; "&T9 -> 486; 486; 486; 486 | W9: =ROMAN(MAX(IF(OR(K9=$Z$8,M9=$AD$8,M9=$AH$8),3,IF(OR(K9=$AA$8,M9=$AE$8,M9=$AG$8),2,1)),IF(V9="bt",1,2)),0) -> II
A10: 1 | B10: Nguyễn Ngọc Bảo | C10: An | D10: 21/04/2018 | F10: x | G10: 1/1 | H10: 45720 | I10: 22 | J10: 126 | K10: {=LOOKUP(2,1/(J10>=INDEX(IF(F10="x",CCTT!$F$3:$I$170,CCTT!$B$3:$E$170),MATCH(DATEDIF(D10,DATE(2024,7,11),"m"),CCTT!$A$3:$A$170,0),0)),CCTT!$F$2:$I$2)} -> bt | L10: =(I10/J10^2)*10^4 -> 13.857395 | M10: {=LOOKUP(2,1/(L10>=INDEX(IF(F10="x",BMI!$G$3:$K$170,BMI!$B$3:$F$170),MATCH(DATEDIF(D10,DATE(2024,7,11),"m"),BMI!$A$3:$A$170,0),0)),BMI!$G$2:$K$2)} -> bt | N10: 80/50 | O10: 83 | P10: 10/10 | Q10: bt | R10: bt | S10: bt | T10: bt | U10: =Q10&"; "&R10&"; "&S10&"; "&T10 -> bt; bt; bt; bt | V10: bt | W10: =ROMAN(MAX(IF(OR(K10=$Z$8,M10=$AD$8,M10=$AH$8),3,IF(OR(K10=$AA$8,M10=$AE$8,M10=$AG$8),2,1)),IF(V10="bt",1,2)),0) -> I | Y10: Số lượng | Z10: =COUNTIF($K$10:$K$495,Z8) -> 72 | AA10: =COUNTIF($K$10:$K$495,AA8) -> 3 | AB10: =COUNTIF($K$10:$K$495,AB8) -> 370 | AC10: =COUNTIF($K$10:$K$495,AC8) -> 31 | AD10: =COUNTIF($M$10:$M$495,AD8) -> 13 | AE10: =COUNTIF($M$10:$M$495,AE8) -> 38 | AF10: =COUNTIF($M$10:$M$495,AF8) -> 234 | AG10: =COUNTIF($M$10:$M$495,AG8) -> 63 | AH10: =COUNTIF($M$10:$M$495,AH8) -> 56 | AI10: =Q9 -> 486 | AJ10: =R9 -> 486 | AK10: =S9 -> 486 | AL10: =T9 -> 486 | AM10: =COUNTIF($W$10:$W$495,AM8) -> 105 | AN10: =COUNTIF($W$10:$W$495,AN8) -> 228 | AO10: =COUNTIF($W$10:$W$495,AO8) -> 69
A11: =A10+1 -> 2 | B11: Phạm Thị Vân | C11: Anh | D11: 10/12/2018 | F11: x | G11: 1/1 | H11: 45720 | I11: 18 | J11: 116 | K11: {=LOOKUP(2,1/(J11>=INDEX(IF(F11="x",CCTT!$F$3:$I$170,CCTT!$B$3:$E$170),MATCH(DATEDIF(D11,DATE(2024,7,11),"m"),CCTT!$A$3:$A$170,0),0)),CCTT!$F$2:$I$2)} -> bt | L11: =(I11/J11^2)*10^4 -> 13.376932 | M11: {=LOOKUP(2,1/(L11>=INDEX(IF(F11="x",BMI!$G$3:$K$170,BMI!$B$3:$F$170),MATCH(DATEDIF(D11,DATE(2024,7,11),"m"),BMI!$A$3:$A$170,0),0)),BMI!$G$2:$K$2)} -> bt | N11: 80/40 | O11: 83 | P11: 10/10 | Q11: bt | R11: bt | S11: Đa sâu răng | T11: bt | U11: =Q11&"; "&R11&"; "&S11&"; "&T11 -> bt; bt; Đa sâu răng; bt | V11: Đa sâu răng | W11: =ROMAN(MAX(IF(OR(K11=$Z$8,M11=$AD$8,M11=$AH$8),3,IF(OR(K11=$AA$8,M11=$AE$8,M11=$AG$8),2,1)),IF(V11="bt",1,2)),0) -> II | Y11: Tổng: | Z11: =SUM(Z10:AC10) -> 476
A12: =A11+1 -> 3 | B12: Nguyễn Hà Ngọc | C12: Ánh | D12: 07/01/2018 | F12: x | G12: 1/1 | H12: 45720 | I12: 25 | J12: 126 | K12: {=LOOKUP(2,1/(J12>=INDEX(IF(F12="x",CCTT!$F$3:$I$170,CCTT!$B$3:$E$170),MATCH(DATEDIF(D12,DATE(2024,7,11),"m"),CCTT!$A$3:$A$170,0),0)),CCTT!$F$2:$I$2)} -> bt | L12: =(I12/J12^2)*10^4 -> 15.74704 | M12: {=LOOKUP(2,1/(L12>=INDEX(IF(F12="x",BMI!$G$3:$K$170,BMI!$B$3:$F$170),MATCH(DATEDIF(D12,DATE(2024,7,11),"m"),BMI!$A$3:$A$170,0),0)),BMI!$G$2:$K$2)} -> bt | N12: 80/50 | O12: 83 | P12: 10/10 | Q12: bt | R12: bt | S12: bt | T12: bt | U12: =Q12&"; "&R12&"; "&S12&"; "&T12 -> bt; bt; bt; bt | V12: bt | W12: =ROMAN(MAX(IF(OR(K12=$Z$8,M12=$AD$8,M12=$AH$8),3,IF(OR(K12=$AA$8,M12=$AE$8,M12=$AG$8),2,1)),IF(V12="bt",1,2)),0) -> I | Y12: Tổng: | Z12: =SUM(AD10:AH10) -> 404
A13: =A12+1 -> 4 | B13: Trần Nguyễn Quốc | C13: Bảo | D13: 22/03/2018 | E13: x | G13: 1/1 | H13: 45720 | I13: 23 | J13: 128 | K13: {=LOOKUP(2,1/(J13>=INDEX(IF(F13="x",CCTT!$F$3:$I$170,CCTT!$B$3:$E$170),MATCH(DATEDIF(D13,DATE(2024,7,11),"m"),CCTT!$A$3:$A$170,0),0)),CCTT!$F$2:$I$2)} -> CHT | L13: =(I13/J13^2)*10^4 -> 14.038086 | M13: {=LOOKUP(2,1/(L13>=INDEX(IF(F13="x",BMI!$G$3:$K$170,BMI!$B$3:$F$170),MATCH(DATEDIF(D13,DATE(2024,7,11),"m"),BMI!$A$3:$A$170,0),0)),BMI!$G$2:$K$2)} -> bt | N13: 85/55 | O13: 80 | P13: 10/10 | Q13: bt | R13: bt | S13: Đa sâu răng | T13: bt | U13: =Q13&"; "&R13&"; "&S13&"; "&T13 -> bt; bt; Đa sâu răng; bt | V13: Đa sâu răng | W13: =ROMAN(MAX(IF(OR(K13=$Z$8,M13=$AD$8,M13=$AH$8),3,IF(OR(K13=$AA$8,M13=$AE$8,M13=$AG$8),2,1)),IF(V13="bt",1,2)),0) -> II | Y13: Tổng: | Z13: =SUM(AM10:AO10) -> 402
A14: =A13+1 -> 5 | B14: Nguyễn Quang | C14: Châu | D14: 25/10/2018 | E14: x | G14: 1/1 | H14: 45720 | I14: 34 | J14: 124 | K14: {=LOOKUP(2,1/(J14>=INDEX(IF(F14="x",CCTT!$F$3:$I$170,CCTT!$B$3:$E$170),MATCH(DATEDIF(D14,DATE(2024,7,11),"m"),CCTT!$A$3:$A$170,0),0)),CCTT!$F$2:$I$2)} -> CHT | L14: =(I14/J14^2)*10^4 -> 22.112383 | M14: {=LOOKUP(2,1/(L14>=INDEX(IF(F14="x",BMI!$G$3:$K$170,BMI!$B$3:$F$170),MATCH(DATEDIF(D14,DATE(2024,7,11),"m"),BMI!$A$3:$A$170,0),0)),BMI!$G$2:$K$2)} -> BP | N14: 85/55 | O14: 87 | P14: MPT 6/10 | Q14: 2 mắt giảm thị lực | R14: bt | S14: bt | T14: bt | U14: =Q14&"; "&R14&"; "&S14&"; "&T14 -> 2 mắt giảm thị lực; bt; bt; bt | V14: 2 mắt giảm thị lực | W14: =ROMAN(MAX(IF(OR(K14=$Z$8,M14=$AD$8,M14=$AH$8),3,IF(OR(K14=$AA$8,M14=$AE$8,M14=$AG$8),2,1)),IF(V14="bt",1,2)),0) -> III
A15: =A14+1 -> 6 | B15: Nguyễn Hoàng Linh | C15: Đan | D15: 13/05/2018 | F15: x | G15: 1/1 | H15: 45720 | I15: 22 | J15: 126 | K15: {=LOOKUP(2,1/(J15>=INDEX(IF(F15="x",CCTT!$F$3:$I$170,CCTT!$B$3:$E$170),MATCH(DATEDIF(D15,DATE(2024,7,11),"m"),CCTT!$A$3:$A$170,0),0)),CCTT!$F$2:$I$2)} -> CHT | L15: =(I15/J15^2)*10^4 -> 13.857395 | M15: {=LOOKUP(2,1/(L15>=INDEX(IF(F15="x",BMI!$G$3:$K$170,BMI!$B$3:$F$170),MATCH(DATEDIF(D15,DATE(2024,7,11),"m"),BMI!$A$3:$A$170,0),0)),BMI!$G$2:$K$2)} -> bt | N15: 80/55 | O15: 81 | P15: 10/10 | Q15: bt | R15: bt | S15: bt | T15: bt | U15: =Q15&"; "&R15&"; "&S15&"; "&T15 -> bt; bt; bt; bt | V15: bt | W15: =ROMAN(MAX(IF(OR(K15=$Z$8,M15=$AD$8,M15=$AH$8),3,IF(OR(K15=$AA$8,M15=$AE$8,M15=$AG$8),2,1)),IF(V15="bt",1,2)),0) -> I | Z15: 50
A16: =A15+1 -> 7 | B16: Nguyễn Thị Thiên | C16: Di | D16: 04/05/2018 | F16: x | G16: 1/1 | H16: 45720 | I16: 20 | J16: 121 | K16: {=LOOKUP(2,1/(J16>=INDEX(IF(F16="x",CCTT!$F$3:$I$170,CCTT!$B$3:$E$170),MATCH(DATEDIF(D16,DATE(2024,7,11),"m"),CCTT!$A$3:$A$170,0),0)),CCTT!$F$2:$I$2)} -> bt | L16: =(I16/J16^2)*10^4 -> 13.660269 | M16: {=LOOKUP(2,1/(L16>=INDEX(IF(F16="x",BMI!$G$3:$K$170,BMI!$B$3:$F$170),MATCH(DATEDIF(D16,DATE(2024,7,11),"m"),BMI!$A$3:$A$170,0),0)),BMI!$G$2:$K$2)} -> bt | N16: 80/50 | O16: 83 | P16: 10/10 | Q16: bt | R16: bt | S16: Đa sâu răng | T16: bt | U16: =Q16&"; "&R16&"; "&S16&"; "&T16 -> bt; bt; Đa sâu răng; bt | V16: Đa sâu răng | W16: =ROMAN(MAX(IF(OR(K16=$Z$8,M16=$AD$8,M16=$AH$8),3,IF(OR(K16=$AA$8,M16=$AE$8,M16=$AG$8),2,1)),IF(V16="bt",1,2)),0) -> II | Z16: 42
A17: =A16+1 -> 8 | B17: Nguyễn Phạm Gia | C17: Hân | D17: 25/04/2018 | F17: x | G17: 1/1 | H17: 45720 | I17: 20 | J17: 120 | K17: {=LOOKUP(2,1/(J17>=INDEX(IF(F17="x",CCTT!$F$3:$I$170,CCTT!$B$3:$E$170),MATCH(DATEDIF(D17,DATE(2024,7,11),"m"),CCTT!$A$3:$A$170,0),0)),CCTT!$F$2:$I$2)} -> bt | L17: =(I17/J17^2)*10^4 -> 13.888889 | M17: {=LOOKUP(2,1/(L17>=INDEX(IF(F17="x",BMI!$G$3:$K$170,BMI!$B$3:$F$170),MATCH(DATEDIF(D17,DATE(2024,7,11),"m"),BMI!$A$3:$A$170,0),0)),BMI!$G$2:$K$2)} -> bt | N17: 80/40 | O17: 83 | P17: 10/10 | Q17: bt | R17: bt | S17: Đa sâu răng | T17: bt | U17: =Q17&"; "&R17&"; "&S17&"; "&T17 -> bt; bt; Đa sâu răng; bt | V17: Đa sâu răng | W17: =ROMAN(MAX(IF(OR(K17=$Z$8,M17=$AD$8,M17=$AH$8),3,IF(OR(K17=$AA$8,M17=$AE$8,M17=$AG$8),2,1)),IF(V17="bt",1,2)),0) -> II | Z17: 42
A18: =A17+1 -> 9 | B18: Trần Việt | C18: Hoàng | D18: 20/04/2018 | E18: x | G18: 1/1 | H18: 45720 | I18: 23 | J18: 120 | K18: {=LOOKUP(2,1/(J18>=INDEX(IF(F18="x",CCTT!$F$3:$I$170,CCTT!$B$3:$E$170),MATCH(DATEDIF(D18,DATE(2024,7,11),"m"),CCTT!$A$3:$A$170,0),0)),CCTT!$F$2:$I$2)} -> bt | L18: =(I18/J18^2)*10^4 -> 15.972222 | M18: {=LOOKUP(2,1/(L18>=INDEX(IF(F18="x",BMI!$G$3:$K$170,BMI!$B$3:$F$170),MATCH(DATEDIF(D18,DATE(2024,7,11),"m"),BMI!$A$3:$A$170,0),0)),BMI!$G$2:$K$2)} -> bt | N18: 85/45 | O18: 83 | P18: 10/10 | Q18: bt | R18: bt | S18: Đa sâu răng | T18: bt | U18: =Q18&"; "&R18&"; "&S18&"; "&T18 -> bt; bt; Đa sâu răng; bt | V18: Đa sâu răng | W18: =ROMAN(MAX(IF(OR(K18=$Z$8,M18=$AD$8,M18=$AH$8),3,IF(OR(K18=$AA$8,M18=$AE$8,M18=$AG$8),2,1)),IF(V18="bt",1,2)),0) -> II | Z18: 45
A19: =A18+1 -> 10 | B19: Nguyễn Gia | C19: Huy | D19: 17/11/2018 | E19: x | G19: 1/1 | H19: 45720 | I19: 16 | J19: 110 | K19: {=LOOKUP(2,1/(J19>=INDEX(IF(F19="x",CCTT!$F$3:$I$170,CCTT!$B$3:$E$170),MATCH(DATEDIF(D19,DATE(2024,7,11),"m"),CCTT!$A$3:$A$170,0),0)),CCTT!$F$2:$I$2)} -> bt | L19: =(I19/J19^2)*10^4 -> 13.22314 | M19: {=LOOKUP(2,1/(L19>=INDEX(IF(F19="x",BMI!$G$3:$K$170,BMI!$B$3:$F$170),MATCH(DATEDIF(D19,DATE(2024,7,11),"m"),BMI!$A$3:$A$170,0),0)),BMI!$G$2:$K$2)} -> bt | N19: 80/40 | O19: 83 | P19: MPT 5/10 | Q19: 2 mắt giảm thị lực | R19: bt | S19: Đa sâu răng | T19: bt | U19: =Q19&"; "&R19&"; "&S19&"; "&T19 -> 2 mắt giảm thị lực; bt; Đa sâu răng; bt | V19: 2 mắt giảm thị lực; Đa sâu răng | W19: =ROMAN(MAX(IF(OR(K19=$Z$8,M19=$AD$8,M19=$AH$8),3,IF(OR(K19=$AA$8,M19=$AE$8,M19=$AG$8),2,1)),IF(V19="bt",1,2)),0) -> II | Z19: 41
A20: =A19+1 -> 11 | B20: Nguyễn Minh | C20: Khang | D20: 23/12/2018 | E20: x | G20: 1/1 | H20: 45720 | I20: 20 | J20: 120 | K20: {=LOOKUP(2,1/(J20>=INDEX(IF(F20="x",CCTT!$F$3:$I$170,CCTT!$B$3:$E$170),MATCH(DATEDIF(D20,DATE(2024,7,11),"m"),CCTT!$A$3:$A$170,0),0)),CCTT!$F$2:$I$2)} -> bt | L20: =(I20/J20^2)*10^4 -> 13.888889 | M20: {=LOOKUP(2,1/(L20>=INDEX(IF(F20="x",BMI!$G$3:$K$170,BMI!$B$3:$F$170),MATCH(DATEDIF(D20,DATE(2024,7,11),"m"),BMI!$A$3:$A$170,0),0)),BMI!$G$2:$K$2)} -> bt | N20: 80/45 | O20: 79 | P20: 10/10 | Q20: bt | R20: bt | S20: bt | T20: bt | U20: =Q20&"; "&R20&"; "&S20&"; "&T20 -> bt; bt; bt; bt | V20: bt | W20: =ROMAN(MAX(IF(OR(K20=$Z$8,M20=$AD$8,M20=$AH$8),3,IF(OR(K20=$AA$8,M20=$AE$8,M20=$AG$8),2,1)),IF(V20="bt",1,2)),0) -> I | Z20: 44
A21: =A20+1 -> 12 | B21: Mai Hoàng Phúc | C21: Khang | D21: 08/10/2018 | E21: x | G21: 1/1 | H21: 45720 | I21: 21 | J21: 119 | K21: {=LOOKUP(2,1/(J21>=INDEX(IF(F21="x",CCTT!$F$3:$I$170,CCTT!$B$3:$E$170),MATCH(DATEDIF(D21,DATE(2024,7,11),"m"),CCTT!$A$3:$A$170,0),0)),CCTT!$F$2:$I$2)} -> bt | L21: =(I21/J21^2)*10^4 -> 14.829461 | M21: {=LOOKUP(2,1/(L21>=INDEX(IF(F21="x",BMI!$G$3:$K$170,BMI!$B$3:$F$170),MATCH(DATEDIF(D21,DATE(2024,7,11),"m"),BMI!$A$3:$A$170,0),0)),BMI!$G$2:$K$2)} -> bt | N21: 80/50 | O21: 82 | P21: 10/10 | Q21: bt | R21: bt | S21: Đa sâu răng | T21: bt | U21: =Q21&"; "&R21&"; "&S21&"; "&T21 -> bt; bt; Đa sâu răng; bt | V21: Đa sâu răng | W21: =ROMAN(MAX(IF(OR(K21=$Z$8,M21=$AD$8,M21=$AH$8),3,IF(OR(K21=$AA$8,M21=$AE$8,M21=$AG$8),2,1)),IF(V21="bt",1,2)),0) -> II | Z21: 51
A22: =A21+1 -> 13 | B22: Huỳnh Nhã | C22: Khiêm | D22: 03/10/2018 | F22: x | G22: 1/1 | H22: 45720 | I22: 16 | J22: 113 | K22: {=LOOKUP(2,1/(J22>=INDEX(IF(F22="x",CCTT!$F$3:$I$170,CCTT!$B$3:$E$170),MATCH(DATEDIF(D22,DATE(2024,7,11),"m"),CCTT!$A$3:$A$170,0),0)),CCTT!$F$2:$I$2)} -> bt | L22: =(I22/J22^2)*10^4 -> 12.530347 | M22: {=LOOKUP(2,1/(L22>=INDEX(IF(F22="x",BMI!$G$3:$K$170,BMI!$B$3:$F$170),MATCH(DATEDIF(D22,DATE(2024,7,11),"m"),BMI!$A$3:$A$170,0),0)),BMI!$G$2:$K$2)} -> SDDTGC | N22: 80/50 | O22: 83 | P22: 10/10 | Q22: bt | R22: bt | S22: Đa sâu răng | T22: bt | U22: =Q22&"; "&R22&"; "&S22&"; "&T22 -> bt; bt; Đa sâu răng; bt | V22: Đa sâu răng | W22: =ROMAN(MAX(IF(OR(K22=$Z$8,M22=$AD$8,M22=$AH$8),3,IF(OR(K22=$AA$8,M22=$AE$8,M22=$AG$8),2,1)),IF(V22="bt",1,2)),0) -> II | Z22: 49
A23: =A22+1 -> 14 | B23: Trần Dương Đăng | C23: Khoa | D23: 07/11/2018 | E23: x | G23: 1/1 | H23: 45720 | I23: 16 | J23: 106 | K23: {=LOOKUP(2,1/(J23>=INDEX(IF(F23="x",CCTT!$F$3:$I$170,CCTT!$B$3:$E$170),MATCH(DATEDIF(D23,DATE(2024,7,11),"m"),CCTT!$A$3:$A$170,0),0)),CCTT!$F$2:$I$2)} -> bt | L23: =(I23/J23^2)*10^4 -> 14.239943 | M23: {=LOOKUP(2,1/(L23>=INDEX(IF(F23="x",BMI!$G$3:$K$170,BMI!$B$3:$F$170),MATCH(DATEDIF(D23,DATE(2024,7,11),"m"),BMI!$A$3:$A$170,0),0)),BMI!$G$2:$K$2)} -> bt | N23: 80/50 | O23: 79 | P23: 10/10 | Q23: bt | R23: bt | S23: Đa sâu răng | T23: bt | U23: =Q23&"; "&R23&"; "&S23&"; "&T23 -> bt; bt; Đa sâu răng; bt | V23: Đa sâu răng | W23: =ROMAN(MAX(IF(OR(K23=$Z$8,M23=$AD$8,M23=$AH$8),3,IF(OR(K23=$AA$8,M23=$AE$8,M23=$AG$8),2,1)),IF(V23="bt",1,2)),0) -> II | Z23: 40
A24: =A23+1 -> 15 | B24: Nguyễn Ngọc Tường | C24: Lam | D24: 15/07/2018 | F24: x | G24: 1/1 | H24: 45720 | I24: 17 | J24: 116 | K24: {=LOOKUP(2,1/(J24>=INDEX(IF(F24="x",CCTT!$F$3:$I$170,CCTT!$B$3:$E$170),MATCH(DATEDIF(D24,DATE(2024,7,11),"m"),CCTT!$A$3:$A$170,0),0)),CCTT!$F$2:$I$2)} -> bt | L24: =(I24/J24^2)*10^4 -> 12.633769 | M24: {=LOOKUP(2,1/(L24>=INDEX(IF(F24="x",BMI!$G$3:$K$170,BMI!$B$3:$F$170),MATCH(DATEDIF(D24,DATE(2024,7,11),"m"),BMI!$A$3:$A$170,0),0)),BMI!$G$2:$K$2)} -> SDDTGC | N24: 80/50 | O24: 83 | P24: MPT 8/10 | Q24: 2 mắt giảm thị lực | R24: bt | S24: Đa sâu răng | T24: bt | U24: =Q24&"; "&R24&"; "&S24&"; "&T24 -> 2 mắt giảm thị lực; bt; Đa sâu răng; bt | V24: 2 mắt giảm thị lực; Đa sâu răng | W24: =ROMAN(MAX(IF(OR(K24=$Z$8,M24=$AD$8,M24=$AH$8),3,IF(OR(K24=$AA$8,M24=$AE$8,M24=$AG$8),2,1)),IF(V24="bt",1,2)),0) -> II | Z24: 43
A25: =A24+1 -> 16 | B25: Lê Ngọc Tuệ | C25: Lâm | D25: 12/09/2018 | F25: x | G25: 1/1 | H25: 45720 | I25: 19 | J25: 113 | K25: {=LOOKUP(2,1/(J25>=INDEX(IF(F25="x",CCTT!$F$3:$I$170,CCTT!$B$3:$E$170),MATCH(DATEDIF(D25,DATE(2024,7,11),"m"),CCTT!$A$3:$A$170,0),0)),CCTT!$F$2:$I$2)} -> bt | L25: =(I25/J25^2)*10^4 -> 14.879787 | M25: {=LOOKUP(2,1/(L25>=INDEX(IF(F25="x",BMI!$G$3:$K$170,BMI!$B$3:$F$170),MATCH(DATEDIF(D25,DATE(2024,7,11),"m"),BMI!$A$3:$A$170,0),0)),BMI!$G$2:$K$2)} -> bt | N25: 80/40 | O25: 82 | P25: 10/10 | Q25: bt | R25: bt | S25: Đa sâu răng | T25: bt | U25: =Q25&"; "&R25&"; "&S25&"; "&T25 -> bt; bt; Đa sâu răng; bt | V25: Đa sâu răng | W25: =ROMAN(MAX(IF(OR(K25=$Z$8,M25=$AD$8,M25=$AH$8),3,IF(OR(K25=$AA$8,M25=$AE$8,M25=$AG$8),2,1)),IF(V25="bt",1,2)),0) -> II | Z25: 49
A26: =A25+1 -> 17 | B26: Dương Hồ Thu | C26: Ngân | D26: 31/03/2018 | F26: x | G26: 1/1 | H26: 45720 | I26: 21 | J26: 118 | K26: {=LOOKUP(2,1/(J26>=INDEX(IF(F26="x",CCTT!$F$3:$I$170,CCTT!$B$3:$E$170),MATCH(DATEDIF(D26,DATE(2024,7,11),"m"),CCTT!$A$3:$A$170,0),0)),CCTT!$F$2:$I$2)} -> bt | L26: =(I26/J26^2)*10^4 -> 15.081873 | M26: {=LOOKUP(2,1/(L26>=INDEX(IF(F26="x",BMI!$G$3:$K$170,BMI!$B$3:$F$170),MATCH(DATEDIF(D26,DATE(2024,7,11),"m"),BMI!$A$3:$A$170,0),0)),BMI!$G$2:$K$2)} -> bt | N26: 80/50 | O26: 84 | P26: 10/10 | Q26: bt | R26: bt | S26: Đa sâu răng | T26: bt | U26: =Q26&"; "&R26&"; "&S26&"; "&T26 -> bt; bt; Đa sâu răng; bt | V26: Đa sâu răng | W26: =ROMAN(MAX(IF(OR(K26=$Z$8,M26=$AD$8,M26=$AH$8),3,IF(OR(K26=$AA$8,M26=$AE$8,M26=$AG$8),2,1)),IF(V26="bt",1,2)),0) -> II | Z26: 49
A27: =A26+1 -> 18 | B27: Ly Khả | C27: Ngân | D27: 11/02/2018 | F27: x | G27: 1/1 | H27: 45720 | I27: 22 | J27: 128 | K27: {=LOOKUP(2,1/(J27>=INDEX(IF(F27="x",CCTT!$F$3:$I$170,CCTT!$B$3:$E$170),MATCH(DATEDIF(D27,DATE(2024,7,11),"m"),CCTT!$A$3:$A$170,0),0)),CCTT!$F$2:$I$2)} -> CHT | L27: =(I27/J27^2)*10^4 -> 13.427734 | M27: {=LOOKUP(2,1/(L27>=INDEX(IF(F27="x",BMI!$G$3:$K$170,BMI!$B$3:$F$170),MATCH(DATEDIF(D27,DATE(2024,7,11),"m"),BMI!$A$3:$A$170,0),0)),BMI!$G$2:$K$2)} -> bt | N27: 80/55 | O27: 83 | P27: 10/10 | Q27: bt | R27: bt | S27: Đa sâu răng | T27: bt | U27: =Q27&"; "&R27&"; "&S27&"; "&T27 -> bt; bt; Đa sâu răng; bt | V27: Đa sâu răng | W27: =ROMAN(MAX(IF(OR(K27=$Z$8,M27=$AD$8,M27=$AH$8),3,IF(OR(K27=$AA$8,M27=$AE$8,M27=$AG$8),2,1)),IF(V27="bt",1,2)),0) -> II | Z27: 47
A28: =A27+1 -> 19 | B28: Mai Hoàng Yến | C28: Nhi | D28: 11/03/2018 | F28: x | G28: 1/1 | H28: 45720 | I28: 22 | J28: 115 | K28: {=LOOKUP(2,1/(J28>=INDEX(IF(F28="x",CCTT!$F$3:$I$170,CCTT!$B$3:$E$170),MATCH(DATEDIF(D28,DATE(2024,7,11),"m"),CCTT!$A$3:$A$170,0),0)),CCTT!$F$2:$I$2)} -> bt | L28: =(I28/J28^2)*10^4 -> 16.635161 | M28: {=LOOKUP(2,1/(L28>=INDEX(IF(F28="x",BMI!$G$3:$K$170,BMI!$B$3:$F$170),MATCH(DATEDIF(D28,DATE(2024,7,11),"m"),BMI!$A$3:$A$170,0),0)),BMI!$G$2:$K$2)} -> bt | N28: 90/60 | O28: 87 | P28: 10/10 | Q28: bt | R28: bt | S28: Đa sâu răng | T28: bt | U28: =Q28&"; "&R28&"; "&S28&"; "&T28 -> bt; bt; Đa sâu răng; bt | V28: Đa sâu răng | W28: =ROMAN(MAX(IF(OR(K28=$Z$8,M28=$AD$8,M28=$AH$8),3,IF(OR(K28=$AA$8,M28=$AE$8,M28=$AG$8),2,1)),IF(V28="bt",1,2)),0) -> II | Z28: 49
A29: =A28+1 -> 20 | B29: Trần Mai Đình | C29: Phát | D29: 13/09/2018 | E29: x | G29: 1/1 | H29: 45720 | I29: 22 | J29: 124 | K29: {=LOOKUP(2,1/(J29>=INDEX(IF(F29="x",CCTT!$F$3:$I$170,CCTT!$B$3:$E$170),MATCH(DATEDIF(D29,DATE(2024,7,11),"m"),CCTT!$A$3:$A$170,0),0)),CCTT!$F$2:$I$2)} -> bt | L29: =(I29/J29^2)*10^4 -> 14.308012 | M29: {=LOOKUP(2,1/(L29>=INDEX(IF(F29="x",BMI!$G$3:$K$170,BMI!$B$3:$F$170),MATCH(DATEDIF(D29,DATE(2024,7,11),"m"),BMI!$A$3:$A$170,0),0)),BMI!$G$2:$K$2)} -> bt | N29: 85/50 | O29: 83 | P29: 10/10 | Q29: bt | R29: Viêm mũi họng | S29: Đa sâu răng | T29: bt | U29: =Q29&"; "&R29&"; "&S29&"; "&T29 -> bt; Viêm mũi họng; Đa sâu răng; bt | V29: Viêm mũi họng; Đa sâu răng | W29: =ROMAN(MAX(IF(OR(K29=$Z$8,M29=$AD$8,M29=$AH$8),3,IF(OR(K29=$AA$8,M29=$AE$8,M29=$AG$8),2,1)),IF(V29="bt",1,2)),0) -> II | Z29: 47
A30: =A29+1 -> 21 | B30: Huỳnh Nguyễn Long | C30: Phi | D30: 06/08/2018 | E30: x | G30: 1/1 | H30: 45720 | I30: 24 | J30: 124 | K30: {=LOOKUP(2,1/(J30>=INDEX(IF(F30="x",CCTT!$F$3:$I$170,CCTT!$B$3:$E$170),MATCH(DATEDIF(D30,DATE(2024,7,11),"m"),CCTT!$A$3:$A$170,0),0)),CCTT!$F$2:$I$2)} -> bt | L30: =(I30/J30^2)*10^4 -> 15.608741 | M30: {=LOOKUP(2,1/(L30>=INDEX(IF(F30="x",BMI!$G$3:$K$170,BMI!$B$3:$F$170),MATCH(DATEDIF(D30,DATE(2024,7,11),"m"),BMI!$A$3:$A$170,0),0)),BMI!$G$2:$K$2)} -> bt | N30: 85/55 | O30: 83 | P30: MPT 7/10 | Q30: 2 mắt giảm thị lực | R30: bt | S30: bt | T30: bt | U30: =Q30&"; "&R30&"; "&S30&"; "&T30 -> 2 mắt giảm thị lực; bt; bt; bt | V30: 2 mắt giảm thị lực | W30: =ROMAN(MAX(IF(OR(K30=$Z$8,M30=$AD$8,M30=$AH$8),3,IF(OR(K30=$AA$8,M30=$AE$8,M30=$AG$8),2,1)),IF(V30="bt",1,2)),0) -> II | Z30: 40
A31: =A30+1 -> 22 | B31: Nguyễn Hà | C31: Phương | D31: 06/05/2018 | F31: x | G31: 1/1 | H31: 45720 | I31: 24 | J31: 127 | K31: {=LOOKUP(2,1/(J31>=INDEX(IF(F31="x",CCTT!$F$3:$I$170,CCTT!$B$3:$E$170),MATCH(DATEDIF(D31,DATE(2024,7,11),"m"),CCTT!$A$3:$A$170,0),0)),CCTT!$F$2:$I$2)} -> CHT | L31: =(I31/J31^2)*10^4 -> 14.88003 | M31: {=LOOKUP(2,1/(L31>=INDEX(IF(F31="x",BMI!$G$3:$K$170,BMI!$B$3:$F$170),MATCH(DATEDIF(D31,DATE(2024,7,11),"m"),BMI!$A$3:$A$170,0),0)),BMI!$G$2:$K$2)} -> bt | N31: 80/50 | O31: 83 | P31: 10/10 | Q31: bt | R31: bt | S31: bt | T31: bt | U31: =Q31&"; "&R31&"; "&S31&"; "&T31 -> bt; bt; bt; bt | V31: bt | W31: =ROMAN(MAX(IF(OR(K31=$Z$8,M31=$AD$8,M31=$AH$8),3,IF(OR(K31=$AA$8,M31=$AE$8,M31=$AG$8),2,1)),IF(V31="bt",1,2)),0) -> I | Z31: 1095
A32: =A31+1 -> 23 | B32: Mai Ngọc Như | C32: Quỳnh | D32: 07/12/2018 | F32: x | G32: 1/1 | H32: 45720 | I32: 17 | J32: 118 | K32: {=LOOKUP(2,1/(J32>=INDEX(IF(F32="x",CCTT!$F$3:$I$170,CCTT!$B$3:$E$170),MATCH(DATEDIF(D32,DATE(2024,7,11),"m"),CCTT!$A$3:$A$170,0),0)),CCTT!$F$2:$I$2)} -> bt | L32: =(I32/J32^2)*10^4 -> 12.209135 | M32: {=LOOKUP(2,1/(L32>=INDEX(IF(F32="x",BMI!$G$3:$K$170,BMI!$B$3:$F$170),MATCH(DATEDIF(D32,DATE(2024,7,11),"m"),BMI!$A$3:$A$170,0),0)),BMI!$G$2:$K$2)} -> SDDTGC | N32: 80/40 | O32: 84 | P32: 10/10 | Q32: bt | R32: bt | S32: Đa sâu răng | T32: bt | U32: =Q32&"; "&R32&"; "&S32&"; "&T32 -> bt; bt; Đa sâu răng; bt | V32: Đa sâu răng | W32: =ROMAN(MAX(IF(OR(K32=$Z$8,M32=$AD$8,M32=$AH$8),3,IF(OR(K32=$AA$8,M32=$AE$8,M32=$AG$8),2,1)),IF(V32="bt",1,2)),0) -> II | Z32: =SUM(Z15:Z31) -> 1823
A33: =A32+1 -> 24 | B33: Lê Trịnh Khánh | C33: Quỳnh | D33: 20/04/2017 | F33: x | G33: 1/1 | H33: 45720 | I33: 24 | J33: 130 | K33: {=LOOKUP(2,1/(J33>=INDEX(IF(F33="x",CCTT!$F$3:$I$170,CCTT!$B$3:$E$170),MATCH(DATEDIF(D33,DATE(2024,7,11),"m"),CCTT!$A$3:$A$170,0),0)),CCTT!$F$2:$I$2)} -> bt | L33: =(I33/J33^2)*10^4 -> 14.201183 | M33: {=LOOKUP(2,1/(L33>=INDEX(IF(F33="x",BMI!$G$3:$K$170,BMI!$B$3:$F$170),MATCH(DATEDIF(D33,DATE(2024,7,11),"m"),BMI!$A$3:$A$170,0),0)),BMI!$G$2:$K$2)} -> bt | N33: 85/55 | O33: 87 | P33: 10/10 ck | Q33: 2 mắt tật khúc xạ | R33: bt | S33: bt | T33: bt | U33: =Q33&"; "&R33&"; "&S33&"; "&T33 -> 2 mắt tật khúc xạ; bt; bt; bt | V33: 2 mắt tật khúc xạ | W33: =ROMAN(MAX(IF(OR(K33=$Z$8,M33=$AD$8,M33=$AH$8),3,IF(OR(K33=$AA$8,M33=$AE$8,M33=$AG$8),2,1)),IF(V33="bt",1,2)),0) -> II
A34: =A33+1 -> 25 | B34: Đinh Quốc | C34: Thiên | D34: 03/07/2018 | E34: x | G34: 1/1 | H34: 45720 | I34: 17 | J34: 119 | K34: {=LOOKUP(2,1/(J34>=INDEX(IF(F34="x",CCTT!$F$3:$I$170,CCTT!$B$3:$E$170),MATCH(DATEDIF(D34,DATE(2024,7,11),"m"),CCTT!$A$3:$A$170,0),0)),CCTT!$F$2:$I$2)} -> bt | L34: =(I34/J34^2)*10^4 -> 12.004802 | M34: {=LOOKUP(2,1/(L34>=INDEX(IF(F34="x",BMI!$G$3:$K$170,BMI!$B$3:$F$170),MATCH(DATEDIF(D34,DATE(2024,7,11),"m"),BMI!$A$3:$A$170,0),0)),BMI!$G$2:$K$2)} -> SDDTGC MĐN | N34: 80/55 | O34: 85 | P34: 10/10 | Q34: bt | R34: bt | S34: bt | T34: bt | U34: =Q34&"; "&R34&"; "&S34&"; "&T34 -> bt; bt; bt; bt | V34: bt | W34: =ROMAN(MAX(IF(OR(K34=$Z$8,M34=$AD$8,M34=$AH$8),3,IF(OR(K34=$AA$8,M34=$AE$8,M34=$AG$8),2,1)),IF(V34="bt",1,2)),0) -> III
A35: =A34+1 -> 26 | B35: Nguyễn Cao | C35: Tiến | D35: 22/10/2018 | E35: x | G35: 1/1 | H35: 45720 | I35: 18 | J35: 118 | K35: {=LOOKUP(2,1/(J35>=INDEX(IF(F35="x",CCTT!$F$3:$I$170,CCTT!$B$3:$E$170),MATCH(DATEDIF(D35,DATE(2024,7,11),"m"),CCTT!$A$3:$A$170,0),0)),CCTT!$F$2:$I$2)} -> bt | L35: =(I35/J35^2)*10^4 -> 12.92732 | M35: {=LOOKUP(2,1/(L35>=INDEX(IF(F35="x",BMI!$G$3:$K$170,BMI!$B$3:$F$170),MATCH(DATEDIF(D35,DATE(2024,7,11),"m"),BMI!$A$3:$A$170,0),0)),BMI!$G$2:$K$2)} -> SDDTGC | N35: 80/50 | O35: 83 | P35: 10/10 | Q35: bt | R35: bt | S35: bt | T35: bt | U35: =Q35&"; "&R35&"; "&S35&"; "&T35 -> bt; bt; bt; bt | V35: bt | W35: =ROMAN(MAX(IF(OR(K35=$Z$8,M35=$AD$8,M35=$AH$8),3,IF(OR(K35=$AA$8,M35=$AE$8,M35=$AG$8),2,1)),IF(V35="bt",1,2)),0) -> II
A36: =A35+1 -> 27 | B36: Võ Nhật Quỳnh | C36: Trâm | D36: 14/09/2018 | F36: x | G36: 1/1 | H36: 45720 | I36: 18 | J36: 117 | K36: {=LOOKUP(2,1/(J36>=INDEX(IF(F36="x",CCTT!$F$3:$I$170,CCTT!$B$3:$E$170),MATCH(DATEDIF(D36,DATE(2024,7,11),"m"),CCTT!$A$3:$A$170,0),0)),CCTT!$F$2:$I$2)} -> bt | L36: =(I36/J36^2)*10^4 -> 13.149244 | M36: {=LOOKUP(2,1/(L36>=INDEX(IF(F36="x",BMI!$G$3:$K$170,BMI!$B$3:$F$170),MATCH(DATEDIF(D36,DATE(2024,7,11),"m"),BMI!$A$3:$A$170,0),0)),BMI!$G$2:$K$2)} -> bt | N36: 80/45 | O36: 83 | P36: MPT 7/10 | Q36: 2 mắt giảm thị lực | R36: bt | S36: Đa sâu răng | T36: bt | U36: =Q36&"; "&R36&"; "&S36&"; "&T36 -> 2 mắt giảm thị lực; bt; Đa sâu răng; bt | V36: 2 mắt giảm thị lực; Đa sâu răng | W36: =ROMAN(MAX(IF(OR(K36=$Z$8,M36=$AD$8,M36=$AH$8),3,IF(OR(K36=$AA$8,M36=$AE$8,M36=$AG$8),2,1)),IF(V36="bt",1,2)),0) -> II
A37: =A36+1 -> 28 | B37: Nguyễn Gia Bảo | C37: Trân | D37: 43437 | F37: x | G37: 1/1 | H37: 45720 | K37: {=LOOKUP(2,1/(J37>=INDEX(IF(F37="x",CCTT!$F$3:$I$170,CCTT!$B$3:$E$170),MATCH(DATEDIF(D37,DATE(2024,7,11),"m"),CCTT!$A$3:$A$170,0),0)),CCTT!$F$2:$I$2)} -> SDDTTC MĐN | L37: =(I37/J37^2)*10^4 -> #DIV/0! | M37: {=LOOKUP(2,1/(L37>=INDEX(IF(F37="x",BMI!$G$3:$K$170,BMI!$B$3:$F$170),MATCH(DATEDIF(D37,DATE(2024,7,11),"m"),BMI!$A$3:$A$170,0),0)),BMI!$G$2:$K$2)} -> #N/A | N37: 90/60 | O37: 83 | P37: 10/10 | Q37: bt | R37: bt | S37: Đa sâu răng | T37: bt | U37: =Q37&"; "&R37&"; "&S37&"; "&T37 -> bt; bt; Đa sâu răng; bt | V37: Đa sâu răng | W37: =ROMAN(MAX(IF(OR(K37=$Z$8,M37=$AD$8,M37=$AH$8),3,IF(OR(K37=$AA$8,M37=$AE$8,M37=$AG$8),2,1)),IF(V37="bt",1,2)),0) -> #N/A
A38: =A37+1 -> 29 | B38: Nguyễn Đức | C38: Trí | D38: 28/10/2018 | E38: x | G38: 1/1 | H38: 45720 | K38: {=LOOKUP(2,1/(J38>=INDEX(IF(F38="x",CCTT!$F$3:$I$170,CCTT!$B$3:$E$170),MATCH(DATEDIF(D38,DATE(2024,7,11),"m"),CCTT!$A$3:$A$170,0),0)),CCTT!$F$2:$I$2)} -> SDDTTC MĐN | L38: =(I38/J38^2)*10^4 -> #DIV/0! | M38: {=LOOKUP(2,1/(L38>=INDEX(IF(F38="x",BMI!$G$3:$K$170,BMI!$B$3:$F$170),MATCH(DATEDIF(D38,DATE(2024,7,11),"m"),BMI!$A$3:$A$170,0),0)),BMI!$G$2:$K$2)} -> #N/A | N38: 100/60 | O38: 80 | P38: 10/10 | Q38: bt | R38: bt | S38: Đa sâu răng | T38: bt | U38: =Q38&"; "&R38&"; "&S38&"; "&T38 -> bt; bt; Đa sâu răng; bt | V38: Đa sâu răng | W38: =ROMAN(MAX(IF(OR(K38=$Z$8,M38=$AD$8,M38=$AH$8),3,IF(OR(K38=$AA$8,M38=$AE$8,M38=$AG$8),2,1)),IF(V38="bt",1,2)),0) -> #N/A
A39: =A38+1 -> 30 | B39: Đổng Quốc | C39: Trí | D39: 19/02/2018 | E39: x | G39: 1/1 | H39: 45720 | I39: 18 | J39: 114 | K39: {=LOOKUP(2,1/(J39>=INDEX(IF(F39="x",CCTT!$F$3:$I$170,CCTT!$B$3:$E$170),MATCH(DATEDIF(D39,DATE(2024,7,11),"m"),CCTT!$A$3:$A$170,0),0)),CCTT!$F$2:$I$2)} -> bt | L39: =(I39/J39^2)*10^4 -> 13.850416 | M39: {=LOOKUP(2,1/(L39>=INDEX(IF(F39="x",BMI!$G$3:$K$170,BMI!$B$3:$F$170),MATCH(DATEDIF(D39,DATE(2024,7,11),"m"),BMI!$A$3:$A$170,0),0)),BMI!$G$2:$K$2)} -> bt | N39: 80/55 | O39: 78 | P39: 10/10 | Q39: bt | R39: bt | S39: bt | T39: bt | U39: =Q39&"; "&R39&"; "&S39&"; "&T39 -> bt; bt; bt; bt | V39: bt | W39: =ROMAN(MAX(IF(OR(K39=$Z$8,M39=$AD$8,M39=$AH$8),3,IF(OR(K39=$AA$8,M39=$AE$8,M39=$AG$8),2,1)),IF(V39="bt",1,2)),0) -> I
A40: =A39+1 -> 31 | B40: Mai Hoàng Nhã | C40: Uyên | D40: 01/06/2018 | F40: x | G40: 1/1 | H40: 45720 | I40: 21 | J40: 123 | K40: {=LOOKUP(2,1/(J40>=INDEX(IF(F40="x",CCTT!$F$3:$I$170,CCTT!$B$3:$E$170),MATCH(DATEDIF(D40,DATE(2024,7,11),"m"),CCTT!$A$3:$A$170,0),0)),CCTT!$F$2:$I$2)} -> bt | L40: =(I40/J40^2)*10^4 -> 13.880627 | M40: {=LOOKUP(2,1/(L40>=INDEX(IF(F40="x",BMI!$G$3:$K$170,BMI!$B$3:$F$170),MATCH(DATEDIF(D40,DATE(2024,7,11),"m"),BMI!$A$3:$A$170,0),0)),BMI!$G$2:$K$2)} -> bt | N40: 85/45 | O40: 87 | P40: MPT9/10 | Q40: bt | R40: bt | S40: Đa sâu răng | T40: bt | U40: =Q40&"; "&R40&"; "&S40&"; "&T40 -> bt; bt; Đa sâu răng; bt | V40: Đa sâu răng | W40: =ROMAN(MAX(IF(OR(K40=$Z$8,M40=$AD$8,M40=$AH$8),3,IF(OR(K40=$AA$8,M40=$AE$8,M40=$AG$8),2,1)),IF(V40="bt",1,2)),0) -> II
A41: =A40+1 -> 32 | B41: Phạm Đăng Quốc | C41: Việt | D41: 17/06/2018 | E41: x | G41: 1/1 | H41: 45720 | I41: 18 | J41: 117 | K41: {=LOOKUP(2,1/(J41>=INDEX(IF(F41="x",CCTT!$F$3:$I$170,CCTT!$B$3:$E$170),MATCH(DATEDIF(D41,DATE(2024,7,11),"m"),CCTT!$A$3:$A$170,0),0)),CCTT!$F$2:$I$2)} -> bt | L41: =(I41/J41^2)*10^4 -> 13.149244 | M41: {=LOOKUP(2,1/(L41>=INDEX(IF(F41="x",BMI!$G$3:$K$170,BMI!$B$3:$F$170),MATCH(DATEDIF(D41,DATE(2024,7,11),"m"),BMI!$A$3:$A$170,0),0)),BMI!$G$2:$K$2)} -> bt | N41: 85/55 | O41: 82 | P41: 10/10 | Q41: bt | R41: bt | S41: Đa sâu răng | T41: bt | U41: =Q41&"; "&R41&"; "&S41&"; "&T41 -> bt; bt; Đa sâu răng; bt | V41: Đa sâu răng | W41: =ROMAN(MAX(IF(OR(K41=$Z$8,M41=$AD$8,M41=$AH$8),3,IF(OR(K41=$AA$8,M41=$AE$8,M41=$AG$8),2,1)),IF(V41="bt",1,2)),0) -> II
A42: =A41+1 -> 33 | B42: Nguyễn Tuấn | C42: Kiệt | D42: 42942 | E42: x | G42: 1/1 | H42: 45720 | I42: 20 | J42: 119 | K42: {=LOOKUP(2,1/(J42>=INDEX(IF(F42="x",CCTT!$F$3:$I$170,CCTT!$B$3:$E$170),MATCH(DATEDIF(D42,DATE(2024,7,11),"m"),CCTT!$A$3:$A$170,0),0)),CCTT!$F$2:$I$2)} -> bt | L42: =(I42/J42^2)*10^4 -> 14.123296 | M42: {=LOOKUP(2,1/(L42>=INDEX(IF(F42="x",BMI!$G$3:$K$170,BMI!$B$3:$F$170),MATCH(DATEDIF(D42,DATE(2024,7,11),"m"),BMI!$A$3:$A$170,0),0)),BMI!$G$2:$K$2)} -> bt | N42: 80/50 | O42: 82 | P42: MPT 7/10 | Q42: 2 mắt giảm thị lực | R42: Viêm tai giữa | S42: Đa sâu răng | T42: bt | U42: =Q42&"; "&R42&"; "&S42&"; "&T42 -> 2 mắt giảm thị lực; Viêm tai giữa; Đa sâu răng; bt | V42: 2 mắt giảm thị lực; Viêm tai giữa; Đa sâu răng | W42: =ROMAN(MAX(IF(OR(K42=$Z$8,M42=$AD$8,M42=$AH$8),3,IF(OR(K42=$AA$8,M42=$AE$8,M42=$AG$8),2,1)),IF(V42="bt",1,2)),0) -> II
...

Sheet BTH
A1: SỞ Y TẾ KHÁNH HÒA | M1: CỘNG HÒA XÃ HỘI CHỦ NGHĨA VIỆT NAM
A2: PHÒNG KHÁM ĐA KHOA PHÚC THIỆN NHÂN | M2: Độc lập - Tự do - Hạnh phúc
M4: Nha Trang, ngày 18 tháng 03 năm 2025
A6: BẢNG TỔNG HỢP KHÁM SỨC KHỎE HỌC SINH
A7: (Khám sức khỏe học sinh năm học 2024-2025 ngày 04 tháng 03 năm 2025)
A9: TÊN ĐƠN VỊ | C9: : TRƯỜNG TIỂU HỌC PHƯỚC ĐỒNG
A10: ĐỊA CHỈ | C10: : Thôn Phước Điền - Xã Phước Đồng - Nha Trang - Khánh Hòa
A12: STT | B12: TÊN LỚP | C12: SỐ LƯỢNG | D12: TÌNH TRẠNG DINH DƯỠNG | M12: KHÁM CHUYÊN KHOA | Q12: PHÂN LOẠI SỨC KHỎE
D13: Chiều cao | H13: Cân nặng theo chiều cao (BMI)
D14: SDDTTC MĐN | E14: SDDTTC | F14: bt | G14: CHT | H14: SDDTGC MĐN | I14: SDDTGC | J14: bt | K14: TC | L14: BP | M14: MẮT | N14: TAI MŨI HỌNG | O14: RĂNG HÀM MẶT | P14: KHÁC | Q14: I | R14: II | S14: III
A15: 1 | B15: 1/1 | C15: 35 | T15: =D15+E15+F15+G15 -> 0 | U15: =H15+I15+J15+K15+L15 -> 0 | V15: =Q15+R15+S15 -> 0
A16: 2 | B16: 1/2 | C16: 41 | T16: =D16+E16+F16+G16 -> 0 | U16: =H16+I16+J16+K16+L16 -> 0 | V16: =Q16+R16+S16 -> 0
A17: 3 | B17: 1/3 | C17: 48 | T17: =D17+E17+F17+G17 -> 0 | U17: =H17+I17+J17+K17+L17 -> 0 | V17: =Q17+R17+S17 -> 0
A18: 4 | B18: 1/4 | C18: 49 | T18: =D18+E18+F18+G18 -> 0 | U18: =H18+I18+J18+K18+L18 -> 0 | V18: =Q18+R18+S18 -> 0
A19: 5 | B19: 1/5 | C19: 49 | T19: =D19+E19+F19+G19 -> 0 | U19: =H19+I19+J19+K19+L19 -> 0 | V19: =Q19+R19+S19 -> 0
A20: 6 | B20: 1/6 | C20: 50 | T20: =D20+E20+F20+G20 -> 0 | U20: =H20+I20+J20+K20+L20 -> 0 | V20: =Q20+R20+S20 -> 0
A21: 7 | B21: 1/7 | C21: 50 | T21: =D21+E21+F21+G21 -> 0 | U21: =H21+I21+J21+K21+L21 -> 0 | V21: =Q21+R21+S21 -> 0
A22: 8 | B22: 1/8 | C22: 47 | T22: =D22+E22+F22+G22 -> 0 | U22: =H22+I22+J22+K22+L22 -> 0 | V22: =Q22+R22+S22 -> 0
A23: 9 | B23: 1/9 | C23: 46 | T23: =D23+E23+F23+G23 -> 0 | U23: =H23+I23+J23+K23+L23 -> 0 | V23: =Q23+R23+S23 -> 0
A24: 10 | B24: 2/1 | C24: 29 | T24: =D24+E24+F24+G24 -> 0 | U24: =H24+I24+J24+K24+L24 -> 0 | V24: =Q24+R24+S24 -> 0
A25: 11 | B25: 2/2 | C25: 36 | T25: =D25+E25+F25+G25 -> 0 | U25: =H25+I25+J25+K25+L25 -> 0 | V25: =Q25+R25+S25 -> 0
A26: 12 | B26: 2/3 | C26: 45 | T26: =D26+E26+F26+G26 -> 0 | U26: =H26+I26+J26+K26+L26 -> 0 | V26: =Q26+R26+S26 -> 0
... A57: 43 | B57: 5/8 | C57: 47 | T57: =D57+E57+F57+G57 -> 0 | U57: =H57+I57+J57+K57+L57 -> 0 | V57: =Q57+R57+S57 -> 0
A58: TỔNG CỘNG | C58: =SUM(C15:C57) -> 1870 | D58: =SUM(D15:D57) -> 0 | E58: =SUM(E15:E57) -> 0 | F58: =SUM(F15:F57) -> 0 | G58: =SUM(G15:G57) -> 0 | H58: =SUM(H15:H57) -> 0 | I58: =SUM(I15:I57) -> 0 | J58: =SUM(J15:J57) -> 0 | ... S58: =SUM(S15:S57) -> 0 | T58: =D58+E58+F58+G58 -> 0 | U58: =SUM(U15:U57) -> 0 | V58: =Q58+R58+S58 -> 0
A59: TỶ LỆ | C59: 100 | D59: =D58/$C58*100 -> 0 | E59: =E58/$C58*100 -> 0 | F59: =F58/$C58*100 -> 0 | G59: =G58/$C58*100 -> 0 | H59: =H58/$C58*100 -> 0 | I59: =I58/$C58*100 -> 0 | J59: =J58/$C58*100 -> 0 | K59: =K58/$C58*100 -> 0 | ... P59: =P58/$C58*100 -> 0 | Q59: 31.8 | R59: =R58/$C58*100 -> 0 | S59: =S58/$C58*100 -> 0
A61: KIẾN NGHỊ
A62: - Nhà trường, phụ huynh có chế độ ăn hợp lý cho các cháu thừa cân, béo phì. Tăng cường vận động, luyện tập thể dục thể thao, hạn chế chất ngọt, béo…. - Tăng cường truyền thông cho phụ huynh, học sinh, giáo viên chủ nhiệm về tình trạng dinh dưỡng của học sinh. - Tăng cường chất dinh dưỡng cho các cháu bị suy dinh dưỡng thể gầy còm. - Thông báo đến phụ huynh các cháu bị viêm mũi họng, sâu răng, cận thị, da liễu,… khám thêm chuyên khoa để có hướng điều trị. (Có danh sách trong sổ theo dõi tình trạng bệnh). - Đề nghị tăng cường vệ sinh răng miệng hàng ngày, tăng công tác truyền thông Nha học đường cho phụ huynh và học sinh, giữ gìn vệ sinh thân thể thường xuyên.
B70: NGƯỜI TỔNG HỢP | O70: ĐOÀN KHÁM
B76: YS. Lê Thị Diệu Hiền

Sheet BIỂU ĐỒ
A1: SỞ Y TẾ KHÁNH HÒA | I1: CỘNG HÒA XÃ HỘI CHỦ NGHĨA VIỆT NAM | R1: BIỂU ĐỒ CHIỀU CAO THEO TUỔI | AB1: =CONCATENATE("BIỂU ĐỒ ",RIGHT(#REF!,LEN(#REF!)-7)) -> #REF!
A2: PHÒNG KHÁM ĐA KHOA PHÚC THIỆN NHÂN | I2: Độc lập - Tự do - Hạnh phúc
I4: Nha Trang, ngày 18 tháng 03 năm 2025 | AC4: Tỷ lệ %
AB5: Suy dinh dưỡng thấp còi nặng | AC5: =O21/100 -> 0
A6: TỔNG HỢP KHÁM SỨC KHỎE HỌC SINH NĂM HỌC 2024-2025 | AB6: Suy dinh dưỡng thấp còi | AC6: =O22/100 -> 0
AB7: Bình thường | AC7: =O23/100 -> 0
A8: (Khám sức khỏe học sinh năm học 2024-2025 ngày 04 tháng 03 năm 2025) | AB8: Cao hơn tuổi | AC8: =O24/100 -> 0
A10: TÊN ĐƠN VỊ | D10: : TRƯỜNG TIỂU HỌC PHƯỚC ĐỒNG
A11: ĐỊA CHỈ | D11: : Thôn Phước Điền - Xã Phước Đồng - Nha Trang - Khánh Hòa
A13: I. THÔNG TIN CHUNG:
A15: ‐ Tổng số học sinh | E15: =": "&BTH!C58&" học sinh" -> : 1870 học sinh | K15: ‐ Tổng số lớp | N15: =": "&COUNTA(BTH!A15:A57) -> : 43
A17: II. TÌNH TRẠNG DINH DƯỠNG:
A19: 2.1. Chiều cao theo tuổi
B21: ‐ Suy dinh dưỡng thể thấp còi nặng | J21: =": "&BTH!D58 -> : 0 | M21: chiếm | O21: =ROUND(BTH!D59,1) -> 0 | P21: % | R21: BIỂU ĐỒ BMI | AC21: Tỷ lệ %
B22: ‐ Suy dinh dưỡng thể thấp còi | J22: =": "&BTH!E58 -> : 0 | M22: chiếm | O22: =ROUND(BTH!E59,1) -> 0 | P22: % | AB22: Suy dinh dưỡng gầy còm nặng | AC22: =O28/100 -> 0
B23: ‐ Bình thường | J23: =": "&BTH!F58 -> : 0 | M23: chiếm | O23: =ROUND(BTH!F59,1) -> 0 | P23: % | AB23: Suy dinh dưỡng gầy còm | AC23: =O29/100 -> 0
B24: ‐ Cao hơn tuổi | J24: =": "&BTH!G58 -> : 0 | M24: chiếm | O24: =ROUND(BTH!G59,1) -> 0 | P24: % | AB24: Bình thường | AC24: =O30/100 -> 0
AB25: Thừa cân | AC25: =O31/100 -> 0
A26: 2.3 Theo BMI | AB26: Béo phì | AC26: =O32/100 -> 0
